Workbook

Sheet Format description
A1: Notations | C1: Example | E1: Content
B4: Status | C4: V | E4: Last used of the statioin during BITS (Quarter 1 in 2011)
A5: Position | B5: NrHaul | C5: 22002 | E5: Number of the haul (SD followed by 3 figures)
B6: Rectangular | C6: 3756 | E6: Notation of the rectangle (3756 and 37G1 is used parallel)
B7: ICES SD | C7: 22 | E7: ICES subdivision
A8: 1 | B8: Latitude | C8: 54 | E8: 1. Position: Degree of latitudes
C9: 11.27 | E9: 1. Position: minutes of latitude
B10: Longitude | C10: 11 | E10: 1. Position: Degree of longitude
C11: 55.26 | E11: 1. Position: minutes of longitude
A12: 2 | B12: Latitude | C12: 54 | E12: 2. Position: Degree of latitudes
C13: 11.19 | E13: 2. Position: minutes of latitude
B14: Longitude | C14: 11 | E14: 2. Position: Degree of longitude
C15: 49.49 | E15: 2. Position: minutes of longitude
A16: 3 | B16: Latitude | C16: 0
C17: 0
B18: Longitude | C18: 0
C19: 0 | E19: In each caseat least two positions are available. More than two subsequent positions are available if the haul does not present a straigth line
A20: 4 | B20: Latitude | C20: 0
C21: 0
B22: Longitude | C22: 0
C23: 0
A24: 5 | B24: Latitude | C24: 0
C25: 0
B26: Longitude | C26: 0
C27: 0
A28: 6 | B28: Latitude | C28: 0
C29: 0
B30: Longitude | C30: 0
C31: 0
A32: 7 | B32: Latitude | C32: 0
C33: 0
B34: Longitude | C34: 0
C35: 0
A36: 8 | B36: Latitude | C36: 0
C37: 0
B38: Longitude | C38: 0
C39: 0
A40: 9 | B40: Latitude | C40: 0
C41: 0
B42: Longitude | C42: 0
...

Sheet SD22N
B2: Position | I2: 1 | M2: 2 | Q2: 3 | U2: 4 | Y2: 5 | AC2: 6 | AG2: 7 | AK2: 8 | AO2: 9 | AS2: 10 | BR2: Depth | BS2: 1. Pos | BU2: Unit 1. Pos | BW2: Mean Pos. Unit
A3: Status | B3: NrHaul | C3: Rectangle | E3: Check | F3: Rect. Num | G3: Rect. Alpha | H3: ICES SD | I3: Latitude | K3: Longitude | M3: Latitude | O3: Longitude | Q3: Latitude | S3: Longitude | U3: Latitude | W3: Longitude | Y3: Latitude | AA3: Longitude | AC3: Latitude | AE3: Longitude | AG3: Latitude | AI3: Longitude | AK3: Latitude | AM3: Longitude | AO3: Latitude | AQ3: Longitude | AS3: Latitude | AU3: Longitude | AX3: Depth | AY3: 1 | AZ3: 2 | BA3: 3 | BB3: 4 | BC3: 5 | BD3: 6 | BE3: 7 | BF3: 8 | BG3: 9 | BH3: 10 | BI3: Source | BJ3: EEZ | BK3: 12NM | BL3: rope | BM3: Direction | BN3: Distance | BQ3: Dist | BR3: layer | BS3: Lati | BT3: Long | BU3: Lati | BV3: Long | BW3: Lati | BX3: Long
A4: V | B4: 22002 | C4: 3756 | D4: =IF(K4=9,54,IF(K4=10,55,IF(K4=11,56,""))) -> 56 | E4: =IF(D4=_xlfn.NUMBERVALUE(RIGHT(C4,2)),"OK","") -> OK | F4: =CONCATENATE(LEFT(C4,2),D4) -> 3756 | G4: =IF(RIGHT(C4,2)="54",CONCATENATE(LEFT(C4,2),"F9"),IF(RIGHT(C4,2)="55",CONCATENATE(LEFT(C4,2),"G0"),IF(RIGHT(C4,2)="56",CONCATENATE(LEFT(C4,2),"G1"),IF(RIGHT(C4,2)="57",CONCATENATE(LEFT(C4,2),"G2"),IF(RIGHT(C4,2)="58",CONCATENATE(LEFT(C4,2),"G3"),IF(RIGHT(C4,2)="59",CONCATENATE(LEFT(C4,2),"G4"),IF(RIGHT(C4,2)="60",CONCATENATE(LEFT(C4,2),"G5"),IF(RIGHT(C4,2)="61",CONCATENATE(LEFT(C4,2),"G6"),IF(RIGHT(C4,2)="62",CONCATENATE(LEFT(C4,2),"G7"),IF(RIGHT(C4,2)="63",CONCATENATE(LEFT(C4,2),"G8"),IF(RIGHT(C4,2)="64",CONCATENATE(LEFT(C4,2),"G9"),IF(RIGHT(C4,2)="65",CONCATENATE(LEFT(C4,2),"H0"),IF(RIGHT(C4,2)="66",CONCATENATE(LEFT(C4,2),"H1"),IF(RIGHT(C4,2)="67",CONCATENATE(LEFT(C4,2),"H2"),IF(RIGHT(C4,2)="68",CONCATENATE(LEFT(C4,2),"H3"),IF(RIGHT(C4,2)="68",CONCATENATE(LEFT(C4,2),"H4"),C4)))))))))))))))) -> 37G1 | H4: 22 | I4: 54 | J4: 11.27 | K4: 11 | L4: 55.26 | M4: 54 | N4: 11.19 | O4: 11 | P4: 49.49 | Q4: 0 | R4: 0 | S4: 0 | T4: 0 | U4: 0 | V4: 0 | W4: 0 | X4: 0 | Y4: 0 | Z4: 0 | AA4: 0 | AB4: 0 | AC4: 0 | AD4: 0 | AE4: 0 | AF4: 0 | AG4: 0 | AH4: 0 | AI4: 0 | AJ4: 0 | AK4: 0 | AL4: 0 | AM4: 0 | AN4: 0 | AO4: 0 | AP4: 0 | AQ4: 0 | AR4: 0 | AS4: 0 | AT4: 0 | AU4: 0 | AV4: 0 | AW4: =IF(A4="",1,"") | AX4: 18 | AY4: 19 | AZ4: 17 | BA4: 0 | BB4: 0 | BC4: 0 | BD4: 0 | BE4: 0 | BF4: 0 | BG4: 0 | BH4: 0 | BI4: German R/V | BJ4: GFR | BK4: No | BL4: 1 | BM4: 1 | BN4: 3.3772013 | BP4: 2 | BQ4: 3.3772013 | BR4: 2 | BS4: 5411.27 | BT4: 1155.26 | BU4: 3702 | BV4: 5603 | BW4: 5415 | BX4: 1150
A5: V | B5: 22003 | C5: 3756 | D5: =IF(K5=9,54,IF(K5=10,55,IF(K5=11,56,""))) -> 56 | E5: =IF(D5=_xlfn.NUMBERVALUE(RIGHT(C5,2)),"OK","") -> OK | F5: =CONCATENATE(LEFT(C5,2),D5) -> 3756 | G5: =IF(RIGHT(C5,2)="54",CONCATENATE(LEFT(C5,2),"F9"),IF(RIGHT(C5,2)="55",CONCATENATE(LEFT(C5,2),"G0"),IF(RIGHT(C5,2)="56",CONCATENATE(LEFT(C5,2),"G1"),IF(RIGHT(C5,2)="57",CONCATENATE(LEFT(C5,2),"G2"),IF(RIGHT(C5,2)="58",CONCATENATE(LEFT(C5,2),"G3"),IF(RIGHT(C5,2)="59",CONCATENATE(LEFT(C5,2),"G4"),IF(RIGHT(C5,2)="60",CONCATENATE(LEFT(C5,2),"G5"),IF(RIGHT(C5,2)="61",CONCATENATE(LEFT(C5,2),"G6"),IF(RIGHT(C5,2)="62",CONCATENATE(LEFT(C5,2),"G7"),IF(RIGHT(C5,2)="63",CONCATENATE(LEFT(C5,2),"G8"),IF(RIGHT(C5,2)="64",CONCATENATE(LEFT(C5,2),"G9"),IF(RIGHT(C5,2)="65",CONCATENATE(LEFT(C5,2),"H0"),IF(RIGHT(C5,2)="66",CONCATENATE(LEFT(C5,2),"H1"),IF(RIGHT(C5,2)="67",CONCATENATE(LEFT(C5,2),"H2"),IF(RIGHT(C5,2)="68",CONCATENATE(LEFT(C5,2),"H3"),IF(RIGHT(C5,2)="68",CONCATENATE(LEFT(C5,2),"H4"),C5)))))))))))))))) -> 37G1 | H5: 22 | I5: 54 | J5: 11.8 | K5: 11 | L5: 53.4 | M5: 54 | N5: 14.2 | O5: 11 | P5: 53.2 | Q5: 0 | R5: 0 | S5: 0 | T5: 0 | U5: 0 | V5: 0 | W5: 0 | X5: 0 | Y5: 0 | Z5: 0 | AA5: 0 | AB5: 0 | AC5: 0 | AD5: 0 | AE5: 0 | AF5: 0 | AG5: 0 | AH5: 0 | AI5: 0 | AJ5: 0 | AK5: 0 | AL5: 0 | AM5: 0 | AN5: 0 | AO5: 0 | AP5: 0 | AQ5: 0 | AR5: 0 | AS5: 0 | AT5: 0 | AU5: 0 | AV5: 0 | AW5: =IF(A5="",1,"") | AX5: 19 | AY5: 19 | AZ5: 19 | BA5: 0 | BB5: 0 | BC5: 0 | BD5: 0 | BE5: 0 | BF5: 0 | BG5: 0 | BH5: 0 | BI5: Havfisken | BJ5: GFR | BK5: No | BL5: 0 | BM5: 1 | BN5: 2.4028475 | BP5: 2 | BQ5: 2.4028475 | BR5: 2 | BS5: 5411.8 | BT5: 1153.4 | BU5: 3702 | BV5: 5603 | BW5: 5415 | BX5: 1150
A6: V | B6: 22004 | C6: 3755 | D6: =IF(K6=9,54,IF(K6=10,55,IF(K6=11,56,""))) -> 55 | E6: =IF(D6=_xlfn.NUMBERVALUE(RIGHT(C6,2)),"OK","") -> OK | F6: =CONCATENATE(LEFT(C6,2),D6) -> 3755 | G6: =IF(RIGHT(C6,2)="54",CONCATENATE(LEFT(C6,2),"F9"),IF(RIGHT(C6,2)="55",CONCATENATE(LEFT(C6,2),"G0"),IF(RIGHT(C6,2)="56",CONCATENATE(LEFT(C6,2),"G1"),IF(RIGHT(C6,2)="57",CONCATENATE(LEFT(C6,2),"G2"),IF(RIGHT(C6,2)="58",CONCATENATE(LEFT(C6,2),"G3"),IF(RIGHT(C6,2)="59",CONCATENATE(LEFT(C6,2),"G4"),IF(RIGHT(C6,2)="60",CONCATENATE(LEFT(C6,2),"G5"),IF(RIGHT(C6,2)="61",CONCATENATE(LEFT(C6,2),"G6"),IF(RIGHT(C6,2)="62",CONCATENATE(LEFT(C6,2),"G7"),IF(RIGHT(C6,2)="63",CONCATENATE(LEFT(C6,2),"G8"),IF(RIGHT(C6,2)="64",CONCATENATE(LEFT(C6,2),"G9"),IF(RIGHT(C6,2)="65",CONCATENATE(LEFT(C6,2),"H0"),IF(RIGHT(C6,2)="66",CONCATENATE(LEFT(C6,2),"H1"),IF(RIGHT(C6,2)="67",CONCATENATE(LEFT(C6,2),"H2"),IF(RIGHT(C6,2)="68",CONCATENATE(LEFT(C6,2),"H3"),IF(RIGHT(C6,2)="68",CONCATENATE(LEFT(C6,2),"H4"),C6)))))))))))))))) -> 37G0 | H6: 22 | I6: 54 | J6: 26.5 | K6: 10 | L6: 39.66 | M6: 54 | N6: 27.31 | O6: 10 | P6: 35.55 | Q6: 0 | R6: 0 | S6: 0 | T6: 0 | U6: 0 | V6: 0 | W6: 0 | X6: 0 | Y6: 0 | Z6: 0 | AA6: 0 | AB6: 0 | AC6: 0 | AD6: 0 | AE6: 0 | AF6: 0 | AG6: 0 | AH6: 0 | AI6: 0 | AJ6: 0 | AK6: 0 | AL6: 0 | AM6: 0 | AN6: 0 | AO6: 0 | AP6: 0 | AQ6: 0 | AR6: 0 | AS6: 0 | AT6: 0 | AU6: 0 | AV6: 0 | AW6: =IF(A6="",1,"") | AX6: 18 | AY6: 18 | AZ6: 18 | BA6: 0 | BB6: 0 | BC6: 0 | BD6: 0 | BE6: 0 | BF6: 0 | BG6: 0 | BH6: 0 | BI6: German R/V | BJ6: GFR | BK6: No | BL6: 1 | BM6: 1 | BN6: 2.5232456 | BP6: 2 | BQ6: 2.5232456 | BR6: 2 | BS6: 5426.5 | BT6: 1039.66 | BU6: 3703 | BV6: 5502 | BW6: 5425 | BX6: 1030
A7: V | B7: 22005 | C7: 3755 | D7: =IF(K7=9,54,IF(K7=10,55,IF(K7=11,56,""))) -> 55 | E7: =IF(D7=_xlfn.NUMBERVALUE(RIGHT(C7,2)),"OK","") -> OK | F7: =CONCATENATE(LEFT(C7,2),D7) -> 3755 | G7: =IF(RIGHT(C7,2)="54",CONCATENATE(LEFT(C7,2),"F9"),IF(RIGHT(C7,2)="55",CONCATENATE(LEFT(C7,2),"G0"),IF(RIGHT(C7,2)="56",CONCATENATE(LEFT(C7,2),"G1"),IF(RIGHT(C7,2)="57",CONCATENATE(LEFT(C7,2),"G2"),IF(RIGHT(C7,2)="58",CONCATENATE(LEFT(C7,2),"G3"),IF(RIGHT(C7,2)="59",CONCATENATE(LEFT(C7,2),"G4"),IF(RIGHT(C7,2)="60",CONCATENATE(LEFT(C7,2),"G5"),IF(RIGHT(C7,2)="61",CONCATENATE(LEFT(C7,2),"G6"),IF(RIGHT(C7,2)="62",CONCATENATE(LEFT(C7,2),"G7"),IF(RIGHT(C7,2)="63",CONCATENATE(LEFT(C7,2),"G8"),IF(RIGHT(C7,2)="64",CONCATENATE(LEFT(C7,2),"G9"),IF(RIGHT(C7,2)="65",CONCATENATE(LEFT(C7,2),"H0"),IF(RIGHT(C7,2)="66",CONCATENATE(LEFT(C7,2),"H1"),IF(RIGHT(C7,2)="67",CONCATENATE(LEFT(C7,2),"H2"),IF(RIGHT(C7,2)="68",CONCATENATE(LEFT(C7,2),"H3"),IF(RIGHT(C7,2)="68",CONCATENATE(LEFT(C7,2),"H4"),C7)))))))))))))))) -> 37G0 | H7: 22 | I7: 54 | J7: 24.24 | K7: 10 | L7: 45.27 | M7: 54 | N7: 25.45 | O7: 10 | P7: 43.58 | Q7: 0 | R7: 0 | S7: 0 | T7: 0 | U7: 0 | V7: 0 | W7: 0 | X7: 0 | Y7: 0 | Z7: 0 | AA7: 0 | AB7: 0 | AC7: 0 | AD7: 0 | AE7: 0 | AF7: 0 | AG7: 0 | AH7: 0 | AI7: 0 | AJ7: 0 | AK7: 0 | AL7: 0 | AM7: 0 | AN7: 0 | AO7: 0 | AP7: 0 | AQ7: 0 | AR7: 0 | AS7: 0 | AT7: 0 | AU7: 0 | AV7: 0 | AW7: =IF(A7="",1,"") | AX7: 17 | AY7: 17 | AZ7: 17 | BA7: 0 | BB7: 0 | BC7: 0 | BD7: 0 | BE7: 0 | BF7: 0 | BG7: 0 | BH7: 0 | BI7: Havfisken | BJ7: GFR | BK7: No | BL7: 0 | BM7: 1 | BN7: 1.5592543 | BP7: 1 | BQ7: 1.5592543 | BR7: 2 | BS7: 5424.24 | BT7: 1045.27 | BU7: 3703 | BV7: 5503 | BW7: 5425 | BX7: 1050
A8: I | B8: 22006 | C8: 3755 | D8: =IF(K8=9,54,IF(K8=10,55,IF(K8=11,56,""))) -> 55 | E8: =IF(D8=_xlfn.NUMBERVALUE(RIGHT(C8,2)),"OK","") -> OK | F8: =CONCATENATE(LEFT(C8,2),D8) -> 3755 | G8: =IF(RIGHT(C8,2)="54",CONCATENATE(LEFT(C8,2),"F9"),IF(RIGHT(C8,2)="55",CONCATENATE(LEFT(C8,2),"G0"),IF(RIGHT(C8,2)="56",CONCATENATE(LEFT(C8,2),"G1"),IF(RIGHT(C8,2)="57",CONCATENATE(LEFT(C8,2),"G2"),IF(RIGHT(C8,2)="58",CONCATENATE(LEFT(C8,2),"G3"),IF(RIGHT(C8,2)="59",CONCATENATE(LEFT(C8,2),"G4"),IF(RIGHT(C8,2)="60",CONCATENATE(LEFT(C8,2),"G5"),IF(RIGHT(C8,2)="61",CONCATENATE(LEFT(C8,2),"G6"),IF(RIGHT(C8,2)="62",CONCATENATE(LEFT(C8,2),"G7"),IF(RIGHT(C8,2)="63",CONCATENATE(LEFT(C8,2),"G8"),IF(RIGHT(C8,2)="64",CONCATENATE(LEFT(C8,2),"G9"),IF(RIGHT(C8,2)="65",CONCATENATE(LEFT(C8,2),"H0"),IF(RIGHT(C8,2)="66",CONCATENATE(LEFT(C8,2),"H1"),IF(RIGHT(C8,2)="67",CONCATENATE(LEFT(C8,2),"H2"),IF(RIGHT(C8,2)="68",CONCATENATE(LEFT(C8,2),"H3"),IF(RIGHT(C8,2)="68",CONCATENATE(LEFT(C8,2),"H4"),C8)))))))))))))))) -> 37G0 | H8: 22 | I8: 54 | J8: 29.8 | K8: 10 | L8: 41.2 | M8: 54 | N8: 27.7 | O8: 10 | P8: 42.6 | Q8: 0 | R8: 0 | S8: 0 | T8: 0 | U8: 0 | V8: 0 | W8: 0 | X8: 0 | Y8: 0 | Z8: 0 | AA8: 0 | AB8: 0 | AC8: 0 | AD8: 0 | AE8: 0 | AF8: 0 | AG8: 0 | AH8: 0 | AI8: 0 | AJ8: 0 | AK8: 0 | AL8: 0 | AM8: 0 | AN8: 0 | AO8: 0 | AP8: 0 | AQ8: 0 | AR8: 0 | AS8: 0 | AT8: 0 | AU8: 0 | AV8: 0 | AW8: =IF(A8="",1,"") | AX8: 19 | AY8: 19 | AZ8: 19 | BA8: 0 | BB8: 0 | BC8: 0 | BD8: 0 | BE8: 0 | BF8: 0 | BG8: 0 | BH8: 0 | BI8: Havfisken | BJ8: GFR | BK8: No | BL8: 0 | BM8: 0 | BN8: 2.2520251 | BP8: 2 | BQ8: 2.2520251 | BR8: 2 | BS8: 5429.8 | BT8: 1041.2 | BU8: 3703 | BV8: 5503 | BW8: 5425 | BX8: 1050
A9: V | B9: 22007 | C9: 3756 | D9: =IF(K9=9,54,IF(K9=10,55,IF(K9=11,56,""))) -> 56 | E9: =IF(D9=_xlfn.NUMBERVALUE(RIGHT(C9,2)),"OK","") -> OK | F9: =CONCATENATE(LEFT(C9,2),D9) -> 3756 | G9: =IF(RIGHT(C9,2)="54",CONCATENATE(LEFT(C9,2),"F9"),IF(RIGHT(C9,2)="55",CONCATENATE(LEFT(C9,2),"G0"),IF(RIGHT(C9,2)="56",CONCATENATE(LEFT(C9,2),"G1"),IF(RIGHT(C9,2)="57",CONCATENATE(LEFT(C9,2),"G2"),IF(RIGHT(C9,2)="58",CONCATENATE(LEFT(C9,2),"G3"),IF(RIGHT(C9,2)="59",CONCATENATE(LEFT(C9,2),"G4"),IF(RIGHT(C9,2)="60",CONCATENATE(LEFT(C9,2),"G5"),IF(RIGHT(C9,2)="61",CONCATENATE(LEFT(C9,2),"G6"),IF(RIGHT(C9,2)="62",CONCATENATE(LEFT(C9,2),"G7"),IF(RIGHT(C9,2)="63",CONCATENATE(LEFT(C9,2),"G8"),IF(RIGHT(C9,2)="64",CONCATENATE(LEFT(C9,2),"G9"),IF(RIGHT(C9,2)="65",CONCATENATE(LEFT(C9,2),"H0"),IF(RIGHT(C9,2)="66",CONCATENATE(LEFT(C9,2),"H1"),IF(RIGHT(C9,2)="67",CONCATENATE(LEFT(C9,2),"H2"),IF(RIGHT(C9,2)="68",CONCATENATE(LEFT(C9,2),"H3"),IF(RIGHT(C9,2)="68",CONCATENATE(LEFT(C9,2),"H4"),C9)))))))))))))))) -> 37G1 | H9: 22 | I9: 54 | J9: 27.13 | K9: 11 | L9: 23.18 | M9: 54 | N9: 23.17 | O9: 11 | P9: 22.24 | Q9: 0 | R9: 0 | S9: 0 | T9: 0 | U9: 0 | V9: 0 | W9: 0 | X9: 0 | Y9: 0 | Z9: 0 | AA9: 0 | AB9: 0 | AC9: 0 | AD9: 0 | AE9: 0 | AF9: 0 | AG9: 0 | AH9: 0 | AI9: 0 | AJ9: 0 | AK9: 0 | AL9: 0 | AM9: 0 | AN9: 0 | AO9: 0 | AP9: 0 | AQ9: 0 | AR9: 0 | AS9: 0 | AT9: 0 | AU9: 0 | AV9: 0 | AW9: =IF(A9="",1,"") | AX9: 16 | AY9: 16 | AZ9: 15 | BA9: 0 | BB9: 0 | BC9: 0 | BD9: 0 | BE9: 0 | BF9: 0 | BG9: 0 | BH9: 0 | BI9: German R/V | BJ9: GFR | BK9: No | BL9: 1 | BM9: 1 | BN9: 3.9975922 | BP9: 2 | BQ9: 3.9975922 | BR9: 2 | BS9: 5427.13 | BT9: 1123.18 | BU9: 3703 | BV9: 5602 | BW9: 5425 | BX9: 1130
A10: V | B10: 22008 | C10: 3756 | D10: =IF(K10=9,54,IF(K10=10,55,IF(K10=11,56,""))) -> 56 | E10: =IF(D10=_xlfn.NUMBERVALUE(RIGHT(C10,2)),"OK","") -> OK | F10: =CONCATENATE(LEFT(C10,2),D10) -> 3756 | G10: =IF(RIGHT(C10,2)="54",CONCATENATE(LEFT(C10,2),"F9"),IF(RIGHT(C10,2)="55",CONCATENATE(LEFT(C10,2),"G0"),IF(RIGHT(C10,2)="56",CONCATENATE(LEFT(C10,2),"G1"),IF(RIGHT(C10,2)="57",CONCATENATE(LEFT(C10,2),"G2"),IF(RIGHT(C10,2)="58",CONCATENATE(LEFT(C10,2),"G3"),IF(RIGHT(C10,2)="59",CONCATENATE(LEFT(C10,2),"G4"),IF(RIGHT(C10,2)="60",CONCATENATE(LEFT(C10,2),"G5"),IF(RIGHT(C10,2)="61",CONCATENATE(LEFT(C10,2),"G6"),IF(RIGHT(C10,2)="62",CONCATENATE(LEFT(C10,2),"G7"),IF(RIGHT(C10,2)="63",CONCATENATE(LEFT(C10,2),"G8"),IF(RIGHT(C10,2)="64",CONCATENATE(LEFT(C10,2),"G9"),IF(RIGHT(C10,2)="65",CONCATENATE(LEFT(C10,2),"H0"),IF(RIGHT(C10,2)="66",CONCATENATE(LEFT(C10,2),"H1"),IF(RIGHT(C10,2)="67",CONCATENATE(LEFT(C10,2),"H2"),IF(RIGHT(C10,2)="68",CONCATENATE(LEFT(C10,2),"H3"),IF(RIGHT(C10,2)="68",CONCATENATE(LEFT(C10,2),"H4"),C10)))))))))))))))) -> 37G1 | H10: 22 | I10: 54 | J10: 20.8 | K10: 11 | L10: 55.3 | M10: 54 | N10: 18.5 | O10: 11 | P10: 55.4 | Q10: 0 | R10: 0 | S10: 0 | T10: 0 | U10: 0 | V10: 0 | W10: 0 | X10: 0 | Y10: 0 | Z10: 0 | AA10: 0 | AB10: 0 | AC10: 0 | AD10: 0 | AE10: 0 | AF10: 0 | AG10: 0 | AH10: 0 | AI10: 0 | AJ10: 0 | AK10: 0 | AL10: 0 | AM10: 0 | AN10: 0 | AO10: 0 | AP10: 0 | AQ10: 0 | AR10: 0 | AS10: 0 | AT10: 0 | AU10: 0 | AV10: 0 | AW10: =IF(A10="",1,"") | AX10: 19 | AY10: 19 | AZ10: 19 | BA10: 0 | BB10: 0 | BC10: 0 | BD10: 0 | BE10: 0 | BF10: 0 | BG10: 0 | BH10: 0 | BI10: Havfisken | BJ10: GFR | BK10: No | BL10: 0 | BM10: 0 | BN10: 2.3007392 | BP10: 2 | BQ10: 2.3007392 | BR10: 2 | BS10: 5420.8 | BT10: 1155.3 | BU10: 3703 | BV10: 5603 | BW10: 5425 | BX10: 1150
A11: V | B11: 22011 | C11: 3855 | D11: =IF(K11=9,54,IF(K11=10,55,IF(K11=11,56,""))) -> 55 | E11: =IF(D11=_xlfn.NUMBERVALUE(RIGHT(C11,2)),"OK","") -> OK | F11: =CONCATENATE(LEFT(C11,2),D11) -> 3855 | G11: =IF(RIGHT(C11,2)="54",CONCATENATE(LEFT(C11,2),"F9"),IF(RIGHT(C11,2)="55",CONCATENATE(LEFT(C11,2),"G0"),IF(RIGHT(C11,2)="56",CONCATENATE(LEFT(C11,2),"G1"),IF(RIGHT(C11,2)="57",CONCATENATE(LEFT(C11,2),"G2"),IF(RIGHT(C11,2)="58",CONCATENATE(LEFT(C11,2),"G3"),IF(RIGHT(C11,2)="59",CONCATENATE(LEFT(C11,2),"G4"),IF(RIGHT(C11,2)="60",CONCATENATE(LEFT(C11,2),"G5"),IF(RIGHT(C11,2)="61",CONCATENATE(LEFT(C11,2),"G6"),IF(RIGHT(C11,2)="62",CONCATENATE(LEFT(C11,2),"G7"),IF(RIGHT(C11,2)="63",CONCATENATE(LEFT(C11,2),"G8"),IF(RIGHT(C11,2)="64",CONCATENATE(LEFT(C11,2),"G9"),IF(RIGHT(C11,2)="65",CONCATENATE(LEFT(C11,2),"H0"),IF(RIGHT(C11,2)="66",CONCATENATE(LEFT(C11,2),"H1"),IF(RIGHT(C11,2)="67",CONCATENATE(LEFT(C11,2),"H2"),IF(RIGHT(C11,2)="68",CONCATENATE(LEFT(C11,2),"H3"),IF(RIGHT(C11,2)="68",CONCATENATE(LEFT(C11,2),"H4"),C11)))))))))))))))) -> 38G0 | H11: 22 | I11: 54 | J11: 34.55 | K11: 10 | L11: 10.19 | M11: 54 | N11: 33.53 | O11: 10 | P11: 14.12 | Q11: 0 | R11: 0 | S11: 0 | T11: 0 | U11: 0 | V11: 0 | W11: 0 | X11: 0 | Y11: 0 | Z11: 0 | AA11: 0 | AB11: 0 | AC11: 0 | AD11: 0 | AE11: 0 | AF11: 0 | AG11: 0 | AH11: 0 | AI11: 0 | AJ11: 0 | AK11: 0 | AL11: 0 | AM11: 0 | AN11: 0 | AO11: 0 | AP11: 0 | AQ11: 0 | AR11: 0 | AS11: 0 | AT11: 0 | AU11: 0 | AV11: 0 | AW11: =IF(A11="",1,"") | AX11: 20 | AY11: 18 | AZ11: 17 | BA11: 0 | BB11: 0 | BC11: 0 | BD11: 0 | BE11: 0 | BF11: 0 | BG11: 0 | BH11: 0 | BI11: German R/V | BJ11: GFR | BK11: No | BL11: 1 | BM11: 0 | BN11: 2.4962994 | BP11: 2 | BQ11: 2.4962994 | BR11: 2 | BS11: 5434.55 | BT11: 1010.19 | BU11: 3801 | BV11: 5501 | BW11: 5435 | BX11: 1010
A12: V | B12: 22012 | C12: 37G1 | D12: =IF(K12=9,54,IF(K12=10,55,IF(K12=11,56,""))) -> 56 | E12: =IF(D12=_xlfn.NUMBERVALUE(RIGHT(C12,2)),"OK","") -> #VALUE! | F12: =CONCATENATE(LEFT(C12,2),D12) -> 3756 | G12: =IF(RIGHT(C12,2)="54",CONCATENATE(LEFT(C12,2),"F9"),IF(RIGHT(C12,2)="55",CONCATENATE(LEFT(C12,2),"G0"),IF(RIGHT(C12,2)="56",CONCATENATE(LEFT(C12,2),"G1"),IF(RIGHT(C12,2)="57",CONCATENATE(LEFT(C12,2),"G2"),IF(RIGHT(C12,2)="58",CONCATENATE(LEFT(C12,2),"G3"),IF(RIGHT(C12,2)="59",CONCATENATE(LEFT(C12,2),"G4"),IF(RIGHT(C12,2)="60",CONCATENATE(LEFT(C12,2),"G5"),IF(RIGHT(C12,2)="61",CONCATENATE(LEFT(C12,2),"G6"),IF(RIGHT(C12,2)="62",CONCATENATE(LEFT(C12,2),"G7"),IF(RIGHT(C12,2)="63",CONCATENATE(LEFT(C12,2),"G8"),IF(RIGHT(C12,2)="64",CONCATENATE(LEFT(C12,2),"G9"),IF(RIGHT(C12,2)="65",CONCATENATE(LEFT(C12,2),"H0"),IF(RIGHT(C12,2)="66",CONCATENATE(LEFT(C12,2),"H1"),IF(RIGHT(C12,2)="67",CONCATENATE(LEFT(C12,2),"H2"),IF(RIGHT(C12,2)="68",CONCATENATE(LEFT(C12,2),"H3"),IF(RIGHT(C12,2)="68",CONCATENATE(LEFT(C12,2),"H4"),C12)))))))))))))))) -> 37G1 | H12: 22 | I12: 54 | J12: 25.22 | K12: 11 | L12: 31.07 | M12: 54 | N12: 23.61 | O12: 11 | P12: 30.54 | Q12: 0 | R12: 0 | S12: 0 | T12: 0 | U12: 0 | V12: 0 | W12: 0 | X12: 0 | Y12: 0 | Z12: 0 | AA12: 0 | AB12: 0 | AC12: 0 | AD12: 0 | AE12: 0 | AF12: 0 | AG12: 0 | AH12: 0 | AI12: 0 | AJ12: 0 | AK12: 0 | AL12: 0 | AM12: 0 | AN12: 0 | AO12: 0 | AP12: 0 | AQ12: 0 | AR12: 0 | AS12: 0 | AT12: 0 | AU12: 0 | AV12: 0 | AX12: 25 | AY12: 0 | AZ12: 0 | BA12: 0 | BB12: 0 | BC12: 0 | BD12: 0 | BE12: 0 | BF12: 0 | BG12: 0 | BH12: 0 | BI12: Solea | BJ12: GFR | BK12: No | BP12: 2 | BQ12: 1.6392851 | BR12: 2 | BS12: 5425.22 | BT12: 1131.07 | BU12: 3703 | BV12: 5602 | BW12: 5425 | BX12: 1130
A13: V | B13: 22013 | C13: 3856 | D13: =IF(K13=9,54,IF(K13=10,55,IF(K13=11,56,""))) -> 56 | E13: =IF(D13=_xlfn.NUMBERVALUE(RIGHT(C13,2)),"OK","") -> OK | F13: =CONCATENATE(LEFT(C13,2),D13) -> 3856 | G13: =IF(RIGHT(C13,2)="54",CONCATENATE(LEFT(C13,2),"F9"),IF(RIGHT(C13,2)="55",CONCATENATE(LEFT(C13,2),"G0"),IF(RIGHT(C13,2)="56",CONCATENATE(LEFT(C13,2),"G1"),IF(RIGHT(C13,2)="57",CONCATENATE(LEFT(C13,2),"G2"),IF(RIGHT(C13,2)="58",CONCATENATE(LEFT(C13,2),"G3"),IF(RIGHT(C13,2)="59",CONCATENATE(LEFT(C13,2),"G4"),IF(RIGHT(C13,2)="60",CONCATENATE(LEFT(C13,2),"G5"),IF(RIGHT(C13,2)="61",CONCATENATE(LEFT(C13,2),"G6"),IF(RIGHT(C13,2)="62",CONCATENATE(LEFT(C13,2),"G7"),IF(RIGHT(C13,2)="63",CONCATENATE(LEFT(C13,2),"G8"),IF(RIGHT(C13,2)="64",CONCATENATE(LEFT(C13,2),"G9"),IF(RIGHT(C13,2)="65",CONCATENATE(LEFT(C13,2),"H0"),IF(RIGHT(C13,2)="66",CONCATENATE(LEFT(C13,2),"H1"),IF(RIGHT(C13,2)="67",CONCATENATE(LEFT(C13,2),"H2"),IF(RIGHT(C13,2)="68",CONCATENATE(LEFT(C13,2),"H3"),IF(RIGHT(C13,2)="68",CONCATENATE(LEFT(C13,2),"H4"),C13)))))))))))))))) -> 38G1 | H13: 22 | I13: 54 | J13: 31.38 | K13: 11 | L13: 19.27 | M13: 54 | N13: 30.17 | O13: 11 | P13: 21.19 | Q13: 0 | R13: 0 | S13: 0 | T13: 0 | U13: 0 | V13: 0 | W13: 0 | X13: 0 | Y13: 0 | Z13: 0 | AA13: 0 | AB13: 0 | AC13: 0 | AD13: 0 | AE13: 0 | AF13: 0 | AG13: 0 | AH13: 0 | AI13: 0 | AJ13: 0 | AK13: 0 | AL13: 0 | AM13: 0 | AN13: 0 | AO13: 0 | AP13: 0 | AQ13: 0 | AR13: 0 | AS13: 0 | AT13: 0 | AU13: 0 | AV13: 0 | AW13: =IF(A13="",1,"") | AX13: 28 | AY13: 24 | AZ13: 14 | BA13: 0 | BB13: 0 | BC13: 0 | BD13: 0 | BE13: 0 | BF13: 0 | BG13: 0 | BH13: 0 | BI13: German R/V | BJ13: GFR | BK13: No | BL13: 0 | BM13: 0 | BN13: 1.6451222 | BP13: 2 | BQ13: 1.6451222 | BR13: 2 | BS13: 5431.38 | BT13: 1119.27 | BU13: 3801 | BV13: 5601 | BW13: 5435 | BX13: 1110
A14: V | B14: 22014 | C14: 3855 | D14: =IF(K14=9,54,IF(K14=10,55,IF(K14=11,56,""))) -> 55 | E14: =IF(D14=_xlfn.NUMBERVALUE(RIGHT(C14,2)),"OK","") -> OK | F14: =CONCATENATE(LEFT(C14,2),D14) -> 3855 | G14: =IF(RIGHT(C14,2)="54",CONCATENATE(LEFT(C14,2),"F9"),IF(RIGHT(C14,2)="55",CONCATENATE(LEFT(C14,2),"G0"),IF(RIGHT(C14,2)="56",CONCATENATE(LEFT(C14,2),"G1"),IF(RIGHT(C14,2)="57",CONCATENATE(LEFT(C14,2),"G2"),IF(RIGHT(C14,2)="58",CONCATENATE(LEFT(C14,2),"G3"),IF(RIGHT(C14,2)="59",CONCATENATE(LEFT(C14,2),"G4"),IF(RIGHT(C14,2)="60",CONCATENATE(LEFT(C14,2),"G5"),IF(RIGHT(C14,2)="61",CONCATENATE(LEFT(C14,2),"G6"),IF(RIGHT(C14,2)="62",CONCATENATE(LEFT(C14,2),"G7"),IF(RIGHT(C14,2)="63",CONCATENATE(LEFT(C14,2),"G8"),IF(RIGHT(C14,2)="64",CONCATENATE(LEFT(C14,2),"G9"),IF(RIGHT(C14,2)="65",CONCATENATE(LEFT(C14,2),"H0"),IF(RIGHT(C14,2)="66",CONCATENATE(LEFT(C14,2),"H1"),IF(RIGHT(C14,2)="67",CONCATENATE(LEFT(C14,2),"H2"),IF(RIGHT(C14,2)="68",CONCATENATE(LEFT(C14,2),"H3"),IF(RIGHT(C14,2)="68",CONCATENATE(LEFT(C14,2),"H4"),C14)))))))))))))))) -> 38G0 | H14: 22 | I14: 54 | J14: 37.16 | K14: 10 | L14: 39.03 | M14: 54 | N14: 35.53 | O14: 10 | P14: 39.03 | Q14: 0 | R14: 0 | S14: 0 | T14: 0 | U14: 0 | V14: 0 | W14: 0 | X14: 0 | Y14: 0 | Z14: 0 | AA14: 0 | AB14: 0 | AC14: 0 | AD14: 0 | AE14: 0 | AF14: 0 | AG14: 0 | AH14: 0 | AI14: 0 | AJ14: 0 | AK14: 0 | AL14: 0 | AM14: 0 | AN14: 0 | AO14: 0 | AP14: 0 | AQ14: 0 | AR14: 0 | AS14: 0 | AT14: 0 | AU14: 0 | AV14: 0 | AW14: =IF(A14="",1,"") | AX14: 19 | AY14: 19 | AZ14: 19 | BA14: 19 | BB14: 0 | BC14: 0 | BD14: 0 | BE14: 0 | BF14: 0 | BG14: 0 | BH14: 0 | BI14: Havfisken | BJ14: DEN | BK14: No | BL14: 1 | BM14: 0 | BN14: 1.63 | BP14: 1 | BQ14: 1.63 | BR14: 2 | BS14: 5437.16 | BT14: 1039.03 | BU14: 3801 | BV14: 5502 | BW14: 5435 | BX14: 1030
A15: V | B15: 22016 | C15: 3955 | D15: =IF(K15=9,54,IF(K15=10,55,IF(K15=11,56,""))) -> 55 | E15: =IF(D15=_xlfn.NUMBERVALUE(RIGHT(C15,2)),"OK","") -> OK | F15: =CONCATENATE(LEFT(C15,2),D15) -> 3955 | G15: =IF(RIGHT(C15,2)="54",CONCATENATE(LEFT(C15,2),"F9"),IF(RIGHT(C15,2)="55",CONCATENATE(LEFT(C15,2),"G0"),IF(RIGHT(C15,2)="56",CONCATENATE(LEFT(C15,2),"G1"),IF(RIGHT(C15,2)="57",CONCATENATE(LEFT(C15,2),"G2"),IF(RIGHT(C15,2)="58",CONCATENATE(LEFT(C15,2),"G3"),IF(RIGHT(C15,2)="59",CONCATENATE(LEFT(C15,2),"G4"),IF(RIGHT(C15,2)="60",CONCATENATE(LEFT(C15,2),"G5"),IF(RIGHT(C15,2)="61",CONCATENATE(LEFT(C15,2),"G6"),IF(RIGHT(C15,2)="62",CONCATENATE(LEFT(C15,2),"G7"),IF(RIGHT(C15,2)="63",CONCATENATE(LEFT(C15,2),"G8"),IF(RIGHT(C15,2)="64",CONCATENATE(LEFT(C15,2),"G9"),IF(RIGHT(C15,2)="65",CONCATENATE(LEFT(C15,2),"H0"),IF(RIGHT(C15,2)="66",CONCATENATE(LEFT(C15,2),"H1"),IF(RIGHT(C15,2)="67",CONCATENATE(LEFT(C15,2),"H2"),IF(RIGHT(C15,2)="68",CONCATENATE(LEFT(C15,2),"H3"),IF(RIGHT(C15,2)="68",CONCATENATE(LEFT(C15,2),"H4"),C15)))))))))))))))) -> 39G0 | H15: 22 | I15: 55 | J15: 5.9 | K15: 10 | L15: 48.7 | M15: 55 | N15: 3.7 | O15: 10 | P15: 46.7 | Q15: 0 | R15: 0 | S15: 0 | T15: 0 | U15: 0 | V15: 0 | W15: 0 | X15: 0 | Y15: 0 | Z15: 0 | AA15: 0 | AB15: 0 | AC15: 0 | AD15: 0 | AE15: 0 | AF15: 0 | AG15: 0 | AH15: 0 | AI15: 0 | AJ15: 0 | AK15: 0 | AL15: 0 | AM15: 0 | AN15: 0 | AO15: 0 | AP15: 0 | AQ15: 0 | AR15: 0 | AS15: 0 | AT15: 0 | AU15: 0 | AV15: 0 | AW15: =IF(A15="",1,"") | AX15: 13 | AY15: 13 | AZ15: 13 | BA15: 0 | BB15: 0 | BC15: 0 | BD15: 0 | BE15: 0 | BF15: 0 | BG15: 0 | BH15: 0 | BI15: Havfisken | BJ15: DEN | BK15: No | BL15: 0 | BM15: 1 | BN15: 2.4800633 | BP15: 1 | BQ15: 2.4800633 | BR15: 2 | BS15: 5505.9 | BT15: 1048.7 | BU15: 3901 | BV15: 5503 | BW15: 5505 | BX15: 1050
A16: V | B16: 22017 | C16: 3956 | D16: =IF(K16=9,54,IF(K16=10,55,IF(K16=11,56,""))) -> 56 | E16: =IF(D16=_xlfn.NUMBERVALUE(RIGHT(C16,2)),"OK","") -> OK | F16: =CONCATENATE(LEFT(C16,2),D16) -> 3956 | G16: =IF(RIGHT(C16,2)="54",CONCATENATE(LEFT(C16,2),"F9"),IF(RIGHT(C16,2)="55",CONCATENATE(LEFT(C16,2),"G0"),IF(RIGHT(C16,2)="56",CONCATENATE(LEFT(C16,2),"G1"),IF(RIGHT(C16,2)="57",CONCATENATE(LEFT(C16,2),"G2"),IF(RIGHT(C16,2)="58",CONCATENATE(LEFT(C16,2),"G3"),IF(RIGHT(C16,2)="59",CONCATENATE(LEFT(C16,2),"G4"),IF(RIGHT(C16,2)="60",CONCATENATE(LEFT(C16,2),"G5"),IF(RIGHT(C16,2)="61",CONCATENATE(LEFT(C16,2),"G6"),IF(RIGHT(C16,2)="62",CONCATENATE(LEFT(C16,2),"G7"),IF(RIGHT(C16,2)="63",CONCATENATE(LEFT(C16,2),"G8"),IF(RIGHT(C16,2)="64",CONCATENATE(LEFT(C16,2),"G9"),IF(RIGHT(C16,2)="65",CONCATENATE(LEFT(C16,2),"H0"),IF(RIGHT(C16,2)="66",CONCATENATE(LEFT(C16,2),"H1"),IF(RIGHT(C16,2)="67",CONCATENATE(LEFT(C16,2),"H2"),IF(RIGHT(C16,2)="68",CONCATENATE(LEFT(C16,2),"H3"),IF(RIGHT(C16,2)="68",CONCATENATE(LEFT(C16,2),"H4"),C16)))))))))))))))) -> 39G1 | H16: 22 | I16: 55 | J16: 0.41 | K16: 11 | L16: 3.57 | M16: 54 | N16: 58.2 | O16: 11 | P16: 1.55 | Q16: 0 | R16: 0 | S16: 0 | T16: 0 | U16: 0 | V16: 0 | W16: 0 | X16: 0 | Y16: 0 | Z16: 0 | AA16: 0 | AB16: 0 | AC16: 0 | AD16: 0 | AE16: 0 | AF16: 0 | AG16: 0 | AH16: 0 | AI16: 0 | AJ16: 0 | AK16: 0 | AL16: 0 | AM16: 0 | AN16: 0 | AO16: 0 | AP16: 0 | AQ16: 0 | AR16: 0 | AS16: 0 | AT16: 0 | AU16: 0 | AV16: 0 | AW16: =IF(A16="",1,"") | AX16: 15 | AY16: 14 | AZ16: 14 | BA16: 0 | BB16: 0 | BC16: 0 | BD16: 0 | BE16: 0 | BF16: 0 | BG16: 0 | BH16: 0 | BI16: German R/V | BJ16: DEN | BK16: No | BL16: 0 | BM16: 1 | BN16: 2.4954529 | BP16: 1 | BQ16: 2.4954529 | BR16: 2 | BS16: 5500.41 | BT16: 1103.57 | BU16: 3901 | BV16: 5601 | BW16: 5505 | BX16: 1110
A17: V | B17: 22018 | C17: 3956 | D17: =IF(K17=9,54,IF(K17=10,55,IF(K17=11,56,""))) -> 56 | E17: =IF(D17=_xlfn.NUMBERVALUE(RIGHT(C17,2)),"OK","") -> OK | F17: =CONCATENATE(LEFT(C17,2),D17) -> 3956 | G17: =IF(RIGHT(C17,2)="54",CONCATENATE(LEFT(C17,2),"F9"),IF(RIGHT(C17,2)="55",CONCATENATE(LEFT(C17,2),"G0"),IF(RIGHT(C17,2)="56",CONCATENATE(LEFT(C17,2),"G1"),IF(RIGHT(C17,2)="57",CONCATENATE(LEFT(C17,2),"G2"),IF(RIGHT(C17,2)="58",CONCATENATE(LEFT(C17,2),"G3"),IF(RIGHT(C17,2)="59",CONCATENATE(LEFT(C17,2),"G4"),IF(RIGHT(C17,2)="60",CONCATENATE(LEFT(C17,2),"G5"),IF(RIGHT(C17,2)="61",CONCATENATE(LEFT(C17,2),"G6"),IF(RIGHT(C17,2)="62",CONCATENATE(LEFT(C17,2),"G7"),IF(RIGHT(C17,2)="63",CONCATENATE(LEFT(C17,2),"G8"),IF(RIGHT(C17,2)="64",CONCATENATE(LEFT(C17,2),"G9"),IF(RIGHT(C17,2)="65",CONCATENATE(LEFT(C17,2),"H0"),IF(RIGHT(C17,2)="66",CONCATENATE(LEFT(C17,2),"H1"),IF(RIGHT(C17,2)="67",CONCATENATE(LEFT(C17,2),"H2"),IF(RIGHT(C17,2)="68",CONCATENATE(LEFT(C17,2),"H3"),IF(RIGHT(C17,2)="68",CONCATENATE(LEFT(C17,2),"H4"),C17)))))))))))))))) -> 39G1 | H17: 22 | I17: 55 | J17: 4.2 | K17: 11 | L17: 4.1 | M17: 55 | N17: 3.8 | O17: 11 | P17: 5 | Q17: 55 | R17: 3 | S17: 11 | T17: 5.6 | U17: 55 | V17: 2.6 | W17: 11 | X17: 6.7 | Y17: 0 | Z17: 0 | AA17: 0 | AB17: 0 | AC17: 0 | AD17: 0 | AE17: 0 | AF17: 0 | AG17: 0 | AH17: 0 | AI17: 0 | AJ17: 0 | AK17: 0 | AL17: 0 | AM17: 0 | AN17: 0 | AO17: 0 | AP17: 0 | AQ17: 0 | AR17: 0 | AS17: 0 | AT17: 0 | AU17: 0 | AV17: 0 | AW17: =IF(A17="",1,"") | AX17: 13 | AY17: 13 | AZ17: 13 | BA17: 13 | BB17: 13 | BC17: 0 | BD17: 0 | BE17: 0 | BF17: 0 | BG17: 0 | BH17: 0 | BI17: Havfisken | BJ17: DEN | BK17: No | BL17: 0 | BM17: 0 | BN17: 2.2694943 | BP17: 1 | BQ17: 2.2694943 | BR17: 2 | BS17: 5504.2 | BT17: 1104.1 | BU17: 3901 | BV17: 5601 | BW17: 5505 | BX17: 1110
A18: V | B18: 22019 | C18: 3956 | D18: =IF(K18=9,54,IF(K18=10,55,IF(K18=11,56,""))) -> 56 | E18: =IF(D18=_xlfn.NUMBERVALUE(RIGHT(C18,2)),"OK","") -> OK | F18: =CONCATENATE(LEFT(C18,2),D18) -> 3956 | G18: =IF(RIGHT(C18,2)="54",CONCATENATE(LEFT(C18,2),"F9"),IF(RIGHT(C18,2)="55",CONCATENATE(LEFT(C18,2),"G0"),IF(RIGHT(C18,2)="56",CONCATENATE(LEFT(C18,2),"G1"),IF(RIGHT(C18,2)="57",CONCATENATE(LEFT(C18,2),"G2"),IF(RIGHT(C18,2)="58",CONCATENATE(LEFT(C18,2),"G3"),IF(RIGHT(C18,2)="59",CONCATENATE(LEFT(C18,2),"G4"),IF(RIGHT(C18,2)="60",CONCATENATE(LEFT(C18,2),"G5"),IF(RIGHT(C18,2)="61",CONCATENATE(LEFT(C18,2),"G6"),IF(RIGHT(C18,2)="62",CONCATENATE(LEFT(C18,2),"G7"),IF(RIGHT(C18,2)="63",CONCATENATE(LEFT(C18,2),"G8"),IF(RIGHT(C18,2)="64",CONCATENATE(LEFT(C18,2),"G9"),IF(RIGHT(C18,2)="65",CONCATENATE(LEFT(C18,2),"H0"),IF(RIGHT(C18,2)="66",CONCATENATE(LEFT(C18,2),"H1"),IF(RIGHT(C18,2)="67",CONCATENATE(LEFT(C18,2),"H2"),IF(RIGHT(C18,2)="68",CONCATENATE(LEFT(C18,2),"H3"),IF(RIGHT(C18,2)="68",CONCATENATE(LEFT(C18,2),"H4"),C18)))))))))))))))) -> 39G1 | H18: 22 | I18: 55 | J18: 3.44 | K18: 11 | L18: 24.15 | M18: 55 | N18: 2.81 | O18: 11 | P18: 19.93 | Q18: 0 | R18: 0 | S18: 0 | T18: 0 | U18: 0 | V18: 0 | W18: 0 | X18: 0 | Y18: 0 | Z18: 0 | AA18: 0 | AB18: 0 | AC18: 0 | AD18: 0 | AE18: 0 | AF18: 0 | AG18: 0 | AH18: 0 | AI18: 0 | AJ18: 0 | AK18: 0 | AL18: 0 | AM18: 0 | AN18: 0 | AO18: 0 | AP18: 0 | AQ18: 0 | AR18: 0 | AS18: 0 | AT18: 0 | AU18: 0 | AV18: 0 | AW18: =IF(A18="",1,"") | AX18: 17 | AY18: 19 | AZ18: 18 | BA18: 0 | BB18: 0 | BC18: 0 | BD18: 0 | BE18: 0 | BF18: 0 | BG18: 0 | BH18: 0 | BI18: German R/V | BJ18: DEN | BK18: No | BL18: 0 | BM18: 1 | BN18: 2.4980946 | BP18: 1 | BQ18: 2.4980946 | BR18: 2 | BS18: 5503.44 | BT18: 1124.15 | BU18: 3901 | BV18: 5602 | BW18: 5505 | BX18: 1130
A19: V | B19: 22020 | C19: 3955 | D19: =IF(K19=9,54,IF(K19=10,55,IF(K19=11,56,""))) -> 55 | E19: =IF(D19=_xlfn.NUMBERVALUE(RIGHT(C19,2)),"OK","") -> OK | F19: =CONCATENATE(LEFT(C19,2),D19) -> 3955 | G19: =IF(RIGHT(C19,2)="54",CONCATENATE(LEFT(C19,2),"F9"),IF(RIGHT(C19,2)="55",CONCATENATE(LEFT(C19,2),"G0"),IF(RIGHT(C19,2)="56",CONCATENATE(LEFT(C19,2),"G1"),IF(RIGHT(C19,2)="57",CONCATENATE(LEFT(C19,2),"G2"),IF(RIGHT(C19,2)="58",CONCATENATE(LEFT(C19,2),"G3"),IF(RIGHT(C19,2)="59",CONCATENATE(LEFT(C19,2),"G4"),IF(RIGHT(C19,2)="60",CONCATENATE(LEFT(C19,2),"G5"),IF(RIGHT(C19,2)="61",CONCATENATE(LEFT(C19,2),"G6"),IF(RIGHT(C19,2)="62",CONCATENATE(LEFT(C19,2),"G7"),IF(RIGHT(C19,2)="63",CONCATENATE(LEFT(C19,2),"G8"),IF(RIGHT(C19,2)="64",CONCATENATE(LEFT(C19,2),"G9"),IF(RIGHT(C19,2)="65",CONCATENATE(LEFT(C19,2),"H0"),IF(RIGHT(C19,2)="66",CONCATENATE(LEFT(C19,2),"H1"),IF(RIGHT(C19,2)="67",CONCATENATE(LEFT(C19,2),"H2"),IF(RIGHT(C19,2)="68",CONCATENATE(LEFT(C19,2),"H3"),IF(RIGHT(C19,2)="68",CONCATENATE(LEFT(C19,2),"H4"),C19)))))))))))))))) -> 39G0 | H19: 22 | I19: 55 | J19: 12.7 | K19: 10 | L19: 56.3 | M19: 55 | N19: 13.5 | O19: 10 | P19: 57.3 | Q19: 55 | R19: 13.7 | S19: 10 | T19: 59.2 | U19: 55 | V19: 14.2 | W19: 10 | X19: 59.6 | Y19: 0 | Z19: 0 | AA19: 0 | AB19: 0 | AC19: 0 | AD19: 0 | AE19: 0 | AF19: 0 | AG19: 0 | AH19: 0 | AI19: 0 | AJ19: 0 | AK19: 0 | AL19: 0 | AM19: 0 | AN19: 0 | AO19: 0 | AP19: 0 | AQ19: 0 | AR19: 0 | AS19: 0 | AT19: 0 | AU19: 0 | AV19: 0 | AW19: =IF(A19="",1,"") | AX19: 18 | AY19: 18 | AZ19: 18 | BA19: 18 | BB19: 18 | BC19: 0 | BD19: 0 | BE19: 0 | BF19: 0 | BG19: 0 | BH19: 0 | BI19: Havfisken | BJ19: DEN | BK19: No | BL19: 0 | BM19: 0 | BN19: 2.6340581 | BP19: 1 | BQ19: 2.6340581 | BR19: 2 | BS19: 5512.7 | BT19: 1056.3 | BU19: 3902 | BV19: 5503 | BW19: 5515 | BX19: 1050
A20: V | B20: 22021 | C20: 3955 | D20: =IF(K20=9,54,IF(K20=10,55,IF(K20=11,56,""))) -> 55 | E20: =IF(D20=_xlfn.NUMBERVALUE(RIGHT(C20,2)),"OK","") -> OK | F20: =CONCATENATE(LEFT(C20,2),D20) -> 3955 | G20: =IF(RIGHT(C20,2)="54",CONCATENATE(LEFT(C20,2),"F9"),IF(RIGHT(C20,2)="55",CONCATENATE(LEFT(C20,2),"G0"),IF(RIGHT(C20,2)="56",CONCATENATE(LEFT(C20,2),"G1"),IF(RIGHT(C20,2)="57",CONCATENATE(LEFT(C20,2),"G2"),IF(RIGHT(C20,2)="58",CONCATENATE(LEFT(C20,2),"G3"),IF(RIGHT(C20,2)="59",CONCATENATE(LEFT(C20,2),"G4"),IF(RIGHT(C20,2)="60",CONCATENATE(LEFT(C20,2),"G5"),IF(RIGHT(C20,2)="61",CONCATENATE(LEFT(C20,2),"G6"),IF(RIGHT(C20,2)="62",CONCATENATE(LEFT(C20,2),"G7"),IF(RIGHT(C20,2)="63",CONCATENATE(LEFT(C20,2),"G8"),IF(RIGHT(C20,2)="64",CONCATENATE(LEFT(C20,2),"G9"),IF(RIGHT(C20,2)="65",CONCATENATE(LEFT(C20,2),"H0"),IF(RIGHT(C20,2)="66",CONCATENATE(LEFT(C20,2),"H1"),IF(RIGHT(C20,2)="67",CONCATENATE(LEFT(C20,2),"H2"),IF(RIGHT(C20,2)="68",CONCATENATE(LEFT(C20,2),"H3"),IF(RIGHT(C20,2)="68",CONCATENATE(LEFT(C20,2),"H4"),C20)))))))))))))))) -> 39G0 | H20: 22 | I20: 55 | J20: 14.9 | K20: 10 | L20: 50.7 | M20: 55 | N20: 14.2 | O20: 10 | P20: 50.4 | Q20: 55 | R20: 13.3 | S20: 10 | T20: 50.3 | U20: 55 | V20: 12.9 | W20: 10 | X20: 50.1 | Y20: 0 | Z20: 0 | AA20: 0 | AB20: 0 | AC20: 0 | AD20: 0 | AE20: 0 | AF20: 0 | AG20: 0 | AH20: 0 | AI20: 0 | AJ20: 0 | AK20: 0 | AL20: 0 | AM20: 0 | AN20: 0 | AO20: 0 | AP20: 0 | AQ20: 0 | AR20: 0 | AS20: 0 | AT20: 0 | AU20: 0 | AV20: 0 | AW20: =IF(A20="",1,"") | AX20: 20 | AY20: 20 | AZ20: 20 | BA20: 20 | BB20: 20 | BC20: 0 | BD20: 0 | BE20: 0 | BF20: 0 | BG20: 0 | BH20: 0 | BI20: Havfisken | BJ20: DEN | BK20: No | BL20: 0 | BM20: 1 | BN20: 2.0383489 | BP20: 1 | BQ20: 2.0383489 | BR20: 2 | BS20: 5514.9 | BT20: 1050.7 | BU20: 3902 | BV20: 5503 | BW20: 5515 | BX20: 1050
A21: V | B21: 22022 | C21: 3956 | D21: =IF(K21=9,54,IF(K21=10,55,IF(K21=11,56,""))) -> 56 | E21: =IF(D21=_xlfn.NUMBERVALUE(RIGHT(C21,2)),"OK","") -> OK | F21: =CONCATENATE(LEFT(C21,2),D21) -> 3956 | G21: =IF(RIGHT(C21,2)="54",CONCATENATE(LEFT(C21,2),"F9"),IF(RIGHT(C21,2)="55",CONCATENATE(LEFT(C21,2),"G0"),IF(RIGHT(C21,2)="56",CONCATENATE(LEFT(C21,2),"G1"),IF(RIGHT(C21,2)="57",CONCATENATE(LEFT(C21,2),"G2"),IF(RIGHT(C21,2)="58",CONCATENATE(LEFT(C21,2),"G3"),IF(RIGHT(C21,2)="59",CONCATENATE(LEFT(C21,2),"G4"),IF(RIGHT(C21,2)="60",CONCATENATE(LEFT(C21,2),"G5"),IF(RIGHT(C21,2)="61",CONCATENATE(LEFT(C21,2),"G6"),IF(RIGHT(C21,2)="62",CONCATENATE(LEFT(C21,2),"G7"),IF(RIGHT(C21,2)="63",CONCATENATE(LEFT(C21,2),"G8"),IF(RIGHT(C21,2)="64",CONCATENATE(LEFT(C21,2),"G9"),IF(RIGHT(C21,2)="65",CONCATENATE(LEFT(C21,2),"H0"),IF(RIGHT(C21,2)="66",CONCATENATE(LEFT(C21,2),"H1"),IF(RIGHT(C21,2)="67",CONCATENATE(LEFT(C21,2),"H2"),IF(RIGHT(C21,2)="68",CONCATENATE(LEFT(C21,2),"H3"),IF(RIGHT(C21,2)="68",CONCATENATE(LEFT(C21,2),"H4"),C21)))))))))))))))) -> 39G1 | H21: 22 | I21: 55 | J21: 14.7 | K21: 11 | L21: 3.3 | M21: 55 | N21: 14.3 | O21: 11 | P21: 1.5 | Q21: 55 | R21: 13 | S21: 11 | T21: 0.6 | U21: 0 | V21: 0 | W21: 0 | X21: 0 | Y21: 0 | Z21: 0 | AA21: 0 | AB21: 0 | AC21: 0 | AD21: 0 | AE21: 0 | AF21: 0 | AG21: 0 | AH21: 0 | AI21: 0 | AJ21: 0 | AK21: 0 | AL21: 0 | AM21: 0 | AN21: 0 | AO21: 0 | AP21: 0 | AQ21: 0 | AR21: 0 | AS21: 0 | AT21: 0 | AU21: 0 | AV21: 0 | AW21: =IF(A21="",1,"") | AX21: 19 | AY21: 19 | AZ21: 19 | BA21: 19 | BB21: 0 | BC21: 0 | BD21: 0 | BE21: 0 | BF21: 0 | BG21: 0 | BH21: 0 | BI21: Havfisken | BJ21: DEN | BK21: No | BL21: 0 | BM21: 1 | BN21: 2.4990744 | BP21: 1 | BQ21: 2.4990744 | BR21: 2 | BS21: 5514.7 | BT21: 1103.3 | BU21: 3902 | BV21: 5601 | BW21: 5515 | BX21: 1110
A22: V | B22: 22023 | C22: 3956 | D22: =IF(K22=9,54,IF(K22=10,55,IF(K22=11,56,""))) -> 56 | E22: =IF(D22=_xlfn.NUMBERVALUE(RIGHT(C22,2)),"OK","") -> OK | F22: =CONCATENATE(LEFT(C22,2),D22) -> 3956 | G22: =IF(RIGHT(C22,2)="54",CONCATENATE(LEFT(C22,2),"F9"),IF(RIGHT(C22,2)="55",CONCATENATE(LEFT(C22,2),"G0"),IF(RIGHT(C22,2)="56",CONCATENATE(LEFT(C22,2),"G1"),IF(RIGHT(C22,2)="57",CONCATENATE(LEFT(C22,2),"G2"),IF(RIGHT(C22,2)="58",CONCATENATE(LEFT(C22,2),"G3"),IF(RIGHT(C22,2)="59",CONCATENATE(LEFT(C22,2),"G4"),IF(RIGHT(C22,2)="60",CONCATENATE(LEFT(C22,2),"G5"),IF(RIGHT(C22,2)="61",CONCATENATE(LEFT(C22,2),"G6"),IF(RIGHT(C22,2)="62",CONCATENATE(LEFT(C22,2),"G7"),IF(RIGHT(C22,2)="63",CONCATENATE(LEFT(C22,2),"G8"),IF(RIGHT(C22,2)="64",CONCATENATE(LEFT(C22,2),"G9"),IF(RIGHT(C22,2)="65",CONCATENATE(LEFT(C22,2),"H0"),IF(RIGHT(C22,2)="66",CONCATENATE(LEFT(C22,2),"H1"),IF(RIGHT(C22,2)="67",CONCATENATE(LEFT(C22,2),"H2"),IF(RIGHT(C22,2)="68",CONCATENATE(LEFT(C22,2),"H3"),IF(RIGHT(C22,2)="68",CONCATENATE(LEFT(C22,2),"H4"),C22)))))))))))))))) -> 39G1 | H22: 22 | I22: 55 | J22: 18.47 | K22: 11 | L22: 1.28 | M22: 55 | N22: 16.01 | O22: 11 | P22: 2.03 | Q22: 0 | R22: 0 | S22: 0 | T22: 0 | U22: 0 | V22: 0 | W22: 0 | X22: 0 | Y22: 0 | Z22: 0 | AA22: 0 | AB22: 0 | AC22: 0 | AD22: 0 | AE22: 0 | AF22: 0 | AG22: 0 | AH22: 0 | AI22: 0 | AJ22: 0 | AK22: 0 | AL22: 0 | AM22: 0 | AN22: 0 | AO22: 0 | AP22: 0 | AQ22: 0 | AR22: 0 | AS22: 0 | AT22: 0 | AU22: 0 | AV22: 0 | AW22: =IF(A22="",1,"") | AX22: 15 | AY22: 23 | AZ22: 34 | BA22: 0 | BB22: 0 | BC22: 0 | BD22: 0 | BE22: 0 | BF22: 0 | BG22: 0 | BH22: 0 | BI22: German R/V | BJ22: DEN | BK22: No | BL22: 0 | BM22: 0 | BN22: 2.4968001 | BP22: 1 | BQ22: 2.4968001 | BR22: 2 | BS22: 5518.47 | BT22: 1101.28 | BU22: 3902 | BV22: 5601 | BW22: 5515 | BX22: 1110
A23: V | B23: 22024 | C23: 3954 | D23: =IF(K23=9,54,IF(K23=10,55,IF(K23=11,56,""))) -> 54 | E23: =IF(D23=_xlfn.NUMBERVALUE(RIGHT(C23,2)),"OK","") -> OK | F23: =CONCATENATE(LEFT(C23,2),D23) -> 3954 | G23: =IF(RIGHT(C23,2)="54",CONCATENATE(LEFT(C23,2),"F9"),IF(RIGHT(C23,2)="55",CONCATENATE(LEFT(C23,2),"G0"),IF(RIGHT(C23,2)="56",CONCATENATE(LEFT(C23,2),"G1"),IF(RIGHT(C23,2)="57",CONCATENATE(LEFT(C23,2),"G2"),IF(RIGHT(C23,2)="58",CONCATENATE(LEFT(C23,2),"G3"),IF(RIGHT(C23,2)="59",CONCATENATE(LEFT(C23,2),"G4"),IF(RIGHT(C23,2)="60",CONCATENATE(LEFT(C23,2),"G5"),IF(RIGHT(C23,2)="61",CONCATENATE(LEFT(C23,2),"G6"),IF(RIGHT(C23,2)="62",CONCATENATE(LEFT(C23,2),"G7"),IF(RIGHT(C23,2)="63",CONCATENATE(LEFT(C23,2),"G8"),IF(RIGHT(C23,2)="64",CONCATENATE(LEFT(C23,2),"G9"),IF(RIGHT(C23,2)="65",CONCATENATE(LEFT(C23,2),"H0"),IF(RIGHT(C23,2)="66",CONCATENATE(LEFT(C23,2),"H1"),IF(RIGHT(C23,2)="67",CONCATENATE(LEFT(C23,2),"H2"),IF(RIGHT(C23,2)="68",CONCATENATE(LEFT(C23,2),"H3"),IF(RIGHT(C23,2)="68",CONCATENATE(LEFT(C23,2),"H4"),C23)))))))))))))))) -> 39F9 | H23: 22 | I23: 55 | J23: 21.9 | K23: 9 | L23: 45.16 | M23: 55 | N23: 24.1 | O23: 9 | P23: 43.94 | Q23: 0 | R23: 0 | S23: 0 | T23: 0 | U23: 0 | V23: 0 | W23: 0 | X23: 0 | Y23: 0 | Z23: 0 | AA23: 0 | AB23: 0 | AC23: 0 | AD23: 0 | AE23: 0 | AF23: 0 | AG23: 0 | AH23: 0 | AI23: 0 | AJ23: 0 | AK23: 0 | AL23: 0 | AM23: 0 | AN23: 0 | AO23: 0 | AP23: 0 | AQ23: 0 | AR23: 0 | AS23: 0 | AT23: 0 | AU23: 0 | AV23: 0 | AW23: =IF(A23="",1,"") | AX23: 18 | AY23: 18 | AZ23: 18 | BA23: 0 | BB23: 0 | BC23: 0 | BD23: 0 | BE23: 0 | BF23: 0 | BG23: 0 | BH23: 0 | BI23: Havfisken | BJ23: DEN | BK23: No | BL23: 0 | BM23: 1 | BN23: 2.3065849 | BP23: 1 | BQ23: 2.3065849 | BR23: 2 | BS23: 5521.9 | BT23: 945.16 | BU23: 3903 | BV23: 5403 | BW23: 5525 | BX23: 950
A24: V | B24: 22025 | C24: 3955 | D24: =IF(K24=9,54,IF(K24=10,55,IF(K24=11,56,""))) -> 55 | E24: =IF(D24=_xlfn.NUMBERVALUE(RIGHT(C24,2)),"OK","") -> OK | F24: =CONCATENATE(LEFT(C24,2),D24) -> 3955 | G24: =IF(RIGHT(C24,2)="54",CONCATENATE(LEFT(C24,2),"F9"),IF(RIGHT(C24,2)="55",CONCATENATE(LEFT(C24,2),"G0"),IF(RIGHT(C24,2)="56",CONCATENATE(LEFT(C24,2),"G1"),IF(RIGHT(C24,2)="57",CONCATENATE(LEFT(C24,2),"G2"),IF(RIGHT(C24,2)="58",CONCATENATE(LEFT(C24,2),"G3"),IF(RIGHT(C24,2)="59",CONCATENATE(LEFT(C24,2),"G4"),IF(RIGHT(C24,2)="60",CONCATENATE(LEFT(C24,2),"G5"),IF(RIGHT(C24,2)="61",CONCATENATE(LEFT(C24,2),"G6"),IF(RIGHT(C24,2)="62",CONCATENATE(LEFT(C24,2),"G7"),IF(RIGHT(C24,2)="63",CONCATENATE(LEFT(C24,2),"G8"),IF(RIGHT(C24,2)="64",CONCATENATE(LEFT(C24,2),"G9"),IF(RIGHT(C24,2)="65",CONCATENATE(LEFT(C24,2),"H0"),IF(RIGHT(C24,2)="66",CONCATENATE(LEFT(C24,2),"H1"),IF(RIGHT(C24,2)="67",CONCATENATE(LEFT(C24,2),"H2"),IF(RIGHT(C24,2)="68",CONCATENATE(LEFT(C24,2),"H3"),IF(RIGHT(C24,2)="68",CONCATENATE(LEFT(C24,2),"H4"),C24)))))))))))))))) -> 39G0 | H24: 22 | I24: 55 | J24: 23.14 | K24: 10 | L24: 50.56 | M24: 55 | N24: 22.97 | O24: 10 | P24: 54.95 | Q24: 0 | R24: 0 | S24: 0 | T24: 0 | U24: 0 | V24: 0 | W24: 0 | X24: 0 | Y24: 0 | Z24: 0 | AA24: 0 | AB24: 0 | AC24: 0 | AD24: 0 | AE24: 0 | AF24: 0 | AG24: 0 | AH24: 0 | AI24: 0 | AJ24: 0 | AK24: 0 | AL24: 0 | AM24: 0 | AN24: 0 | AO24: 0 | AP24: 0 | AQ24: 0 | AR24: 0 | AS24: 0 | AT24: 0 | AU24: 0 | AV24: 0 | AW24: =IF(A24="",1,"") | AX24: 19 | AY24: 16 | AZ24: 18 | BA24: 0 | BB24: 0 | BC24: 0 | BD24: 0 | BE24: 0 | BF24: 0 | BG24: 0 | BH24: 0 | BI24: German R/V | BJ24: DEN | BK24: No | BL24: 0 | BM24: 0 | BN24: 2.4996148 | BP24: 1 | BQ24: 2.4996148 | BR24: 2 | BS24: 5523.14 | BT24: 1050.56 | BU24: 3903 | BV24: 5503 | BW24: 5525 | BX24: 1050
... A53: V | B53: 22064 | C53: 3855 | D53: =IF(K53=9,54,IF(K53=10,55,IF(K53=11,56,""))) -> 55 | E53: =IF(D53=_xlfn.NUMBERVALUE(RIGHT(C53,2)),"OK","") -> OK | F53: =CONCATENATE(LEFT(C53,2),D53) -> 3855 | G53: =IF(RIGHT(C53,2)="54",CONCATENATE(LEFT(C53,2),"F9"),IF(RIGHT(C53,2)="55",CONCATENATE(LEFT(C53,2),"G0"),IF(RIGHT(C53,2)="56",CONCATENATE(LEFT(C53,2),"G1"),IF(RIGHT(C53,2)="57",CONCATENATE(LEFT(C53,2),"G2"),IF(RIGHT(C53,2)="58",CONCATENATE(LEFT(C53,2),"G3"),IF(RIGHT(C53,2)="59",CONCATENATE(LEFT(C53,2),"G4"),IF(RIGHT(C53,2)="60",CONCATENATE(LEFT(C53,2),"G5"),IF(RIGHT(C53,2)="61",CONCATENATE(LEFT(C53,2),"G6"),IF(RIGHT(C53,2)="62",CONCATENATE(LEFT(C53,2),"G7"),IF(RIGHT(C53,2)="63",CONCATENATE(LEFT(C53,2),"G8"),IF(RIGHT(C53,2)="64",CONCATENATE(LEFT(C53,2),"G9"),IF(RIGHT(C53,2)="65",CONCATENATE(LEFT(C53,2),"H0"),IF(RIGHT(C53,2)="66",CONCATENATE(LEFT(C53,2),"H1"),IF(RIGHT(C53,2)="67",CONCATENATE(LEFT(C53,2),"H2"),IF(RIGHT(C53,2)="68",CONCATENATE(LEFT(C53,2),"H3"),IF(RIGHT(C53,2)="68",CONCATENATE(LEFT(C53,2),"H4"),C53)))))))))))))))) -> 38G0 | H53: 22 | I53: 54 | J53: 37.66 | K53: 10 | L53: 19.84 | M53: 54 | N53: 40.23 | O53: 10 | P53: 21.25 | Q53: 0 | R53: 0 | S53: 0 | T53: 0 | U53: 0 | V53: 0 | W53: 0 | X53: 0 | Y53: 0 | Z53: 0 | AA53: 0 | AB53: 0 | AC53: 0 | AD53: 0 | AE53: 0 | AF53: 0 | AG53: 0 | AH53: 0 | AI53: 0 | AJ53: 0 | AK53: 0 | AL53: 0 | AM53: 0 | AN53: 0 | AO53: 0 | AP53: 0 | AQ53: 0 | AR53: 0 | AS53: 0 | AT53: 0 | AU53: 0 | AV53: 0 | AW53: =IF(A53="",1,"") | AX53: 21 | AY53: 31 | AZ53: 23 | BA53: 0 | BB53: 0 | BC53: 0 | BD53: 0 | BE53: 0 | BF53: 0 | BG53: 0 | BH53: 0 | BI53: German R/V | BJ53: GFR | BK53: No | BL53: 1 | BM53: 0 | BN53: 2.6963739 | BP53: 2 | BQ53: 2.6963739 | BR53: 2 | BS53: 5437.66 | BT53: 1019.84 | BU53: 3801 | BV53: 5501 | BW53: 5435 | BX53: 1010
A54: V | B54: 22065 | C54: 38G0 | D54: =IF(K54=9,54,IF(K54=10,55,IF(K54=11,56,""))) -> 55 | E54: =IF(D54=_xlfn.NUMBERVALUE(RIGHT(C54,2)),"OK","") -> #VALUE! | F54: =CONCATENATE(LEFT(C54,2),D54) -> 3855 | G54: =IF(RIGHT(C54,2)="54",CONCATENATE(LEFT(C54,2),"F9"),IF(RIGHT(C54,2)="55",CONCATENATE(LEFT(C54,2),"G0"),IF(RIGHT(C54,2)="56",CONCATENATE(LEFT(C54,2),"G1"),IF(RIGHT(C54,2)="57",CONCATENATE(LEFT(C54,2),"G2"),IF(RIGHT(C54,2)="58",CONCATENATE(LEFT(C54,2),"G3"),IF(RIGHT(C54,2)="59",CONCATENATE(LEFT(C54,2),"G4"),IF(RIGHT(C54,2)="60",CONCATENATE(LEFT(C54,2),"G5"),IF(RIGHT(C54,2)="61",CONCATENATE(LEFT(C54,2),"G6"),IF(RIGHT(C54,2)="62",CONCATENATE(LEFT(C54,2),"G7"),IF(RIGHT(C54,2)="63",CONCATENATE(LEFT(C54,2),"G8"),IF(RIGHT(C54,2)="64",CONCATENATE(LEFT(C54,2),"G9"),IF(RIGHT(C54,2)="65",CONCATENATE(LEFT(C54,2),"H0"),IF(RIGHT(C54,2)="66",CONCATENATE(LEFT(C54,2),"H1"),IF(RIGHT(C54,2)="67",CONCATENATE(LEFT(C54,2),"H2"),IF(RIGHT(C54,2)="68",CONCATENATE(LEFT(C54,2),"H3"),IF(RIGHT(C54,2)="68",CONCATENATE(LEFT(C54,2),"H4"),C54)))))))))))))))) -> 38G0 | H54: 22 | I54: 54 | J54: 36.4 | K54: 10 | L54: 38.58 | M54: 54 | N54: 37.99 | O54: 10 | P54: 35.24 | Q54: 0 | R54: 0 | S54: 0 | T54: 0 | U54: 0 | V54: 0 | W54: 0 | X54: 0 | Y54: 0 | Z54: 0 | AA54: 0 | AB54: 0 | AC54: 0 | AD54: 0 | AE54: 0 | AF54: 0 | AG54: 0 | AH54: 0 | AI54: 0 | AJ54: 0 | AK54: 0 | AL54: 0 | AM54: 0 | AN54: 0 | AO54: 0 | AP54: 0 | AQ54: 0 | AR54: 0 | AS54: 0 | AT54: 0 | AU54: 0 | AV54: 0 | AW54: =IF(A54="",1,"") | AX54: 25 | AY54: 24 | AZ54: 23 | BA54: 0 | BB54: 0 | BC54: 0 | BD54: 0 | BE54: 0 | BF54: 0 | BG54: 0 | BH54: 0 | BI54: German R/V | BJ54: DEN | BK54: No | BL54: 1 | BM54: 1 | BN54: 2.5035745 | BP54: 1 | BQ54: 2.5035745 | BR54: 2 | BS54: 5436.4 | BT54: 1038.58 | BU54: 3801 | BV54: 5502 | BW54: 5435 | BX54: 1030
A55: V | B55: 22071 | C55: 3856 | D55: =IF(K55=9,54,IF(K55=10,55,IF(K55=11,56,""))) -> 56 | E55: =IF(D55=_xlfn.NUMBERVALUE(RIGHT(C55,2)),"OK","") -> OK | F55: =CONCATENATE(LEFT(C55,2),D55) -> 3856 | G55: =IF(RIGHT(C55,2)="54",CONCATENATE(LEFT(C55,2),"F9"),IF(RIGHT(C55,2)="55",CONCATENATE(LEFT(C55,2),"G0"),IF(RIGHT(C55,2)="56",CONCATENATE(LEFT(C55,2),"G1"),IF(RIGHT(C55,2)="57",CONCATENATE(LEFT(C55,2),"G2"),IF(RIGHT(C55,2)="58",CONCATENATE(LEFT(C55,2),"G3"),IF(RIGHT(C55,2)="59",CONCATENATE(LEFT(C55,2),"G4"),IF(RIGHT(C55,2)="60",CONCATENATE(LEFT(C55,2),"G5"),IF(RIGHT(C55,2)="61",CONCATENATE(LEFT(C55,2),"G6"),IF(RIGHT(C55,2)="62",CONCATENATE(LEFT(C55,2),"G7"),IF(RIGHT(C55,2)="63",CONCATENATE(LEFT(C55,2),"G8"),IF(RIGHT(C55,2)="64",CONCATENATE(LEFT(C55,2),"G9"),IF(RIGHT(C55,2)="65",CONCATENATE(LEFT(C55,2),"H0"),IF(RIGHT(C55,2)="66",CONCATENATE(LEFT(C55,2),"H1"),IF(RIGHT(C55,2)="67",CONCATENATE(LEFT(C55,2),"H2"),IF(RIGHT(C55,2)="68",CONCATENATE(LEFT(C55,2),"H3"),IF(RIGHT(C55,2)="68",CONCATENATE(LEFT(C55,2),"H4"),C55)))))))))))))))) -> 38G1 | H55: 22 | I55: 54 | J55: 32.4 | K55: 11 | L55: 24.4 | M55: 54 | N55: 31.4 | O55: 11 | P55: 27.3 | Q55: 54 | R55: 30.6 | S55: 11 | T55: 28.1 | U55: 0 | V55: 0 | W55: 0 | X55: 0 | Y55: 0 | Z55: 0 | AA55: 0 | AB55: 0 | AC55: 0 | AD55: 0 | AE55: 0 | AF55: 0 | AG55: 0 | AH55: 0 | AI55: 0 | AJ55: 0 | AK55: 0 | AL55: 0 | AM55: 0 | AN55: 0 | AO55: 0 | AP55: 0 | AQ55: 0 | AR55: 0 | AS55: 0 | AT55: 0 | AU55: 0 | AV55: 0 | AW55: =IF(A55="",1,"") | AX55: 28 | AY55: 28 | AZ55: 28 | BA55: 28 | BB55: 0 | BC55: 0 | BD55: 0 | BE55: 0 | BF55: 0 | BG55: 0 | BH55: 0 | BI55: Havfisken | BJ55: DEN | BK55: No | BL55: 1 | BM55: 0 | BN55: 2.8824545 | BP55: 2 | BQ55: 2.8824545 | BR55: 2 | BS55: 5432.4 | BT55: 1124.4 | BU55: 3801 | BV55: 5602 | BW55: 5435 | BX55: 1130
A56: V | B56: 22072 | C56: 3856 | D56: =IF(K56=9,54,IF(K56=10,55,IF(K56=11,56,""))) -> 56 | E56: =IF(D56=_xlfn.NUMBERVALUE(RIGHT(C56,2)),"OK","") -> OK | F56: =CONCATENATE(LEFT(C56,2),D56) -> 3856 | G56: =IF(RIGHT(C56,2)="54",CONCATENATE(LEFT(C56,2),"F9"),IF(RIGHT(C56,2)="55",CONCATENATE(LEFT(C56,2),"G0"),IF(RIGHT(C56,2)="56",CONCATENATE(LEFT(C56,2),"G1"),IF(RIGHT(C56,2)="57",CONCATENATE(LEFT(C56,2),"G2"),IF(RIGHT(C56,2)="58",CONCATENATE(LEFT(C56,2),"G3"),IF(RIGHT(C56,2)="59",CONCATENATE(LEFT(C56,2),"G4"),IF(RIGHT(C56,2)="60",CONCATENATE(LEFT(C56,2),"G5"),IF(RIGHT(C56,2)="61",CONCATENATE(LEFT(C56,2),"G6"),IF(RIGHT(C56,2)="62",CONCATENATE(LEFT(C56,2),"G7"),IF(RIGHT(C56,2)="63",CONCATENATE(LEFT(C56,2),"G8"),IF(RIGHT(C56,2)="64",CONCATENATE(LEFT(C56,2),"G9"),IF(RIGHT(C56,2)="65",CONCATENATE(LEFT(C56,2),"H0"),IF(RIGHT(C56,2)="66",CONCATENATE(LEFT(C56,2),"H1"),IF(RIGHT(C56,2)="67",CONCATENATE(LEFT(C56,2),"H2"),IF(RIGHT(C56,2)="68",CONCATENATE(LEFT(C56,2),"H3"),IF(RIGHT(C56,2)="68",CONCATENATE(LEFT(C56,2),"H4"),C56)))))))))))))))) -> 38G1 | H56: 22 | I56: 54 | J56: 33.53 | K56: 11 | L56: 21.74 | M56: 54 | N56: 32.54 | O56: 11 | P56: 23.82 | Q56: 0 | R56: 0 | S56: 0 | T56: 0 | U56: 0 | V56: 0 | W56: 0 | X56: 0 | Y56: 0 | Z56: 0 | AA56: 0 | AB56: 0 | AC56: 0 | AD56: 0 | AE56: 0 | AF56: 0 | AG56: 0 | AH56: 0 | AI56: 0 | AJ56: 0 | AK56: 0 | AL56: 0 | AM56: 0 | AN56: 0 | AO56: 0 | AP56: 0 | AQ56: 0 | AR56: 0 | AS56: 0 | AT56: 0 | AU56: 0 | AV56: 0 | AW56: =IF(A56="",1,"") | AX56: 28 | AY56: 28 | AZ56: 28 | BA56: 0 | BB56: 0 | BC56: 0 | BD56: 0 | BE56: 0 | BF56: 0 | BG56: 0 | BH56: 0 | BI56: Solea 2002 | BJ56: GFR | BK56: No | BL56: 1 | BM56: 0 | BN56: 1.5605834 | BP56: 2 | BQ56: 1.5605834 | BR56: 2 | BS56: 5433.53 | BT56: 1121.74 | BU56: 3801 | BV56: 5602 | BW56: 5435 | BX56: 1130
A57: V | B57: 22075 | C57: 3855 | D57: =IF(K57=9,54,IF(K57=10,55,IF(K57=11,56,""))) -> 55 | E57: =IF(D57=_xlfn.NUMBERVALUE(RIGHT(C57,2)),"OK","") -> OK | F57: =CONCATENATE(LEFT(C57,2),D57) -> 3855 | G57: =IF(RIGHT(C57,2)="54",CONCATENATE(LEFT(C57,2),"F9"),IF(RIGHT(C57,2)="55",CONCATENATE(LEFT(C57,2),"G0"),IF(RIGHT(C57,2)="56",CONCATENATE(LEFT(C57,2),"G1"),IF(RIGHT(C57,2)="57",CONCATENATE(LEFT(C57,2),"G2"),IF(RIGHT(C57,2)="58",CONCATENATE(LEFT(C57,2),"G3"),IF(RIGHT(C57,2)="59",CONCATENATE(LEFT(C57,2),"G4"),IF(RIGHT(C57,2)="60",CONCATENATE(LEFT(C57,2),"G5"),IF(RIGHT(C57,2)="61",CONCATENATE(LEFT(C57,2),"G6"),IF(RIGHT(C57,2)="62",CONCATENATE(LEFT(C57,2),"G7"),IF(RIGHT(C57,2)="63",CONCATENATE(LEFT(C57,2),"G8"),IF(RIGHT(C57,2)="64",CONCATENATE(LEFT(C57,2),"G9"),IF(RIGHT(C57,2)="65",CONCATENATE(LEFT(C57,2),"H0"),IF(RIGHT(C57,2)="66",CONCATENATE(LEFT(C57,2),"H1"),IF(RIGHT(C57,2)="67",CONCATENATE(LEFT(C57,2),"H2"),IF(RIGHT(C57,2)="68",CONCATENATE(LEFT(C57,2),"H3"),IF(RIGHT(C57,2)="68",CONCATENATE(LEFT(C57,2),"H4"),C57)))))))))))))))) -> 38G0 | H57: 22 | I57: 54 | J57: 48.3 | K57: 10 | L57: 8.7 | M57: 54 | N57: 46.4 | O57: 10 | P57: 10.8 | Q57: 0 | R57: 0 | S57: 0 | T57: 0 | U57: 0 | V57: 0 | W57: 0 | X57: 0 | Y57: 0 | Z57: 0 | AA57: 0 | AB57: 0 | AC57: 0 | AD57: 0 | AE57: 0 | AF57: 0 | AG57: 0 | AH57: 0 | AI57: 0 | AJ57: 0 | AK57: 0 | AL57: 0 | AM57: 0 | AN57: 0 | AO57: 0 | AP57: 0 | AQ57: 0 | AR57: 0 | AS57: 0 | AT57: 0 | AU57: 0 | AV57: 0 | AW57: =IF(A57="",1,"") | AX57: 28 | AY57: 28 | AZ57: 28 | BA57: 0 | BB57: 0 | BC57: 0 | BD57: 0 | BE57: 0 | BF57: 0 | BG57: 0 | BH57: 0 | BI57: Havfisken | BJ57: DEN | BK57: No | BL57: 0 | BM57: 0 | BN57: 2.2530234 | BP57: 2 | BQ57: 2.2530234 | BR57: 2 | BS57: 5448.3 | BT57: 1008.7 | BU57: 3802 | BV57: 5501 | BW57: 5445 | BX57: 1010
A58: V | B58: 22076 | C58: 3855 | D58: =IF(K58=9,54,IF(K58=10,55,IF(K58=11,56,""))) -> 55 | E58: =IF(D58=_xlfn.NUMBERVALUE(RIGHT(C58,2)),"OK","") -> OK | F58: =CONCATENATE(LEFT(C58,2),D58) -> 3855 | G58: =IF(RIGHT(C58,2)="54",CONCATENATE(LEFT(C58,2),"F9"),IF(RIGHT(C58,2)="55",CONCATENATE(LEFT(C58,2),"G0"),IF(RIGHT(C58,2)="56",CONCATENATE(LEFT(C58,2),"G1"),IF(RIGHT(C58,2)="57",CONCATENATE(LEFT(C58,2),"G2"),IF(RIGHT(C58,2)="58",CONCATENATE(LEFT(C58,2),"G3"),IF(RIGHT(C58,2)="59",CONCATENATE(LEFT(C58,2),"G4"),IF(RIGHT(C58,2)="60",CONCATENATE(LEFT(C58,2),"G5"),IF(RIGHT(C58,2)="61",CONCATENATE(LEFT(C58,2),"G6"),IF(RIGHT(C58,2)="62",CONCATENATE(LEFT(C58,2),"G7"),IF(RIGHT(C58,2)="63",CONCATENATE(LEFT(C58,2),"G8"),IF(RIGHT(C58,2)="64",CONCATENATE(LEFT(C58,2),"G9"),IF(RIGHT(C58,2)="65",CONCATENATE(LEFT(C58,2),"H0"),IF(RIGHT(C58,2)="66",CONCATENATE(LEFT(C58,2),"H1"),IF(RIGHT(C58,2)="67",CONCATENATE(LEFT(C58,2),"H2"),IF(RIGHT(C58,2)="68",CONCATENATE(LEFT(C58,2),"H3"),IF(RIGHT(C58,2)="68",CONCATENATE(LEFT(C58,2),"H4"),C58)))))))))))))))) -> 38G0 | H58: 22 | I58: 54 | J58: 49.11 | K58: 10 | L58: 16.47 | M58: 54 | N58: 50.66 | O58: 10 | P58: 15.28 | Q58: 0 | R58: 0 | S58: 0 | T58: 0 | U58: 0 | V58: 0 | W58: 0 | X58: 0 | Y58: 0 | Z58: 0 | AA58: 0 | AB58: 0 | AC58: 0 | AD58: 0 | AE58: 0 | AF58: 0 | AG58: 0 | AH58: 0 | AI58: 0 | AJ58: 0 | AK58: 0 | AL58: 0 | AM58: 0 | AN58: 0 | AO58: 0 | AP58: 0 | AQ58: 0 | AR58: 0 | AS58: 0 | AT58: 0 | AU58: 0 | AV58: 0 | AW58: =IF(A58="",1,"") | AX58: 32 | AY58: 32 | AZ58: 32 | BA58: 0 | BB58: 0 | BC58: 0 | BD58: 0 | BE58: 0 | BF58: 0 | BG58: 0 | BH58: 0 | BI58: German R/V | BJ58: DEN | BK58: No | BL58: 0 | BM58: 1 | BN58: 1.6947867 | BP58: 1 | BQ58: 1.6947867 | BR58: 2 | BS58: 5449.11 | BT58: 1016.47 | BU58: 3802 | BV58: 5501 | BW58: 5445 | BX58: 1010
A59: V | B59: 22077 | C59: 3855 | D59: =IF(K59=9,54,IF(K59=10,55,IF(K59=11,56,""))) -> 55 | E59: =IF(D59=_xlfn.NUMBERVALUE(RIGHT(C59,2)),"OK","") -> OK | F59: =CONCATENATE(LEFT(C59,2),D59) -> 3855 | G59: =IF(RIGHT(C59,2)="54",CONCATENATE(LEFT(C59,2),"F9"),IF(RIGHT(C59,2)="55",CONCATENATE(LEFT(C59,2),"G0"),IF(RIGHT(C59,2)="56",CONCATENATE(LEFT(C59,2),"G1"),IF(RIGHT(C59,2)="57",CONCATENATE(LEFT(C59,2),"G2"),IF(RIGHT(C59,2)="58",CONCATENATE(LEFT(C59,2),"G3"),IF(RIGHT(C59,2)="59",CONCATENATE(LEFT(C59,2),"G4"),IF(RIGHT(C59,2)="60",CONCATENATE(LEFT(C59,2),"G5"),IF(RIGHT(C59,2)="61",CONCATENATE(LEFT(C59,2),"G6"),IF(RIGHT(C59,2)="62",CONCATENATE(LEFT(C59,2),"G7"),IF(RIGHT(C59,2)="63",CONCATENATE(LEFT(C59,2),"G8"),IF(RIGHT(C59,2)="64",CONCATENATE(LEFT(C59,2),"G9"),IF(RIGHT(C59,2)="65",CONCATENATE(LEFT(C59,2),"H0"),IF(RIGHT(C59,2)="66",CONCATENATE(LEFT(C59,2),"H1"),IF(RIGHT(C59,2)="67",CONCATENATE(LEFT(C59,2),"H2"),IF(RIGHT(C59,2)="68",CONCATENATE(LEFT(C59,2),"H3"),IF(RIGHT(C59,2)="68",CONCATENATE(LEFT(C59,2),"H4"),C59)))))))))))))))) -> 38G0 | H59: 22 | I59: 54 | J59: 41.63 | K59: 10 | L59: 19.45 | M59: 54 | N59: 41.39 | O59: 10 | P59: 22.18 | Q59: 0 | R59: 0 | S59: 0 | T59: 0 | U59: 0 | V59: 0 | W59: 0 | X59: 0 | Y59: 0 | Z59: 0 | AA59: 0 | AB59: 0 | AC59: 0 | AD59: 0 | AE59: 0 | AF59: 0 | AG59: 0 | AH59: 0 | AI59: 0 | AJ59: 0 | AK59: 0 | AL59: 0 | AM59: 0 | AN59: 0 | AO59: 0 | AP59: 0 | AQ59: 0 | AR59: 0 | AS59: 0 | AT59: 0 | AU59: 0 | AV59: 0 | AW59: =IF(A59="",1,"") | AX59: 28 | AY59: 23 | AZ59: 23 | BA59: 23 | BB59: 0 | BC59: 0 | BD59: 0 | BE59: 0 | BF59: 0 | BG59: 0 | BH59: 0 | BI59: Havfisken | BJ59: DEN | BK59: No | BL59: 0 | BM59: 0 | BN59: 1.5960169 | BP59: 1 | BQ59: 1.5960169 | BR59: 2 | BS59: 5441.63 | BT59: 1019.45 | BU59: 3802 | BV59: 5501 | BW59: 5445 | BX59: 1010
A60: V | B60: 22078 | C60: 38G0 | D60: =IF(K60=9,54,IF(K60=10,55,IF(K60=11,56,""))) -> 55 | E60: =IF(D60=_xlfn.NUMBERVALUE(RIGHT(C60,2)),"OK","") -> #VALUE! | F60: =CONCATENATE(LEFT(C60,2),D60) -> 3855 | G60: =IF(RIGHT(C60,2)="54",CONCATENATE(LEFT(C60,2),"F9"),IF(RIGHT(C60,2)="55",CONCATENATE(LEFT(C60,2),"G0"),IF(RIGHT(C60,2)="56",CONCATENATE(LEFT(C60,2),"G1"),IF(RIGHT(C60,2)="57",CONCATENATE(LEFT(C60,2),"G2"),IF(RIGHT(C60,2)="58",CONCATENATE(LEFT(C60,2),"G3"),IF(RIGHT(C60,2)="59",CONCATENATE(LEFT(C60,2),"G4"),IF(RIGHT(C60,2)="60",CONCATENATE(LEFT(C60,2),"G5"),IF(RIGHT(C60,2)="61",CONCATENATE(LEFT(C60,2),"G6"),IF(RIGHT(C60,2)="62",CONCATENATE(LEFT(C60,2),"G7"),IF(RIGHT(C60,2)="63",CONCATENATE(LEFT(C60,2),"G8"),IF(RIGHT(C60,2)="64",CONCATENATE(LEFT(C60,2),"G9"),IF(RIGHT(C60,2)="65",CONCATENATE(LEFT(C60,2),"H0"),IF(RIGHT(C60,2)="66",CONCATENATE(LEFT(C60,2),"H1"),IF(RIGHT(C60,2)="67",CONCATENATE(LEFT(C60,2),"H2"),IF(RIGHT(C60,2)="68",CONCATENATE(LEFT(C60,2),"H3"),IF(RIGHT(C60,2)="68",CONCATENATE(LEFT(C60,2),"H4"),C60)))))))))))))))) -> 38G0 | H60: 22 | I60: 54 | J60: 58.2 | K60: 10 | L60: 6.8 | M60: 54 | N60: 56.2 | O60: 10 | P60: 8.5 | Q60: 0 | R60: 0 | S60: 0 | T60: 0 | U60: 0 | V60: 0 | W60: 0 | X60: 0 | Y60: 0 | Z60: 0 | AA60: 0 | AB60: 0 | AC60: 0 | AD60: 0 | AE60: 0 | AF60: 0 | AG60: 0 | AH60: 0 | AI60: 0 | AJ60: 0 | AK60: 0 | AL60: 0 | AM60: 0 | AN60: 0 | AO60: 0 | AP60: 0 | AQ60: 0 | AR60: 0 | AS60: 0 | AT60: 0 | AU60: 0 | AV60: 0 | AW60: =IF(A60="",1,"") | AX60: 33 | AY60: 33 | AZ60: 33 | BA60: 0 | BB60: 0 | BC60: 0 | BD60: 0 | BE60: 0 | BF60: 0 | BG60: 0 | BH60: 0 | BI60: Havfisken | BJ60: DEN | BK60: No | BL60: 0 | BM60: 0 | BN60: 2.2255321 | BP60: 1 | BQ60: 2.2255321 | BR60: 2 | BS60: 5458.2 | BT60: 1006.8 | BU60: 3803 | BV60: 5501 | BW60: 5455 | BX60: 1010
A61: V | B61: 22079 | C61: 38G0 | D61: =IF(K61=9,54,IF(K61=10,55,IF(K61=11,56,""))) -> 54 | E61: =IF(D61=_xlfn.NUMBERVALUE(RIGHT(C61,2)),"OK","") -> #VALUE! | F61: =CONCATENATE(LEFT(C61,2),D61) -> 3854 | G61: =IF(RIGHT(C61,2)="54",CONCATENATE(LEFT(C61,2),"F9"),IF(RIGHT(C61,2)="55",CONCATENATE(LEFT(C61,2),"G0"),IF(RIGHT(C61,2)="56",CONCATENATE(LEFT(C61,2),"G1"),IF(RIGHT(C61,2)="57",CONCATENATE(LEFT(C61,2),"G2"),IF(RIGHT(C61,2)="58",CONCATENATE(LEFT(C61,2),"G3"),IF(RIGHT(C61,2)="59",CONCATENATE(LEFT(C61,2),"G4"),IF(RIGHT(C61,2)="60",CONCATENATE(LEFT(C61,2),"G5"),IF(RIGHT(C61,2)="61",CONCATENATE(LEFT(C61,2),"G6"),IF(RIGHT(C61,2)="62",CONCATENATE(LEFT(C61,2),"G7"),IF(RIGHT(C61,2)="63",CONCATENATE(LEFT(C61,2),"G8"),IF(RIGHT(C61,2)="64",CONCATENATE(LEFT(C61,2),"G9"),IF(RIGHT(C61,2)="65",CONCATENATE(LEFT(C61,2),"H0"),IF(RIGHT(C61,2)="66",CONCATENATE(LEFT(C61,2),"H1"),IF(RIGHT(C61,2)="67",CONCATENATE(LEFT(C61,2),"H2"),IF(RIGHT(C61,2)="68",CONCATENATE(LEFT(C61,2),"H3"),IF(RIGHT(C61,2)="68",CONCATENATE(LEFT(C61,2),"H4"),C61)))))))))))))))) -> 38G0 | H61: 22 | I61: 55 | J61: 5.09 | K61: 9 | L61: 59.08 | M61: 0 | N61: 0 | O61: 0 | P61: 0 | Q61: 0 | R61: 0 | S61: 0 | T61: 0 | U61: 0 | V61: 0 | W61: 0 | X61: 0 | Y61: 0 | Z61: 0 | AA61: 0 | AB61: 0 | AC61: 0 | AD61: 0 | AE61: 0 | AF61: 0 | AG61: 0 | AH61: 0 | AI61: 0 | AJ61: 0 | AK61: 0 | AL61: 0 | AM61: 0 | AN61: 0 | AO61: 0 | AP61: 0 | AQ61: 0 | AR61: 0 | AS61: 0 | AT61: 0 | AU61: 0 | AV61: 0 | AW61: =IF(A61="",1,"") | AX61: 31 | AY61: 22 | AZ61: 24 | BA61: 0 | BB61: 0 | BC61: 0 | BD61: 0 | BE61: 0 | BF61: 0 | BG61: 0 | BH61: 0 | BI61: German R/V | BJ61: DEN | BK61: No | BL61: 0 | BM61: 0 | BN61: 2.5026823 | BP61: 1 | BQ61: 2.5026823 | BR61: 2 | BS61: 5459.72 | BT61: 1001.41 | BU61: 3803 | BV61: 5501 | BW61: 5455 | BX61: 1010
A62: V | B62: 22081 | C62: 3954 | D62: =IF(K62=9,54,IF(K62=10,55,IF(K62=11,56,""))) -> 54 | E62: =IF(D62=_xlfn.NUMBERVALUE(RIGHT(C62,2)),"OK","") -> OK | F62: =CONCATENATE(LEFT(C62,2),D62) -> 3954 | G62: =IF(RIGHT(C62,2)="54",CONCATENATE(LEFT(C62,2),"F9"),IF(RIGHT(C62,2)="55",CONCATENATE(LEFT(C62,2),"G0"),IF(RIGHT(C62,2)="56",CONCATENATE(LEFT(C62,2),"G1"),IF(RIGHT(C62,2)="57",CONCATENATE(LEFT(C62,2),"G2"),IF(RIGHT(C62,2)="58",CONCATENATE(LEFT(C62,2),"G3"),IF(RIGHT(C62,2)="59",CONCATENATE(LEFT(C62,2),"G4"),IF(RIGHT(C62,2)="60",CONCATENATE(LEFT(C62,2),"G5"),IF(RIGHT(C62,2)="61",CONCATENATE(LEFT(C62,2),"G6"),IF(RIGHT(C62,2)="62",CONCATENATE(LEFT(C62,2),"G7"),IF(RIGHT(C62,2)="63",CONCATENATE(LEFT(C62,2),"G8"),IF(RIGHT(C62,2)="64",CONCATENATE(LEFT(C62,2),"G9"),IF(RIGHT(C62,2)="65",CONCATENATE(LEFT(C62,2),"H0"),IF(RIGHT(C62,2)="66",CONCATENATE(LEFT(C62,2),"H1"),IF(RIGHT(C62,2)="67",CONCATENATE(LEFT(C62,2),"H2"),IF(RIGHT(C62,2)="68",CONCATENATE(LEFT(C62,2),"H3"),IF(RIGHT(C62,2)="68",CONCATENATE(LEFT(C62,2),"H4"),C62)))))))))))))))) -> 39F9 | H62: 22 | I62: 55 | J62: 6.3 | K62: 9 | L62: 59.28 | M62: 55 | N62: 3.9 | O62: 9 | P62: 59.16 | Q62: 0 | R62: 0 | S62: 0 | T62: 0 | U62: 0 | V62: 0 | W62: 0 | X62: 0 | Y62: 0 | Z62: 0 | AA62: 0 | AB62: 0 | AC62: 0 | AD62: 0 | AE62: 0 | AF62: 0 | AG62: 0 | AH62: 0 | AI62: 0 | AJ62: 0 | AK62: 0 | AL62: 0 | AM62: 0 | AN62: 0 | AO62: 0 | AP62: 0 | AQ62: 0 | AR62: 0 | AS62: 0 | AT62: 0 | AU62: 0 | AV62: 0 | AW62: =IF(A62="",1,"") | AX62: 28 | AY62: 28 | AZ62: 28 | BA62: 0 | BB62: 0 | BC62: 0 | BD62: 0 | BE62: 0 | BF62: 0 | BG62: 0 | BH62: 0 | BI62: Havfisken | BJ62: DEN | BK62: No | BL62: 0 | BM62: 1 | BN62: 2.4009826 | BP62: 1 | BQ62: 2.4009826 | BR62: 2 | BS62: 5506.3 | BT62: 959.28 | BU62: 3901 | BV62: 5403 | BW62: 5505 | BX62: 950
A63: V | B63: 22082 | C63: 39G1 | D63: =IF(K63=9,54,IF(K63=10,55,IF(K63=11,56,""))) -> 56 | E63: =IF(D63=_xlfn.NUMBERVALUE(RIGHT(C63,2)),"OK","") -> #VALUE! | F63: =CONCATENATE(LEFT(C63,2),D63) -> 3956 | G63: =IF(RIGHT(C63,2)="54",CONCATENATE(LEFT(C63,2),"F9"),IF(RIGHT(C63,2)="55",CONCATENATE(LEFT(C63,2),"G0"),IF(RIGHT(C63,2)="56",CONCATENATE(LEFT(C63,2),"G1"),IF(RIGHT(C63,2)="57",CONCATENATE(LEFT(C63,2),"G2"),IF(RIGHT(C63,2)="58",CONCATENATE(LEFT(C63,2),"G3"),IF(RIGHT(C63,2)="59",CONCATENATE(LEFT(C63,2),"G4"),IF(RIGHT(C63,2)="60",CONCATENATE(LEFT(C63,2),"G5"),IF(RIGHT(C63,2)="61",CONCATENATE(LEFT(C63,2),"G6"),IF(RIGHT(C63,2)="62",CONCATENATE(LEFT(C63,2),"G7"),IF(RIGHT(C63,2)="63",CONCATENATE(LEFT(C63,2),"G8"),IF(RIGHT(C63,2)="64",CONCATENATE(LEFT(C63,2),"G9"),IF(RIGHT(C63,2)="65",CONCATENATE(LEFT(C63,2),"H0"),IF(RIGHT(C63,2)="66",CONCATENATE(LEFT(C63,2),"H1"),IF(RIGHT(C63,2)="67",CONCATENATE(LEFT(C63,2),"H2"),IF(RIGHT(C63,2)="68",CONCATENATE(LEFT(C63,2),"H3"),IF(RIGHT(C63,2)="68",CONCATENATE(LEFT(C63,2),"H4"),C63)))))))))))))))) -> 39G1 | H63: 22 | I63: 55 | J63: 6.36 | K63: 11 | L63: 19.5 | M63: 0 | N63: 0 | O63: 0 | P63: 0 | Q63: 0 | R63: 0 | S63: 0 | T63: 0 | U63: 0 | V63: 0 | W63: 0 | X63: 0 | Y63: 0 | Z63: 0 | AA63: 0 | AB63: 0 | AC63: 0 | AD63: 0 | AE63: 0 | AF63: 0 | AG63: 0 | AH63: 0 | AI63: 0 | AJ63: 0 | AK63: 0 | AL63: 0 | AM63: 0 | AN63: 0 | AO63: 0 | AP63: 0 | AQ63: 0 | AR63: 0 | AS63: 0 | AT63: 0 | AU63: 0 | AV63: 0 | AW63: =IF(A63="",1,"") | AX63: 37 | AY63: 31 | AZ63: 32 | BA63: 0 | BB63: 0 | BC63: 0 | BD63: 0 | BE63: 0 | BF63: 0 | BG63: 0 | BH63: 0 | BI63: German R/V | BJ63: DEN | BK63: No | BL63: 0 | BM63: 1 | BN63: 2.4971959 | BP63: 1 | BQ63: 2.4971959 | BR63: 2 | BS63: 5506.36 | BT63: 1119.5 | BU63: 3901 | BV63: 5601 | BW63: 5505 | BX63: 1110
