Workbook

Sheet td_all_stations
A1: NrHaul | B1: RectangleAlpha | C1: Area | D1: Layer | E1: Dist | F1: Mean_Depth | G1: EEZ | H1: NM12 | I1: Status | J1: Source | K1: Remark | L1: Lat_start_deg_dec | M1: Lon_start_deg_dec | N1: Lat_end_deg_dec | O1: Lon_end_deg_dec
A2: 22002 | B2: 37G1 | C2: 22 | D2: 8 | E2: 3.3772013 | F2: 18 | G2: DEU | H2: Yes | I2: V | L2: 54.187833 | M2: 11.921 | N2: 54.1865 | O2: 11.824833
A3: 22003 | B3: 37G1 | C3: 22 | D3: 8 | E3: 2.4028475 | F3: 19 | G3: DEU | H3: Yes | I3: V | L3: 54.196667 | M3: 11.89 | N3: 54.236667 | O3: 11.886667
A4: 22004 | B4: 37G0 | C4: 22 | D4: 8 | E4: 2.5232456 | F4: 18 | G4: DEU | H4: Yes | I4: V | L4: 54.441667 | M4: 10.661 | N4: 54.455167 | O4: 10.5925
A5: 22005 | B5: 37G0 | C5: 22 | D5: 8 | E5: 1.5592543 | F5: 17 | G5: DEU | H5: Yes | I5: V | L5: 54.404 | M5: 10.7545 | N5: 54.424167 | O5: 10.726333
A6: 22006 | B6: 37G0 | C6: 22 | D6: 8 | E6: 2.2520251 | F6: 19 | G6: DEU | H6: Yes | I6: I | L6: 54.496667 | M6: 10.686667 | N6: 54.461667 | O6: 10.71
A7: 22007 | B7: 37G1 | C7: 22 | D7: 8 | E7: 3.9975922 | F7: 16 | G7: DEU | H7: Yes | I7: V | L7: 54.452167 | M7: 11.386333 | N7: 54.386167 | O7: 11.370667
A8: 22008 | B8: 37G1 | C8: 22 | D8: 8 | E8: 2.3007392 | F8: 19 | G8: DEU | H8: Yes | I8: V | L8: 54.346667 | M8: 11.921667 | N8: 54.308333 | O8: 11.923333
A9: 22011 | B9: 38G0 | C9: 22 | D9: 9 | E9: 2.4962994 | F9: 20 | G9: DEU | H9: Yes | I9: V | L9: 54.575833 | M9: 10.169833 | N9: 54.558833 | O9: 10.235333
A10: 22012 | B10: 37G1 | C10: 22 | D10: 9 | E10: 1.6392851 | F10: 25 | G10: DEU | H10: Yes | I10: V | L10: 54.420333 | M10: 11.517833 | N10: 54.3935 | O10: 11.509
A11: 22013 | B11: 38G1 | C11: 22 | D11: 9 | E11: 1.6451222 | F11: 28 | G11: DEU | H11: Yes | I11: V | L11: 54.523 | M11: 11.321167 | N11: 54.502833 | O11: 11.353167
A12: 22014 | B12: 38G0 | C12: 22 | D12: 8 | E12: 1.63 | F12: 19 | G12: DNK | H12: Yes | I12: V | L12: 54.619333 | M12: 10.6505 | N12: 54.592167 | O12: 10.6505
A13: 22016 | B13: 39G0 | C13: 22 | D13: 8 | E13: 2.4800633 | F13: 13 | G13: DNK | H13: Yes | I13: V | L13: 55.098333 | M13: 10.811667 | N13: 55.061667 | O13: 10.778333
A14: 24345 | B14: 38G2 | C14: 24 | D14: 8 | E14: 1.1954644 | F14: 17.7 | G14: DNK | H14: Yes | I14: V | J14: Havfisken trawl computer | L14: 54.661 | M14: 12.201 | N14: 54.674166 | O14: 12.226833
A15: 24346 | B15: 38G2 | C15: 24 | D15: 9 | E15: 1.212203 | F15: 19.7 | G15: DNK | H15: Yes | I15: V | J15: Havfisken trawl computer | L15: 54.7145 | M15: 12.268 | N15: 54.7305 | O15: 12.289333
A16: 24347 | B16: 38G2 | C16: 24 | D16: 9 | E16: 1.1533477 | F16: 20 | G16: DNK | H16: Yes | I16: V | J16: Havfisken trawl computer | L16: 54.797666 | M16: 12.361666 | N16: 54.816833 | O16: 12.363833
A17: 24348 | B17: 39G3 | C17: 24 | D17: 10 | E17: 1.1646868 | F17: 39.5 | G17: SWE | H17: Yes | I17: V | J17: Havfisken trawl computer | L17: 55.2105 | M17: 13.236333 | N17: 55.210666 | O17: 13.202333
A18: 24349 | B18: 39G3 | C18: 24 | D18: 10 | E18: 1.2807775 | F18: 39.7 | G18: SWE | H18: Yes | I18: V | J18: Havfisken trawl computer | L18: 55.267166 | M18: 13.7235 | N18: 55.252 | O18: 13.697166
A19: 24350 | B19: 38G2 | C19: 24 | D19: 8 | E19: 1.1198704 | F19: 18.3 | G19: DNK | H19: Yes | I19: V | J19: Havfisken trawl computer | L19: 54.8895 | M19: 12.581166 | N19: 54.884333 | O19: 12.55
A20: 24351 | B20: 39G2 | C20: 24 | D20: 8 | E20: 1.5896328 | F20: 17 | G20: DNK | H20: Yes | I20: V | J20: Havfisken trawl computer | L20: 55.25075 | M20: 12.45795 | N20: 55.236416 | O20: 12.497
A21: 24352 | B21: 39G2 | C21: 24 | D21: 9 | E21: 1.3174946 | F21: 32 | G21: DNK | H21: No | I21: V | J21: Havfisken trawl computer | L21: 55.171666 | M21: 12.755 | N21: 55.155 | O21: 12.78
A22: 24353 | B22: 38G2 | C22: 24 | D22: 8 | E22: 1.49946 | F22: 16 | G22: DNK | H22: Yes | I22: V | J22: Havfisken trawl computer | L22: 54.877633 | M22: 12.569766 | N22: 54.873833 | O22: 12.612666
A23: 24354 | B23: 39G2 | C23: 24 | D23: 9 | E23: 1.5399568 | F23: 30 | G23: DNK | H23: No | I23: V | J23: Havfisken trawl computer | L23: 55.089933 | M23: 12.87485 | N23: 55.090066 | O23: 12.830033
A24: 24355 | B24: 38G2 | C24: 24 | D24: 8 | E24: 1.4487041 | F24: 19 | G24: DNK | H24: Yes | I24: V | J24: Havfisken trawl computer | L24: 54.745483 | M24: 12.3185 | N24: 54.729133 | O24: 12.287766
A25: 24356 | B25: 38G2 | C25: 24 | D25: 8 | E25: 1.4595032 | F25: 15 | G25: DNK | H25: Yes | I25: V | J25: Havfisken trawl computer | L25: 54.829416 | M25: 12.693333 | N25: 54.823866 | O25: 12.734416
A26: 24357 | B26: 38G2 | C26: 24 | D26: 9 | E26: 1.512959 | F26: 36 | G26: DNK | H26: No | I26: V | J26: Havfisken trawl computer | L26: 54.9166 | M26: 12.931416 | N26: 54.907983 | O26: 12.972616
A27: 22018 | B27: 39G1 | C27: 22 | D27: 8 | E27: 2.2694943 | F27: 13 | G27: DNK | H27: Yes | I27: V | L27: 55.07 | M27: 11.068333 | N27: 55.043333 | O27: 11.111667
A28: 22019 | B28: 39G1 | C28: 22 | D28: 8 | E28: 2.4980946 | F28: 17 | G28: DNK | H28: Yes | I28: V | L28: 55.057333 | M28: 11.4025 | N28: 55.046833 | O28: 11.332167
A29: 22020 | B29: 39G0 | C29: 22 | D29: 8 | E29: 2.6340581 | F29: 18 | G29: DNK | H29: Yes | I29: V | L29: 55.211667 | M29: 10.938333 | N29: 55.236667 | O29: 10.993333
A30: 22021 | B30: 39G0 | C30: 22 | D30: 9 | E30: 2.0383489 | F30: 20 | G30: DNK | H30: Yes | I30: V | L30: 55.248333 | M30: 10.845 | N30: 55.215 | O30: 10.835
A31: 22022 | B31: 39G1 | C31: 22 | D31: 8 | E31: 2.4990744 | F31: 19 | G31: DNK | H31: Yes | I31: V | L31: 55.245 | M31: 11.055 | N31: 55.216667 | O31: 11.01
A32: 22023 | B32: 39G1 | C32: 22 | D32: 8 | E32: 2.4968001 | F32: 15 | G32: DNK | H32: Yes | I32: V | L32: 55.307833 | M32: 11.021333 | N32: 55.266833 | O32: 11.033833
A33: 22024 | B33: 39F9 | C33: 22 | D33: 8 | E33: 2.3065849 | F33: 18 | G33: DNK | H33: Yes | I33: V | L33: 55.365 | M33: 9.7526667 | N33: 55.401667 | O33: 9.7323333
A34: 22025 | B34: 39G0 | C34: 22 | D34: 8 | E34: 2.4996148 | F34: 19 | G34: DNK | H34: Yes | I34: V | L34: 55.385667 | M34: 10.842667 | N34: 55.382833 | O34: 10.915833
A35: 22026 | B35: 39G0 | C35: 22 | D35: 8 | E35: 2.2789227 | F35: 18 | G35: DNK | H35: Yes | I35: V | L35: 55.423333 | M35: 10.766667 | N35: 55.42 | O35: 10.833333
A36: 22027 | B36: 40G0 | C36: 22 | D36: 8 | E36: 2.3102729 | F36: 17 | G36: DNK | H36: Yes | I36: V | L36: 55.635 | M36: 10.006667 | N36: 55.653333 | O36: 10.066667
A37: 22029 | B37: 40G0 | C37: 22 | D37: 8 | E37: 2.1052115 | F37: 18 | G37: DNK | H37: Yes | I37: V | L37: 55.651667 | M37: 10.661667 | N37: 55.623333 | O37: 10.698333
A38: 22030 | B38: 40G0 | C38: 22 | D38: 8 | E38: 2.5012336 | F38: 18 | G38: DNK | H38: Yes | I38: V | L38: 55.705667 | M38: 10.272 | N38: 55.6995 | O38: 10.198833
... A70: 22078 | B70: 38G0 | C70: 22 | D70: 9 | E70: 2.2255321 | F70: 33 | G70: DNK | H70: Yes | I70: V | L70: 54.97 | M70: 10.113333 | N70: 54.936667 | O70: 10.141667
A71: 22079 | B71: 38G0 | C71: 22 | D71: 9 | E71: 2.5026823 | F71: 31 | G71: DNK | H71: Yes | I71: V | L71: 55.084833 | M71: 9.9846667
...

Sheet track_deg_dec
A1: NrHaul | B1: lat1 | C1: lon1 | D1: lat2 | E1: lon2 | F1: lat3 | G1: lon3 | H1: lat4 | I1: lon4 | J1: lat5 | K1: lon5 | L1: lat6 | M1: lon6 | N1: lat7 | O1: lon7 | P1: lat8 | Q1: lon8 | R1: lat9 | S1: lon9 | T1: lat10 | U1: lon10
A2: 22002 | B2: 54.187833 | C2: 11.921 | D2: 54.1865 | E2: 11.824833
A3: 22003 | B3: 54.196667 | C3: 11.89 | D3: 54.236667 | E3: 11.886667
A4: 22004 | B4: 54.441667 | C4: 10.661 | D4: 54.455167 | E4: 10.5925
A5: 22005 | B5: 54.404 | C5: 10.7545 | D5: 54.424167 | E5: 10.726333
A6: 22006 | B6: 54.496667 | C6: 10.686667 | D6: 54.461667 | E6: 10.71
A7: 22007 | B7: 54.452167 | C7: 11.386333 | D7: 54.386167 | E7: 11.370667
A8: 22008 | B8: 54.346667 | C8: 11.921667 | D8: 54.308333 | E8: 11.923333
A9: 22011 | B9: 54.575833 | C9: 10.169833 | D9: 54.558833 | E9: 10.235333
A10: 22012 | B10: 54.420333 | C10: 11.517833 | D10: 54.3935 | E10: 11.509
A11: 22013 | B11: 54.523 | C11: 11.321167 | D11: 54.502833 | E11: 11.353167
A12: 22014 | B12: 54.619333 | C12: 10.6505 | D12: 54.592167 | E12: 10.6505
A13: 22016 | B13: 55.098333 | C13: 10.811667 | D13: 55.061667 | E13: 10.778333
A14: 22018 | B14: 55.07 | C14: 11.068333 | D14: 55.063333 | E14: 11.083333 | F14: 55.05 | G14: 11.093333 | H14: 55.043333 | I14: 11.111667
A15: 22019 | B15: 55.057333 | C15: 11.4025 | D15: 55.046833 | E15: 11.332167
A16: 22020 | B16: 55.211667 | C16: 10.938333 | D16: 55.225 | E16: 10.955 | F16: 55.228333 | G16: 10.986667 | H16: 55.236667 | I16: 10.993333
A17: 22021 | B17: 55.248333 | C17: 10.845 | D17: 55.236667 | E17: 10.84 | F17: 55.221667 | G17: 10.838333 | H17: 55.215 | I17: 10.835
A18: 22022 | B18: 55.245 | C18: 11.055 | D18: 55.238333 | E18: 11.025 | F18: 55.216667 | G18: 11.01
A19: 22023 | B19: 55.307833 | C19: 11.021333 | D19: 55.266833 | E19: 11.033833
A20: 22024 | B20: 55.365 | C20: 9.7526667 | D20: 55.401667 | E20: 9.7323333
A21: 22025 | B21: 55.385667 | C21: 10.842667 | D21: 55.382833 | E21: 10.915833
A22: 22026 | B22: 55.423333 | C22: 10.766667 | D22: 55.42 | E22: 10.833333
A23: 22027 | B23: 55.635 | C23: 10.006667 | D23: 55.653333 | E23: 10.066667
A24: 22029 | B24: 55.651667 | C24: 10.661667 | D24: 55.623333 | E24: 10.698333
A25: 22030 | B25: 55.705667 | C25: 10.272 | D25: 55.6995 | E25: 10.198833
A26: 22031 | B26: 55.765 | C26: 10.055 | D26: 55.783333 | E26: 10.118333
A27: 22032 | B27: 55.778333 | C27: 10.68 | D27: 55.801667 | E27: 10.735
A28: 22033 | B28: 55.941667 | C28: 10.48 | D28: 55.903333 | E28: 10.48
A29: 22034 | B29: 55.993333 | C29: 10.64 | D29: 55.993333 | E29: 10.708333
A30: 22035 | B30: 55.983333 | C30: 10.88 | D30: 55.978333 | E30: 10.945
... A51: 22065 | B51: 54.606667 | C51: 10.643 | D51: 54.633167 | E51: 10.587333
A52: 22071 | B52: 54.54 | C52: 11.406667 | D52: 54.523333 | E52: 11.455 | F52: 54.51 | G52: 11.468333
A53: 22072 | B53: 54.558833 | C53: 11.362333 | D53: 54.542333 | E53: 11.397
A54: 22075 | B54: 54.805 | C54: 10.145 | D54: 54.773333 | E54: 10.18
A55: 22076 | B55: 54.8185 | C55: 10.2745 | D55: 54.844333 | E55: 10.254667
A56: 22077 | B56: 54.693833 | C56: 10.324167 | D56: 54.689833 | E56: 10.369667
A57: 22078 | B57: 54.97 | C57: 10.113333 | D57: 54.936667 | E57: 10.141667
A58: 22079 | B58: 55.084833 | C58: 9.9846667
A59: 22081 | B59: 55.105 | C59: 9.988 | D59: 55.065 | E59: 9.986
A60: 22082 | B60: 55.106 | C60: 11.325
...

Sheet track_deg_min
A1: NrHaul | B1: lat1_deg | C1: lat1_min | D1: lon1_deg | E1: lon1_min | F1: lat2_deg | G1: lat2_min | H1: lon2_deg | I1: lon2_min | J1: lat3_deg | K1: lat3_min | L1: lon3_deg | M1: lon3_min | N1: lat4_deg | O1: lat4_min | P1: lon4_deg | Q1: lon4_min | R1: lat5_deg | S1: lat5_min | T1: lon5_deg | U1: lon5_min | V1: lat6_deg | W1: lat6_min | X1: lon6_deg | Y1: lon6_min | Z1: lat7_deg | AA1: lat7_min | AB1: lon7_deg | AC1: lon7_min | AD1: lat8_deg | AE1: lat8_min | AF1: lon8_deg | AG1: lon8_min | AH1: lat9_deg | AI1: lat9_min | AJ1: lon9_deg | AK1: lon9_min | AL1: lat10_deg | AM1: lat10_min | AN1: lon10_deg | AO1: lon10_min
A2: =IF(track_deg_dec!A2 <> "", track_deg_dec!A2, "") -> 22002 | B2: {=IF(track_deg_dec!B2 <> "", _xlfn.CHOOSECOLS(_xlfn.TEXTSPLIT(track_deg_dec!B2,","),1), "")} -> 54 | C2: =IF(track_deg_dec!B2 <> "", _xlfn.CONCAT("0,", _xlfn.CHOOSECOLS(_xlfn.TEXTSPLIT(track_deg_dec!B2,","),2))*60, "") -> 11.27 | D2: {=IF(track_deg_dec!C2 <> "", _xlfn.CHOOSECOLS(_xlfn.TEXTSPLIT(track_deg_dec!C2,","),1), "")} -> 11 | E2: =IF(track_deg_dec!C2 <> "", _xlfn.CONCAT("0,", _xlfn.CHOOSECOLS(_xlfn.TEXTSPLIT(track_deg_dec!C2,","),2))*60, "") -> 55.26 | F2: {=IF(track_deg_dec!D2 <> "", _xlfn.CHOOSECOLS(_xlfn.TEXTSPLIT(track_deg_dec!D2,","),1), "")} -> 54 | G2: =IF(track_deg_dec!D2 <> "", _xlfn.CONCAT("0,", _xlfn.CHOOSECOLS(_xlfn.TEXTSPLIT(track_deg_dec!D2,","),2))*60, "") -> 11.19 | H2: {=IF(track_deg_dec!E2 <> "", _xlfn.CHOOSECOLS(_xlfn.TEXTSPLIT(track_deg_dec!E2,","),1), "")} -> 11 | I2: =IF(track_deg_dec!E2 <> "", _xlfn.CONCAT("0,", _xlfn.CHOOSECOLS(_xlfn.TEXTSPLIT(track_deg_dec!E2,","),2))*60, "") -> 49.49 | J2: {=IF(track_deg_dec!F2 <> "", _xlfn.CHOOSECOLS(_xlfn.TEXTSPLIT(track_deg_dec!F2,","),1), "")} | K2: =IF(track_deg_dec!F2 <> "", _xlfn.CONCAT("0,", _xlfn.CHOOSECOLS(_xlfn.TEXTSPLIT(track_deg_dec!F2,","),2))*60, "") | L2: {=IF(track_deg_dec!G2 <> "", _xlfn.CHOOSECOLS(_xlfn.TEXTSPLIT(track_deg_dec!G2,","),1), "")} | M2: =IF(track_deg_dec!G2 <> "", _xlfn.CONCAT("0,", _xlfn.CHOOSECOLS(_xlfn.TEXTSPLIT(track_deg_dec!G2,","),2))*60, "") | N2: {=IF(track_deg_dec!H2 <> "", _xlfn.CHOOSECOLS(_xlfn.TEXTSPLIT(track_deg_dec!H2,","),1), "")} | O2: =IF(track_deg_dec!H2 <> "", _xlfn.CONCAT("0,", _xlfn.CHOOSECOLS(_xlfn.TEXTSPLIT(track_deg_dec!H2,","),2))*60, "") | P2: {=IF(track_deg_dec!I2 <> "", _xlfn.CHOOSECOLS(_xlfn.TEXTSPLIT(track_deg_dec!I2,","),1), "")} | Q2: =IF(track_deg_dec!I2 <> "", _xlfn.CONCAT("0,", _xlfn.CHOOSECOLS(_xlfn.TEXTSPLIT(track_deg_dec!I2,","),2))*60, "") | R2: {=IF(track_deg_dec!J2 <> "", _xlfn.CHOOSECOLS(_xlfn.TEXTSPLIT(track_deg_dec!J2,","),1), "")} | S2: =IF(track_deg_dec!J2 <> "", _xlfn.CONCAT("0,", _xlfn.CHOOSECOLS(_xlfn.TEXTSPLIT(track_deg_dec!J2,","),2))*60, "") | T2: {=IF(track_deg_dec!K2 <> "", _xlfn.CHOOSECOLS(_xlfn.TEXTSPLIT(track_deg_dec!K2,","),1), "")} | U2: =IF(track_deg_dec!K2 <> "", _xlfn.CONCAT("0,", _xlfn.CHOOSECOLS(_xlfn.TEXTSPLIT(track_deg_dec!K2,","),2))*60, "") | V2: {=IF(track_deg_dec!L2 <> "", _xlfn.CHOOSECOLS(_xlfn.TEXTSPLIT(track_deg_dec!L2,","),1), "")} | W2: =IF(track_deg_dec!L2 <> "", _xlfn.CONCAT("0,", _xlfn.CHOOSECOLS(_xlfn.TEXTSPLIT(track_deg_dec!L2,","),2))*60, "") | X2: {=IF(track_deg_dec!M2 <> "", _xlfn.CHOOSECOLS(_xlfn.TEXTSPLIT(track_deg_dec!M2,","),1), "")} | Y2: =IF(track_deg_dec!M2 <> "", _xlfn.CONCAT("0,", _xlfn.CHOOSECOLS(_xlfn.TEXTSPLIT(track_deg_dec!M2,","),2))*60, "") | Z2: {=IF(track_deg_dec!N2 <> "", _xlfn.CHOOSECOLS(_xlfn.TEXTSPLIT(track_deg_dec!N2,","),1), "")} | AA2: =IF(track_deg_dec!N2 <> "", _xlfn.CONCAT("0,", _xlfn.CHOOSECOLS(_xlfn.TEXTSPLIT(track_deg_dec!N2,","),2))*60, "") | AB2: {=IF(track_deg_dec!O2 <> "", _xlfn.CHOOSECOLS(_xlfn.TEXTSPLIT(track_deg_dec!O2,","),1), "")} | AC2: =IF(track_deg_dec!O2 <> "", _xlfn.CONCAT("0,", _xlfn.CHOOSECOLS(_xlfn.TEXTSPLIT(track_deg_dec!O2,","),2))*60, "") | AD2: {=IF(track_deg_dec!P2 <> "", _xlfn.CHOOSECOLS(_xlfn.TEXTSPLIT(track_deg_dec!P2,","),1), "")} | AE2: =IF(track_deg_dec!P2 <> "", _xlfn.CONCAT("0,", _xlfn.CHOOSECOLS(_xlfn.TEXTSPLIT(track_deg_dec!P2,","),2))*60, "") | AF2: {=IF(track_deg_dec!Q2 <> "", _xlfn.CHOOSECOLS(_xlfn.TEXTSPLIT(track_deg_dec!Q2,","),1), "")} | AG2: =IF(track_deg_dec!Q2 <> "", _xlfn.CONCAT("0,", _xlfn.CHOOSECOLS(_xlfn.TEXTSPLIT(track_deg_dec!Q2,","),2))*60, "") | AH2: {=IF(track_deg_dec!R2 <> "", _xlfn.CHOOSECOLS(_xlfn.TEXTSPLIT(track_deg_dec!R2,","),1), "")} | AI2: =IF(track_deg_dec!R2 <> "", _xlfn.CONCAT("0,", _xlfn.CHOOSECOLS(_xlfn.TEXTSPLIT(track_deg_dec!R2,","),2))*60, "") | AJ2: {=IF(track_deg_dec!S2 <> "", _xlfn.CHOOSECOLS(_xlfn.TEXTSPLIT(track_deg_dec!S2,","),1), "")} | AK2: =IF(track_deg_dec!S2 <> "", _xlfn.CONCAT("0,", _xlfn.CHOOSECOLS(_xlfn.TEXTSPLIT(track_deg_dec!S2,","),2))*60, "") | AL2: {=IF(track_deg_dec!T2 <> "", _xlfn.CHOOSECOLS(_xlfn.TEXTSPLIT(track_deg_dec!T2,","),1), "")} | AM2: =IF(track_deg_dec!T2 <> "", _xlfn.CONCAT("0,", _xlfn.CHOOSECOLS(_xlfn.TEXTSPLIT(track_deg_dec!T2,","),2))*60, "") | AN2: {=IF(track_deg_dec!U2 <> "", _xlfn.CHOOSECOLS(_xlfn.TEXTSPLIT(track_deg_dec!U2,","),1), "")} | AO2: =IF(track_deg_dec!U2 <> "", _xlfn.CONCAT("0,", _xlfn.CHOOSECOLS(_xlfn.TEXTSPLIT(track_deg_dec!U2,","),2))*60, "")
A3: =IF(track_deg_dec!A3 <> "", track_deg_dec!A3, "") -> 22003 | B3: {=IF(track_deg_dec!B3 <> "", _xlfn.CHOOSECOLS(_xlfn.TEXTSPLIT(track_deg_dec!B3,","),1), "")} -> 54 | C3: =IF(track_deg_dec!B3 <> "", _xlfn.CONCAT("0,", _xlfn.CHOOSECOLS(_xlfn.TEXTSPLIT(track_deg_dec!B3,","),2))*60, "") -> 11.8 | D3: {=IF(track_deg_dec!C3 <> "", _xlfn.CHOOSECOLS(_xlfn.TEXTSPLIT(track_deg_dec!C3,","),1), "")} -> 11 | E3: =IF(track_deg_dec!C3 <> "", _xlfn.CONCAT("0,", _xlfn.CHOOSECOLS(_xlfn.TEXTSPLIT(track_deg_dec!C3,","),2))*60, "") -> 53.4 | F3: {=IF(track_deg_dec!D3 <> "", _xlfn.CHOOSECOLS(_xlfn.TEXTSPLIT(track_deg_dec!D3,","),1), "")} -> 54 | G3: =IF(track_deg_dec!D3 <> "", _xlfn.CONCAT("0,", _xlfn.CHOOSECOLS(_xlfn.TEXTSPLIT(track_deg_dec!D3,","),2))*60, "") -> 14.2 | H3: {=IF(track_deg_dec!E3 <> "", _xlfn.CHOOSECOLS(_xlfn.TEXTSPLIT(track_deg_dec!E3,","),1), "")} -> 11 | I3: =IF(track_deg_dec!E3 <> "", _xlfn.CONCAT("0,", _xlfn.CHOOSECOLS(_xlfn.TEXTSPLIT(track_deg_dec!E3,","),2))*60, "") -> 53.2 | J3: {=IF(track_deg_dec!F3 <> "", _xlfn.CHOOSECOLS(_xlfn.TEXTSPLIT(track_deg_dec!F3,","),1), "")} | K3: =IF(track_deg_dec!F3 <> "", _xlfn.CONCAT("0,", _xlfn.CHOOSECOLS(_xlfn.TEXTSPLIT(track_deg_dec!F3,","),2))*60, "") | L3: {=IF(track_deg_dec!G3 <> "", _xlfn.CHOOSECOLS(_xlfn.TEXTSPLIT(track_deg_dec!G3,","),1), "")} | M3: =IF(track_deg_dec!G3 <> "", _xlfn.CONCAT("0,", _xlfn.CHOOSECOLS(_xlfn.TEXTSPLIT(track_deg_dec!G3,","),2))*60, "") | N3: {=IF(track_deg_dec!H3 <> "", _xlfn.CHOOSECOLS(_xlfn.TEXTSPLIT(track_deg_dec!H3,","),1), "")} | O3: =IF(track_deg_dec!H3 <> "", _xlfn.CONCAT("0,", _xlfn.CHOOSECOLS(_xlfn.TEXTSPLIT(track_deg_dec!H3,","),2))*60, "") | P3: {=IF(track_deg_dec!I3 <> "", _xlfn.CHOOSECOLS(_xlfn.TEXTSPLIT(track_deg_dec!I3,","),1), "")} | Q3: =IF(track_deg_dec!I3 <> "", _xlfn.CONCAT("0,", _xlfn.CHOOSECOLS(_xlfn.TEXTSPLIT(track_deg_dec!I3,","),2))*60, "") | R3: {=IF(track_deg_dec!J3 <> "", _xlfn.CHOOSECOLS(_xlfn.TEXTSPLIT(track_deg_dec!J3,","),1), "")} | S3: =IF(track_deg_dec!J3 <> "", _xlfn.CONCAT("0,", _xlfn.CHOOSECOLS(_xlfn.TEXTSPLIT(track_deg_dec!J3,","),2))*60, "") | T3: {=IF(track_deg_dec!K3 <> "", _xlfn.CHOOSECOLS(_xlfn.TEXTSPLIT(track_deg_dec!K3,","),1), "")} | U3: =IF(track_deg_dec!K3 <> "", _xlfn.CONCAT("0,", _xlfn.CHOOSECOLS(_xlfn.TEXTSPLIT(track_deg_dec!K3,","),2))*60, "") | V3: {=IF(track_deg_dec!L3 <> "", _xlfn.CHOOSECOLS(_xlfn.TEXTSPLIT(track_deg_dec!L3,","),1), "")} | W3: =IF(track_deg_dec!L3 <> "", _xlfn.CONCAT("0,", _xlfn.CHOOSECOLS(_xlfn.TEXTSPLIT(track_deg_dec!L3,","),2))*60, "") | X3: {=IF(track_deg_dec!M3 <> "", _xlfn.CHOOSECOLS(_xlfn.TEXTSPLIT(track_deg_dec!M3,","),1), "")} | Y3: =IF(track_deg_dec!M3 <> "", _xlfn.CONCAT("0,", _xlfn.CHOOSECOLS(_xlfn.TEXTSPLIT(track_deg_dec!M3,","),2))*60, "") | Z3: {=IF(track_deg_dec!N3 <> "", _xlfn.CHOOSECOLS(_xlfn.TEXTSPLIT(track_deg_dec!N3,","),1), "")} | AA3: =IF(track_deg_dec!N3 <> "", _xlfn.CONCAT("0,", _xlfn.CHOOSECOLS(_xlfn.TEXTSPLIT(track_deg_dec!N3,","),2))*60, "") | AB3: {=IF(track_deg_dec!O3 <> "", _xlfn.CHOOSECOLS(_xlfn.TEXTSPLIT(track_deg_dec!O3,","),1), "")} | AC3: =IF(track_deg_dec!O3 <> "", _xlfn.CONCAT("0,", _xlfn.CHOOSECOLS(_xlfn.TEXTSPLIT(track_deg_dec!O3,","),2))*60, "") | AD3: {=IF(track_deg_dec!P3 <> "", _xlfn.CHOOSECOLS(_xlfn.TEXTSPLIT(track_deg_dec!P3,","),1), "")} | AE3: =IF(track_deg_dec!P3 <> "", _xlfn.CONCAT("0,", _xlfn.CHOOSECOLS(_xlfn.TEXTSPLIT(track_deg_dec!P3,","),2))*60, "") | AF3: {=IF(track_deg_dec!Q3 <> "", _xlfn.CHOOSECOLS(_xlfn.TEXTSPLIT(track_deg_dec!Q3,","),1), "")} | AG3: =IF(track_deg_dec!Q3 <> "", _xlfn.CONCAT("0,", _xlfn.CHOOSECOLS(_xlfn.TEXTSPLIT(track_deg_dec!Q3,","),2))*60, "") | AH3: {=IF(track_deg_dec!R3 <> "", _xlfn.CHOOSECOLS(_xlfn.TEXTSPLIT(track_deg_dec!R3,","),1), "")} | AI3: =IF(track_deg_dec!R3 <> "", _xlfn.CONCAT("0,", _xlfn.CHOOSECOLS(_xlfn.TEXTSPLIT(track_deg_dec!R3,","),2))*60, "") | AJ3: {=IF(track_deg_dec!S3 <> "", _xlfn.CHOOSECOLS(_xlfn.TEXTSPLIT(track_deg_dec!S3,","),1), "")} | AK3: =IF(track_deg_dec!S3 <> "", _xlfn.CONCAT("0,", _xlfn.CHOOSECOLS(_xlfn.TEXTSPLIT(track_deg_dec!S3,","),2))*60, "") | AL3: {=IF(track_deg_dec!T3 <> "", _xlfn.CHOOSECOLS(_xlfn.TEXTSPLIT(track_deg_dec!T3,","),1), "")} | AM3: =IF(track_deg_dec!T3 <> "", _xlfn.CONCAT("0,", _xlfn.CHOOSECOLS(_xlfn.TEXTSPLIT(track_deg_dec!T3,","),2))*60, "") | AN3: {=IF(track_deg_dec!U3 <> "", _xlfn.CHOOSECOLS(_xlfn.TEXTSPLIT(track_deg_dec!U3,","),1), "")} | AO3: =IF(track_deg_dec!U3 <> "", _xlfn.CONCAT("0,", _xlfn.CHOOSECOLS(_xlfn.TEXTSPLIT(track_deg_dec!U3,","),2))*60, "")
A4: =IF(track_deg_dec!A4 <> "", track_deg_dec!A4, "") -> 22004 | B4: {=IF(track_deg_dec!B4 <> "", _xlfn.CHOOSECOLS(_xlfn.TEXTSPLIT(track_deg_dec!B4,","),1), "")} -> 54 | C4: =IF(track_deg_dec!B4 <> "", _xlfn.CONCAT("0,", _xlfn.CHOOSECOLS(_xlfn.TEXTSPLIT(track_deg_dec!B4,","),2))*60, "") -> 26.5 | D4: {=IF(track_deg_dec!C4 <> "", _xlfn.CHOOSECOLS(_xlfn.TEXTSPLIT(track_deg_dec!C4,","),1), "")} -> 10 | E4: =IF(track_deg_dec!C4 <> "", _xlfn.CONCAT("0,", _xlfn.CHOOSECOLS(_xlfn.TEXTSPLIT(track_deg_dec!C4,","),2))*60, "") -> 39.66 | F4: {=IF(track_deg_dec!D4 <> "", _xlfn.CHOOSECOLS(_xlfn.TEXTSPLIT(track_deg_dec!D4,","),1), "")} -> 54 | G4: =IF(track_deg_dec!D4 <> "", _xlfn.CONCAT("0,", _xlfn.CHOOSECOLS(_xlfn.TEXTSPLIT(track_deg_dec!D4,","),2))*60, "") -> 27.31 | H4: {=IF(track_deg_dec!E4 <> "", _xlfn.CHOOSECOLS(_xlfn.TEXTSPLIT(track_deg_dec!E4,","),1), "")} -> 10 | I4: =IF(track_deg_dec!E4 <> "", _xlfn.CONCAT("0,", _xlfn.CHOOSECOLS(_xlfn.TEXTSPLIT(track_deg_dec!E4,","),2))*60, "") -> 35.55 | J4: {=IF(track_deg_dec!F4 <> "", _xlfn.CHOOSECOLS(_xlfn.TEXTSPLIT(track_deg_dec!F4,","),1), "")} | K4: =IF(track_deg_dec!F4 <> "", _xlfn.CONCAT("0,", _xlfn.CHOOSECOLS(_xlfn.TEXTSPLIT(track_deg_dec!F4,","),2))*60, "") | L4: {=IF(track_deg_dec!G4 <> "", _xlfn.CHOOSECOLS(_xlfn.TEXTSPLIT(track_deg_dec!G4,","),1), "")} | M4: =IF(track_deg_dec!G4 <> "", _xlfn.CONCAT("0,", _xlfn.CHOOSECOLS(_xlfn.TEXTSPLIT(track_deg_dec!G4,","),2))*60, "") | N4: {=IF(track_deg_dec!H4 <> "", _xlfn.CHOOSECOLS(_xlfn.TEXTSPLIT(track_deg_dec!H4,","),1), "")} | O4: =IF(track_deg_dec!H4 <> "", _xlfn.CONCAT("0,", _xlfn.CHOOSECOLS(_xlfn.TEXTSPLIT(track_deg_dec!H4,","),2))*60, "") | P4: {=IF(track_deg_dec!I4 <> "", _xlfn.CHOOSECOLS(_xlfn.TEXTSPLIT(track_deg_dec!I4,","),1), "")} | Q4: =IF(track_deg_dec!I4 <> "", _xlfn.CONCAT("0,", _xlfn.CHOOSECOLS(_xlfn.TEXTSPLIT(track_deg_dec!I4,","),2))*60, "") | R4: {=IF(track_deg_dec!J4 <> "", _xlfn.CHOOSECOLS(_xlfn.TEXTSPLIT(track_deg_dec!J4,","),1), "")} | S4: =IF(track_deg_dec!J4 <> "", _xlfn.CONCAT("0,", _xlfn.CHOOSECOLS(_xlfn.TEXTSPLIT(track_deg_dec!J4,","),2))*60, "") | T4: {=IF(track_deg_dec!K4 <> "", _xlfn.CHOOSECOLS(_xlfn.TEXTSPLIT(track_deg_dec!K4,","),1), "")} | U4: =IF(track_deg_dec!K4 <> "", _xlfn.CONCAT("0,", _xlfn.CHOOSECOLS(_xlfn.TEXTSPLIT(track_deg_dec!K4,","),2))*60, "") | V4: {=IF(track_deg_dec!L4 <> "", _xlfn.CHOOSECOLS(_xlfn.TEXTSPLIT(track_deg_dec!L4,","),1), "")} | W4: =IF(track_deg_dec!L4 <> "", _xlfn.CONCAT("0,", _xlfn.CHOOSECOLS(_xlfn.TEXTSPLIT(track_deg_dec!L4,","),2))*60, "") | X4: {=IF(track_deg_dec!M4 <> "", _xlfn.CHOOSECOLS(_xlfn.TEXTSPLIT(track_deg_dec!M4,","),1), "")} | Y4: =IF(track_deg_dec!M4 <> "", _xlfn.CONCAT("0,", _xlfn.CHOOSECOLS(_xlfn.TEXTSPLIT(track_deg_dec!M4,","),2))*60, "") | Z4: {=IF(track_deg_dec!N4 <> "", _xlfn.CHOOSECOLS(_xlfn.TEXTSPLIT(track_deg_dec!N4,","),1), "")} | AA4: =IF(track_deg_dec!N4 <> "", _xlfn.CONCAT("0,", _xlfn.CHOOSECOLS(_xlfn.TEXTSPLIT(track_deg_dec!N4,","),2))*60, "") | AB4: {=IF(track_deg_dec!O4 <> "", _xlfn.CHOOSECOLS(_xlfn.TEXTSPLIT(track_deg_dec!O4,","),1), "")} | AC4: =IF(track_deg_dec!O4 <> "", _xlfn.CONCAT("0,", _xlfn.CHOOSECOLS(_xlfn.TEXTSPLIT(track_deg_dec!O4,","),2))*60, "") | AD4: {=IF(track_deg_dec!P4 <> "", _xlfn.CHOOSECOLS(_xlfn.TEXTSPLIT(track_deg_dec!P4,","),1), "")} | AE4: =IF(track_deg_dec!P4 <> "", _xlfn.CONCAT("0,", _xlfn.CHOOSECOLS(_xlfn.TEXTSPLIT(track_deg_dec!P4,","),2))*60, "") | AF4: {=IF(track_deg_dec!Q4 <> "", _xlfn.CHOOSECOLS(_xlfn.TEXTSPLIT(track_deg_dec!Q4,","),1), "")} | AG4: =IF(track_deg_dec!Q4 <> "", _xlfn.CONCAT("0,", _xlfn.CHOOSECOLS(_xlfn.TEXTSPLIT(track_deg_dec!Q4,","),2))*60, "") | AH4: {=IF(track_deg_dec!R4 <> "", _xlfn.CHOOSECOLS(_xlfn.TEXTSPLIT(track_deg_dec!R4,","),1), "")} | AI4: =IF(track_deg_dec!R4 <> "", _xlfn.CONCAT("0,", _xlfn.CHOOSECOLS(_xlfn.TEXTSPLIT(track_deg_dec!R4,","),2))*60, "") | AJ4: {=IF(track_deg_dec!S4 <> "", _xlfn.CHOOSECOLS(_xlfn.TEXTSPLIT(track_deg_dec!S4,","),1), "")} | AK4: =IF(track_deg_dec!S4 <> "", _xlfn.CONCAT("0,", _xlfn.CHOOSECOLS(_xlfn.TEXTSPLIT(track_deg_dec!S4,","),2))*60, "") | AL4: {=IF(track_deg_dec!T4 <> "", _xlfn.CHOOSECOLS(_xlfn.TEXTSPLIT(track_deg_dec!T4,","),1), "")} | AM4: =IF(track_deg_dec!T4 <> "", _xlfn.CONCAT("0,", _xlfn.CHOOSECOLS(_xlfn.TEXTSPLIT(track_deg_dec!T4,","),2))*60, "") | AN4: {=IF(track_deg_dec!U4 <> "", _xlfn.CHOOSECOLS(_xlfn.TEXTSPLIT(track_deg_dec!U4,","),1), "")} | AO4: =IF(track_deg_dec!U4 <> "", _xlfn.CONCAT("0,", _xlfn.CHOOSECOLS(_xlfn.TEXTSPLIT(track_deg_dec!U4,","),2))*60, "")
A5: =IF(track_deg_dec!A5 <> "", track_deg_dec!A5, "") -> 22005 | B5: {=IF(track_deg_dec!B5 <> "", _xlfn.CHOOSECOLS(_xlfn.TEXTSPLIT(track_deg_dec!B5,","),1), "")} -> 54 | C5: =IF(track_deg_dec!B5 <> "", _xlfn.CONCAT("0,", _xlfn.CHOOSECOLS(_xlfn.TEXTSPLIT(track_deg_dec!B5,","),2))*60, "") -> 24.24 | D5: {=IF(track_deg_dec!C5 <> "", _xlfn.CHOOSECOLS(_xlfn.TEXTSPLIT(track_deg_dec!C5,","),1), "")} -> 10 | E5: =IF(track_deg_dec!C5 <> "", _xlfn.CONCAT("0,", _xlfn.CHOOSECOLS(_xlfn.TEXTSPLIT(track_deg_dec!C5,","),2))*60, "") -> 45.27 | F5: {=IF(track_deg_dec!D5 <> "", _xlfn.CHOOSECOLS(_xlfn.TEXTSPLIT(track_deg_dec!D5,","),1), "")} -> 54 | G5: =IF(track_deg_dec!D5 <> "", _xlfn.CONCAT("0,", _xlfn.CHOOSECOLS(_xlfn.TEXTSPLIT(track_deg_dec!D5,","),2))*60, "") -> 25.45 | H5: {=IF(track_deg_dec!E5 <> "", _xlfn.CHOOSECOLS(_xlfn.TEXTSPLIT(track_deg_dec!E5,","),1), "")} -> 10 | I5: =IF(track_deg_dec!E5 <> "", _xlfn.CONCAT("0,", _xlfn.CHOOSECOLS(_xlfn.TEXTSPLIT(track_deg_dec!E5,","),2))*60, "") -> 43.58 | J5: {=IF(track_deg_dec!F5 <> "", _xlfn.CHOOSECOLS(_xlfn.TEXTSPLIT(track_deg_dec!F5,","),1), "")} | K5: =IF(track_deg_dec!F5 <> "", _xlfn.CONCAT("0,", _xlfn.CHOOSECOLS(_xlfn.TEXTSPLIT(track_deg_dec!F5,","),2))*60, "") | L5: {=IF(track_deg_dec!G5 <> "", _xlfn.CHOOSECOLS(_xlfn.TEXTSPLIT(track_deg_dec!G5,","),1), "")} | M5: =IF(track_deg_dec!G5 <> "", _xlfn.CONCAT("0,", _xlfn.CHOOSECOLS(_xlfn.TEXTSPLIT(track_deg_dec!G5,","),2))*60, "") | N5: {=IF(track_deg_dec!H5 <> "", _xlfn.CHOOSECOLS(_xlfn.TEXTSPLIT(track_deg_dec!H5,","),1), "")} | O5: =IF(track_deg_dec!H5 <> "", _xlfn.CONCAT("0,", _xlfn.CHOOSECOLS(_xlfn.TEXTSPLIT(track_deg_dec!H5,","),2))*60, "") | P5: {=IF(track_deg_dec!I5 <> "", _xlfn.CHOOSECOLS(_xlfn.TEXTSPLIT(track_deg_dec!I5,","),1), "")} | Q5: =IF(track_deg_dec!I5 <> "", _xlfn.CONCAT("0,", _xlfn.CHOOSECOLS(_xlfn.TEXTSPLIT(track_deg_dec!I5,","),2))*60, "") | R5: {=IF(track_deg_dec!J5 <> "", _xlfn.CHOOSECOLS(_xlfn.TEXTSPLIT(track_deg_dec!J5,","),1), "")} | S5: =IF(track_deg_dec!J5 <> "", _xlfn.CONCAT("0,", _xlfn.CHOOSECOLS(_xlfn.TEXTSPLIT(track_deg_dec!J5,","),2))*60, "") | T5: {=IF(track_deg_dec!K5 <> "", _xlfn.CHOOSECOLS(_xlfn.TEXTSPLIT(track_deg_dec!K5,","),1), "")} | U5: =IF(track_deg_dec!K5 <> "", _xlfn.CONCAT("0,", _xlfn.CHOOSECOLS(_xlfn.TEXTSPLIT(track_deg_dec!K5,","),2))*60, "") | V5: {=IF(track_deg_dec!L5 <> "", _xlfn.CHOOSECOLS(_xlfn.TEXTSPLIT(track_deg_dec!L5,","),1), "")} | W5: =IF(track_deg_dec!L5 <> "", _xlfn.CONCAT("0,", _xlfn.CHOOSECOLS(_xlfn.TEXTSPLIT(track_deg_dec!L5,","),2))*60, "") | X5: {=IF(track_deg_dec!M5 <> "", _xlfn.CHOOSECOLS(_xlfn.TEXTSPLIT(track_deg_dec!M5,","),1), "")} | Y5: =IF(track_deg_dec!M5 <> "", _xlfn.CONCAT("0,", _xlfn.CHOOSECOLS(_xlfn.TEXTSPLIT(track_deg_dec!M5,","),2))*60, "") | Z5: {=IF(track_deg_dec!N5 <> "", _xlfn.CHOOSECOLS(_xlfn.TEXTSPLIT(track_deg_dec!N5,","),1), "")} | AA5: =IF(track_deg_dec!N5 <> "", _xlfn.CONCAT("0,", _xlfn.CHOOSECOLS(_xlfn.TEXTSPLIT(track_deg_dec!N5,","),2))*60, "") | AB5: {=IF(track_deg_dec!O5 <> "", _xlfn.CHOOSECOLS(_xlfn.TEXTSPLIT(track_deg_dec!O5,","),1), "")} | AC5: =IF(track_deg_dec!O5 <> "", _xlfn.CONCAT("0,", _xlfn.CHOOSECOLS(_xlfn.TEXTSPLIT(track_deg_dec!O5,","),2))*60, "") | AD5: {=IF(track_deg_dec!P5 <> "", _xlfn.CHOOSECOLS(_xlfn.TEXTSPLIT(track_deg_dec!P5,","),1), "")} | AE5: =IF(track_deg_dec!P5 <> "", _xlfn.CONCAT("0,", _xlfn.CHOOSECOLS(_xlfn.TEXTSPLIT(track_deg_dec!P5,","),2))*60, "") | AF5: {=IF(track_deg_dec!Q5 <> "", _xlfn.CHOOSECOLS(_xlfn.TEXTSPLIT(track_deg_dec!Q5,","),1), "")} | AG5: =IF(track_deg_dec!Q5 <> "", _xlfn.CONCAT("0,", _xlfn.CHOOSECOLS(_xlfn.TEXTSPLIT(track_deg_dec!Q5,","),2))*60, "") | AH5: {=IF(track_deg_dec!R5 <> "", _xlfn.CHOOSECOLS(_xlfn.TEXTSPLIT(track_deg_dec!R5,","),1), "")} | AI5: =IF(track_deg_dec!R5 <> "", _xlfn.CONCAT("0,", _xlfn.CHOOSECOLS(_xlfn.TEXTSPLIT(track_deg_dec!R5,","),2))*60, "") | AJ5: {=IF(track_deg_dec!S5 <> "", _xlfn.CHOOSECOLS(_xlfn.TEXTSPLIT(track_deg_dec!S5,","),1), "")} | AK5: =IF(track_deg_dec!S5 <> "", _xlfn.CONCAT("0,", _xlfn.CHOOSECOLS(_xlfn.TEXTSPLIT(track_deg_dec!S5,","),2))*60, "") | AL5: {=IF(track_deg_dec!T5 <> "", _xlfn.CHOOSECOLS(_xlfn.TEXTSPLIT(track_deg_dec!T5,","),1), "")} | AM5: =IF(track_deg_dec!T5 <> "", _xlfn.CONCAT("0,", _xlfn.CHOOSECOLS(_xlfn.TEXTSPLIT(track_deg_dec!T5,","),2))*60, "") | AN5: {=IF(track_deg_dec!U5 <> "", _xlfn.CHOOSECOLS(_xlfn.TEXTSPLIT(track_deg_dec!U5,","),1), "")} | AO5: =IF(track_deg_dec!U5 <> "", _xlfn.CONCAT("0,", _xlfn.CHOOSECOLS(_xlfn.TEXTSPLIT(track_deg_dec!U5,","),2))*60, "")
A6: =IF(track_deg_dec!A6 <> "", track_deg_dec!A6, "") -> 22006 | B6: {=IF(track_deg_dec!B6 <> "", _xlfn.CHOOSECOLS(_xlfn.TEXTSPLIT(track_deg_dec!B6,","),1), "")} -> 54 | C6: =IF(track_deg_dec!B6 <> "", _xlfn.CONCAT("0,", _xlfn.CHOOSECOLS(_xlfn.TEXTSPLIT(track_deg_dec!B6,","),2))*60, "") -> 29.8 | D6: {=IF(track_deg_dec!C6 <> "", _xlfn.CHOOSECOLS(_xlfn.TEXTSPLIT(track_deg_dec!C6,","),1), "")} -> 10 | E6: =IF(track_deg_dec!C6 <> "", _xlfn.CONCAT("0,", _xlfn.CHOOSECOLS(_xlfn.TEXTSPLIT(track_deg_dec!C6,","),2))*60, "") -> 41.2 | F6: {=IF(track_deg_dec!D6 <> "", _xlfn.CHOOSECOLS(_xlfn.TEXTSPLIT(track_deg_dec!D6,","),1), "")} -> 54 | G6: =IF(track_deg_dec!D6 <> "", _xlfn.CONCAT("0,", _xlfn.CHOOSECOLS(_xlfn.TEXTSPLIT(track_deg_dec!D6,","),2))*60, "") -> 27.7 | H6: {=IF(track_deg_dec!E6 <> "", _xlfn.CHOOSECOLS(_xlfn.TEXTSPLIT(track_deg_dec!E6,","),1), "")} -> 10 | I6: =IF(track_deg_dec!E6 <> "", _xlfn.CONCAT("0,", _xlfn.CHOOSECOLS(_xlfn.TEXTSPLIT(track_deg_dec!E6,","),2))*60, "") -> 42.6 | J6: {=IF(track_deg_dec!F6 <> "", _xlfn.CHOOSECOLS(_xlfn.TEXTSPLIT(track_deg_dec!F6,","),1), "")} | K6: =IF(track_deg_dec!F6 <> "", _xlfn.CONCAT("0,", _xlfn.CHOOSECOLS(_xlfn.TEXTSPLIT(track_deg_dec!F6,","),2))*60, "") | L6: {=IF(track_deg_dec!G6 <> "", _xlfn.CHOOSECOLS(_xlfn.TEXTSPLIT(track_deg_dec!G6,","),1), "")} | M6: =IF(track_deg_dec!G6 <> "", _xlfn.CONCAT("0,", _xlfn.CHOOSECOLS(_xlfn.TEXTSPLIT(track_deg_dec!G6,","),2))*60, "") | N6: {=IF(track_deg_dec!H6 <> "", _xlfn.CHOOSECOLS(_xlfn.TEXTSPLIT(track_deg_dec!H6,","),1), "")} | O6: =IF(track_deg_dec!H6 <> "", _xlfn.CONCAT("0,", _xlfn.CHOOSECOLS(_xlfn.TEXTSPLIT(track_deg_dec!H6,","),2))*60, "") | P6: {=IF(track_deg_dec!I6 <> "", _xlfn.CHOOSECOLS(_xlfn.TEXTSPLIT(track_deg_dec!I6,","),1), "")} | Q6: =IF(track_deg_dec!I6 <> "", _xlfn.CONCAT("0,", _xlfn.CHOOSECOLS(_xlfn.TEXTSPLIT(track_deg_dec!I6,","),2))*60, "") | R6: {=IF(track_deg_dec!J6 <> "", _xlfn.CHOOSECOLS(_xlfn.TEXTSPLIT(track_deg_dec!J6,","),1), "")} | S6: =IF(track_deg_dec!J6 <> "", _xlfn.CONCAT("0,", _xlfn.CHOOSECOLS(_xlfn.TEXTSPLIT(track_deg_dec!J6,","),2))*60, "") | T6: {=IF(track_deg_dec!K6 <> "", _xlfn.CHOOSECOLS(_xlfn.TEXTSPLIT(track_deg_dec!K6,","),1), "")} | U6: =IF(track_deg_dec!K6 <> "", _xlfn.CONCAT("0,", _xlfn.CHOOSECOLS(_xlfn.TEXTSPLIT(track_deg_dec!K6,","),2))*60, "") | V6: {=IF(track_deg_dec!L6 <> "", _xlfn.CHOOSECOLS(_xlfn.TEXTSPLIT(track_deg_dec!L6,","),1), "")} | W6: =IF(track_deg_dec!L6 <> "", _xlfn.CONCAT("0,", _xlfn.CHOOSECOLS(_xlfn.TEXTSPLIT(track_deg_dec!L6,","),2))*60, "") | X6: {=IF(track_deg_dec!M6 <> "", _xlfn.CHOOSECOLS(_xlfn.TEXTSPLIT(track_deg_dec!M6,","),1), "")} | Y6: =IF(track_deg_dec!M6 <> "", _xlfn.CONCAT("0,", _xlfn.CHOOSECOLS(_xlfn.TEXTSPLIT(track_deg_dec!M6,","),2))*60, "") | Z6: {=IF(track_deg_dec!N6 <> "", _xlfn.CHOOSECOLS(_xlfn.TEXTSPLIT(track_deg_dec!N6,","),1), "")} | AA6: =IF(track_deg_dec!N6 <> "", _xlfn.CONCAT("0,", _xlfn.CHOOSECOLS(_xlfn.TEXTSPLIT(track_deg_dec!N6,","),2))*60, "") | AB6: {=IF(track_deg_dec!O6 <> "", _xlfn.CHOOSECOLS(_xlfn.TEXTSPLIT(track_deg_dec!O6,","),1), "")} | AC6: =IF(track_deg_dec!O6 <> "", _xlfn.CONCAT("0,", _xlfn.CHOOSECOLS(_xlfn.TEXTSPLIT(track_deg_dec!O6,","),2))*60, "") | AD6: {=IF(track_deg_dec!P6 <> "", _xlfn.CHOOSECOLS(_xlfn.TEXTSPLIT(track_deg_dec!P6,","),1), "")} | AE6: =IF(track_deg_dec!P6 <> "", _xlfn.CONCAT("0,", _xlfn.CHOOSECOLS(_xlfn.TEXTSPLIT(track_deg_dec!P6,","),2))*60, "") | AF6: {=IF(track_deg_dec!Q6 <> "", _xlfn.CHOOSECOLS(_xlfn.TEXTSPLIT(track_deg_dec!Q6,","),1), "")} | AG6: =IF(track_deg_dec!Q6 <> "", _xlfn.CONCAT("0,", _xlfn.CHOOSECOLS(_xlfn.TEXTSPLIT(track_deg_dec!Q6,","),2))*60, "") | AH6: {=IF(track_deg_dec!R6 <> "", _xlfn.CHOOSECOLS(_xlfn.TEXTSPLIT(track_deg_dec!R6,","),1), "")} | AI6: =IF(track_deg_dec!R6 <> "", _xlfn.CONCAT("0,", _xlfn.CHOOSECOLS(_xlfn.TEXTSPLIT(track_deg_dec!R6,","),2))*60, "") | AJ6: {=IF(track_deg_dec!S6 <> "", _xlfn.CHOOSECOLS(_xlfn.TEXTSPLIT(track_deg_dec!S6,","),1), "")} | AK6: =IF(track_deg_dec!S6 <> "", _xlfn.CONCAT("0,", _xlfn.CHOOSECOLS(_xlfn.TEXTSPLIT(track_deg_dec!S6,","),2))*60, "") | AL6: {=IF(track_deg_dec!T6 <> "", _xlfn.CHOOSECOLS(_xlfn.TEXTSPLIT(track_deg_dec!T6,","),1), "")} | AM6: =IF(track_deg_dec!T6 <> "", _xlfn.CONCAT("0,", _xlfn.CHOOSECOLS(_xlfn.TEXTSPLIT(track_deg_dec!T6,","),2))*60, "") | AN6: {=IF(track_deg_dec!U6 <> "", _xlfn.CHOOSECOLS(_xlfn.TEXTSPLIT(track_deg_dec!U6,","),1), "")} | AO6: =IF(track_deg_dec!U6 <> "", _xlfn.CONCAT("0,", _xlfn.CHOOSECOLS(_xlfn.TEXTSPLIT(track_deg_dec!U6,","),2))*60, "")
A7: =IF(track_deg_dec!A7 <> "", track_deg_dec!A7, "") -> 22007 | B7: {=IF(track_deg_dec!B7 <> "", _xlfn.CHOOSECOLS(_xlfn.TEXTSPLIT(track_deg_dec!B7,","),1), "")} -> 54 | C7: =IF(track_deg_dec!B7 <> "", _xlfn.CONCAT("0,", _xlfn.CHOOSECOLS(_xlfn.TEXTSPLIT(track_deg_dec!B7,","),2))*60, "") -> 27.13 | D7: {=IF(track_deg_dec!C7 <> "", _xlfn.CHOOSECOLS(_xlfn.TEXTSPLIT(track_deg_dec!C7,","),1), "")} -> 11 | E7: =IF(track_deg_dec!C7 <> "", _xlfn.CONCAT("0,", _xlfn.CHOOSECOLS(_xlfn.TEXTSPLIT(track_deg_dec!C7,","),2))*60, "") -> 23.18 | F7: {=IF(track_deg_dec!D7 <> "", _xlfn.CHOOSECOLS(_xlfn.TEXTSPLIT(track_deg_dec!D7,","),1), "")} -> 54 | G7: =IF(track_deg_dec!D7 <> "", _xlfn.CONCAT("0,", _xlfn.CHOOSECOLS(_xlfn.TEXTSPLIT(track_deg_dec!D7,","),2))*60, "") -> 23.17 | H7: {=IF(track_deg_dec!E7 <> "", _xlfn.CHOOSECOLS(_xlfn.TEXTSPLIT(track_deg_dec!E7,","),1), "")} -> 11 | I7: =IF(track_deg_dec!E7 <> "", _xlfn.CONCAT("0,", _xlfn.CHOOSECOLS(_xlfn.TEXTSPLIT(track_deg_dec!E7,","),2))*60, "") -> 22.24 | J7: {=IF(track_deg_dec!F7 <> "", _xlfn.CHOOSECOLS(_xlfn.TEXTSPLIT(track_deg_dec!F7,","),1), "")} | K7: =IF(track_deg_dec!F7 <> "", _xlfn.CONCAT("0,", _xlfn.CHOOSECOLS(_xlfn.TEXTSPLIT(track_deg_dec!F7,","),2))*60, "") | L7: {=IF(track_deg_dec!G7 <> "", _xlfn.CHOOSECOLS(_xlfn.TEXTSPLIT(track_deg_dec!G7,","),1), "")} | M7: =IF(track_deg_dec!G7 <> "", _xlfn.CONCAT("0,", _xlfn.CHOOSECOLS(_xlfn.TEXTSPLIT(track_deg_dec!G7,","),2))*60, "") | N7: {=IF(track_deg_dec!H7 <> "", _xlfn.CHOOSECOLS(_xlfn.TEXTSPLIT(track_deg_dec!H7,","),1), "")} | O7: =IF(track_deg_dec!H7 <> "", _xlfn.CONCAT("0,", _xlfn.CHOOSECOLS(_xlfn.TEXTSPLIT(track_deg_dec!H7,","),2))*60, "") | P7: {=IF(track_deg_dec!I7 <> "", _xlfn.CHOOSECOLS(_xlfn.TEXTSPLIT(track_deg_dec!I7,","),1), "")} | Q7: =IF(track_deg_dec!I7 <> "", _xlfn.CONCAT("0,", _xlfn.CHOOSECOLS(_xlfn.TEXTSPLIT(track_deg_dec!I7,","),2))*60, "") | R7: {=IF(track_deg_dec!J7 <> "", _xlfn.CHOOSECOLS(_xlfn.TEXTSPLIT(track_deg_dec!J7,","),1), "")} | S7: =IF(track_deg_dec!J7 <> "", _xlfn.CONCAT("0,", _xlfn.CHOOSECOLS(_xlfn.TEXTSPLIT(track_deg_dec!J7,","),2))*60, "") | T7: {=IF(track_deg_dec!K7 <> "", _xlfn.CHOOSECOLS(_xlfn.TEXTSPLIT(track_deg_dec!K7,","),1), "")} | U7: =IF(track_deg_dec!K7 <> "", _xlfn.CONCAT("0,", _xlfn.CHOOSECOLS(_xlfn.TEXTSPLIT(track_deg_dec!K7,","),2))*60, "") | V7: {=IF(track_deg_dec!L7 <> "", _xlfn.CHOOSECOLS(_xlfn.TEXTSPLIT(track_deg_dec!L7,","),1), "")} | W7: =IF(track_deg_dec!L7 <> "", _xlfn.CONCAT("0,", _xlfn.CHOOSECOLS(_xlfn.TEXTSPLIT(track_deg_dec!L7,","),2))*60, "") | X7: {=IF(track_deg_dec!M7 <> "", _xlfn.CHOOSECOLS(_xlfn.TEXTSPLIT(track_deg_dec!M7,","),1), "")} | Y7: =IF(track_deg_dec!M7 <> "", _xlfn.CONCAT("0,", _xlfn.CHOOSECOLS(_xlfn.TEXTSPLIT(track_deg_dec!M7,","),2))*60, "") | Z7: {=IF(track_deg_dec!N7 <> "", _xlfn.CHOOSECOLS(_xlfn.TEXTSPLIT(track_deg_dec!N7,","),1), "")} | AA7: =IF(track_deg_dec!N7 <> "", _xlfn.CONCAT("0,", _xlfn.CHOOSECOLS(_xlfn.TEXTSPLIT(track_deg_dec!N7,","),2))*60, "") | AB7: {=IF(track_deg_dec!O7 <> "", _xlfn.CHOOSECOLS(_xlfn.TEXTSPLIT(track_deg_dec!O7,","),1), "")} | AC7: =IF(track_deg_dec!O7 <> "", _xlfn.CONCAT("0,", _xlfn.CHOOSECOLS(_xlfn.TEXTSPLIT(track_deg_dec!O7,","),2))*60, "") | AD7: {=IF(track_deg_dec!P7 <> "", _xlfn.CHOOSECOLS(_xlfn.TEXTSPLIT(track_deg_dec!P7,","),1), "")} | AE7: =IF(track_deg_dec!P7 <> "", _xlfn.CONCAT("0,", _xlfn.CHOOSECOLS(_xlfn.TEXTSPLIT(track_deg_dec!P7,","),2))*60, "") | AF7: {=IF(track_deg_dec!Q7 <> "", _xlfn.CHOOSECOLS(_xlfn.TEXTSPLIT(track_deg_dec!Q7,","),1), "")} | AG7: =IF(track_deg_dec!Q7 <> "", _xlfn.CONCAT("0,", _xlfn.CHOOSECOLS(_xlfn.TEXTSPLIT(track_deg_dec!Q7,","),2))*60, "") | AH7: {=IF(track_deg_dec!R7 <> "", _xlfn.CHOOSECOLS(_xlfn.TEXTSPLIT(track_deg_dec!R7,","),1), "")} | AI7: =IF(track_deg_dec!R7 <> "", _xlfn.CONCAT("0,", _xlfn.CHOOSECOLS(_xlfn.TEXTSPLIT(track_deg_dec!R7,","),2))*60, "") | AJ7: {=IF(track_deg_dec!S7 <> "", _xlfn.CHOOSECOLS(_xlfn.TEXTSPLIT(track_deg_dec!S7,","),1), "")} | AK7: =IF(track_deg_dec!S7 <> "", _xlfn.CONCAT("0,", _xlfn.CHOOSECOLS(_xlfn.TEXTSPLIT(track_deg_dec!S7,","),2))*60, "") | AL7: {=IF(track_deg_dec!T7 <> "", _xlfn.CHOOSECOLS(_xlfn.TEXTSPLIT(track_deg_dec!T7,","),1), "")} | AM7: =IF(track_deg_dec!T7 <> "", _xlfn.CONCAT("0,", _xlfn.CHOOSECOLS(_xlfn.TEXTSPLIT(track_deg_dec!T7,","),2))*60, "") | AN7: {=IF(track_deg_dec!U7 <> "", _xlfn.CHOOSECOLS(_xlfn.TEXTSPLIT(track_deg_dec!U7,","),1), "")} | AO7: =IF(track_deg_dec!U7 <> "", _xlfn.CONCAT("0,", _xlfn.CHOOSECOLS(_xlfn.TEXTSPLIT(track_deg_dec!U7,","),2))*60, "")
A8: =IF(track_deg_dec!A8 <> "", track_deg_dec!A8, "") -> 22008 | B8: {=IF(track_deg_dec!B8 <> "", _xlfn.CHOOSECOLS(_xlfn.TEXTSPLIT(track_deg_dec!B8,","),1), "")} -> 54 | C8: =IF(track_deg_dec!B8 <> "", _xlfn.CONCAT("0,", _xlfn.CHOOSECOLS(_xlfn.TEXTSPLIT(track_deg_dec!B8,","),2))*60, "") -> 20.8 | D8: {=IF(track_deg_dec!C8 <> "", _xlfn.CHOOSECOLS(_xlfn.TEXTSPLIT(track_deg_dec!C8,","),1), "")} -> 11 | E8: =IF(track_deg_dec!C8 <> "", _xlfn.CONCAT("0,", _xlfn.CHOOSECOLS(_xlfn.TEXTSPLIT(track_deg_dec!C8,","),2))*60, "") -> 55.3 | F8: {=IF(track_deg_dec!D8 <> "", _xlfn.CHOOSECOLS(_xlfn.TEXTSPLIT(track_deg_dec!D8,","),1), "")} -> 54 | G8: =IF(track_deg_dec!D8 <> "", _xlfn.CONCAT("0,", _xlfn.CHOOSECOLS(_xlfn.TEXTSPLIT(track_deg_dec!D8,","),2))*60, "") -> 18.5 | H8: {=IF(track_deg_dec!E8 <> "", _xlfn.CHOOSECOLS(_xlfn.TEXTSPLIT(track_deg_dec!E8,","),1), "")} -> 11 | I8: =IF(track_deg_dec!E8 <> "", _xlfn.CONCAT("0,", _xlfn.CHOOSECOLS(_xlfn.TEXTSPLIT(track_deg_dec!E8,","),2))*60, "") -> 55.4 | J8: {=IF(track_deg_dec!F8 <> "", _xlfn.CHOOSECOLS(_xlfn.TEXTSPLIT(track_deg_dec!F8,","),1), "")} | K8: =IF(track_deg_dec!F8 <> "", _xlfn.CONCAT("0,", _xlfn.CHOOSECOLS(_xlfn.TEXTSPLIT(track_deg_dec!F8,","),2))*60, "") | L8: {=IF(track_deg_dec!G8 <> "", _xlfn.CHOOSECOLS(_xlfn.TEXTSPLIT(track_deg_dec!G8,","),1), "")} | M8: =IF(track_deg_dec!G8 <> "", _xlfn.CONCAT("0,", _xlfn.CHOOSECOLS(_xlfn.TEXTSPLIT(track_deg_dec!G8,","),2))*60, "") | N8: {=IF(track_deg_dec!H8 <> "", _xlfn.CHOOSECOLS(_xlfn.TEXTSPLIT(track_deg_dec!H8,","),1), "")} | O8: =IF(track_deg_dec!H8 <> "", _xlfn.CONCAT("0,", _xlfn.CHOOSECOLS(_xlfn.TEXTSPLIT(track_deg_dec!H8,","),2))*60, "") | P8: {=IF(track_deg_dec!I8 <> "", _xlfn.CHOOSECOLS(_xlfn.TEXTSPLIT(track_deg_dec!I8,","),1), "")} | Q8: =IF(track_deg_dec!I8 <> "", _xlfn.CONCAT("0,", _xlfn.CHOOSECOLS(_xlfn.TEXTSPLIT(track_deg_dec!I8,","),2))*60, "") | R8: {=IF(track_deg_dec!J8 <> "", _xlfn.CHOOSECOLS(_xlfn.TEXTSPLIT(track_deg_dec!J8,","),1), "")} | S8: =IF(track_deg_dec!J8 <> "", _xlfn.CONCAT("0,", _xlfn.CHOOSECOLS(_xlfn.TEXTSPLIT(track_deg_dec!J8,","),2))*60, "") | T8: {=IF(track_deg_dec!K8 <> "", _xlfn.CHOOSECOLS(_xlfn.TEXTSPLIT(track_deg_dec!K8,","),1), "")} | U8: =IF(track_deg_dec!K8 <> "", _xlfn.CONCAT("0,", _xlfn.CHOOSECOLS(_xlfn.TEXTSPLIT(track_deg_dec!K8,","),2))*60, "") | V8: {=IF(track_deg_dec!L8 <> "", _xlfn.CHOOSECOLS(_xlfn.TEXTSPLIT(track_deg_dec!L8,","),1), "")} | W8: =IF(track_deg_dec!L8 <> "", _xlfn.CONCAT("0,", _xlfn.CHOOSECOLS(_xlfn.TEXTSPLIT(track_deg_dec!L8,","),2))*60, "") | X8: {=IF(track_deg_dec!M8 <> "", _xlfn.CHOOSECOLS(_xlfn.TEXTSPLIT(track_deg_dec!M8,","),1), "")} | Y8: =IF(track_deg_dec!M8 <> "", _xlfn.CONCAT("0,", _xlfn.CHOOSECOLS(_xlfn.TEXTSPLIT(track_deg_dec!M8,","),2))*60, "") | Z8: {=IF(track_deg_dec!N8 <> "", _xlfn.CHOOSECOLS(_xlfn.TEXTSPLIT(track_deg_dec!N8,","),1), "")} | AA8: =IF(track_deg_dec!N8 <> "", _xlfn.CONCAT("0,", _xlfn.CHOOSECOLS(_xlfn.TEXTSPLIT(track_deg_dec!N8,","),2))*60, "") | AB8: {=IF(track_deg_dec!O8 <> "", _xlfn.CHOOSECOLS(_xlfn.TEXTSPLIT(track_deg_dec!O8,","),1), "")} | AC8: =IF(track_deg_dec!O8 <> "", _xlfn.CONCAT("0,", _xlfn.CHOOSECOLS(_xlfn.TEXTSPLIT(track_deg_dec!O8,","),2))*60, "") | AD8: {=IF(track_deg_dec!P8 <> "", _xlfn.CHOOSECOLS(_xlfn.TEXTSPLIT(track_deg_dec!P8,","),1), "")} | AE8: =IF(track_deg_dec!P8 <> "", _xlfn.CONCAT("0,", _xlfn.CHOOSECOLS(_xlfn.TEXTSPLIT(track_deg_dec!P8,","),2))*60, "") | AF8: {=IF(track_deg_dec!Q8 <> "", _xlfn.CHOOSECOLS(_xlfn.TEXTSPLIT(track_deg_dec!Q8,","),1), "")} | AG8: =IF(track_deg_dec!Q8 <> "", _xlfn.CONCAT("0,", _xlfn.CHOOSECOLS(_xlfn.TEXTSPLIT(track_deg_dec!Q8,","),2))*60, "") | AH8: {=IF(track_deg_dec!R8 <> "", _xlfn.CHOOSECOLS(_xlfn.TEXTSPLIT(track_deg_dec!R8,","),1), "")} | AI8: =IF(track_deg_dec!R8 <> "", _xlfn.CONCAT("0,", _xlfn.CHOOSECOLS(_xlfn.TEXTSPLIT(track_deg_dec!R8,","),2))*60, "") | AJ8: {=IF(track_deg_dec!S8 <> "", _xlfn.CHOOSECOLS(_xlfn.TEXTSPLIT(track_deg_dec!S8,","),1), "")} | AK8: =IF(track_deg_dec!S8 <> "", _xlfn.CONCAT("0,", _xlfn.CHOOSECOLS(_xlfn.TEXTSPLIT(track_deg_dec!S8,","),2))*60, "") | AL8: {=IF(track_deg_dec!T8 <> "", _xlfn.CHOOSECOLS(_xlfn.TEXTSPLIT(track_deg_dec!T8,","),1), "")} | AM8: =IF(track_deg_dec!T8 <> "", _xlfn.CONCAT("0,", _xlfn.CHOOSECOLS(_xlfn.TEXTSPLIT(track_deg_dec!T8,","),2))*60, "") | AN8: {=IF(track_deg_dec!U8 <> "", _xlfn.CHOOSECOLS(_xlfn.TEXTSPLIT(track_deg_dec!U8,","),1), "")} | AO8: =IF(track_deg_dec!U8 <> "", _xlfn.CONCAT("0,", _xlfn.CHOOSECOLS(_xlfn.TEXTSPLIT(track_deg_dec!U8,","),2))*60, "")
A9: =IF(track_deg_dec!A9 <> "", track_deg_dec!A9, "") -> 22011 | B9: {=IF(track_deg_dec!B9 <> "", _xlfn.CHOOSECOLS(_xlfn.TEXTSPLIT(track_deg_dec!B9,","),1), "")} -> 54 | C9: =IF(track_deg_dec!B9 <> "", _xlfn.CONCAT("0,", _xlfn.CHOOSECOLS(_xlfn.TEXTSPLIT(track_deg_dec!B9,","),2))*60, "") -> 34.55 | D9: {=IF(track_deg_dec!C9 <> "", _xlfn.CHOOSECOLS(_xlfn.TEXTSPLIT(track_deg_dec!C9,","),1), "")} -> 10 | E9: =IF(track_deg_dec!C9 <> "", _xlfn.CONCAT("0,", _xlfn.CHOOSECOLS(_xlfn.TEXTSPLIT(track_deg_dec!C9,","),2))*60, "") -> 10.19 | F9: {=IF(track_deg_dec!D9 <> "", _xlfn.CHOOSECOLS(_xlfn.TEXTSPLIT(track_deg_dec!D9,","),1), "")} -> 54 | G9: =IF(track_deg_dec!D9 <> "", _xlfn.CONCAT("0,", _xlfn.CHOOSECOLS(_xlfn.TEXTSPLIT(track_deg_dec!D9,","),2))*60, "") -> 33.53 | H9: {=IF(track_deg_dec!E9 <> "", _xlfn.CHOOSECOLS(_xlfn.TEXTSPLIT(track_deg_dec!E9,","),1), "")} -> 10 | I9: =IF(track_deg_dec!E9 <> "", _xlfn.CONCAT("0,", _xlfn.CHOOSECOLS(_xlfn.TEXTSPLIT(track_deg_dec!E9,","),2))*60, "") -> 14.12 | J9: {=IF(track_deg_dec!F9 <> "", _xlfn.CHOOSECOLS(_xlfn.TEXTSPLIT(track_deg_dec!F9,","),1), "")} | K9: =IF(track_deg_dec!F9 <> "", _xlfn.CONCAT("0,", _xlfn.CHOOSECOLS(_xlfn.TEXTSPLIT(track_deg_dec!F9,","),2))*60, "") | L9: {=IF(track_deg_dec!G9 <> "", _xlfn.CHOOSECOLS(_xlfn.TEXTSPLIT(track_deg_dec!G9,","),1), "")} | M9: =IF(track_deg_dec!G9 <> "", _xlfn.CONCAT("0,", _xlfn.CHOOSECOLS(_xlfn.TEXTSPLIT(track_deg_dec!G9,","),2))*60, "") | N9: {=IF(track_deg_dec!H9 <> "", _xlfn.CHOOSECOLS(_xlfn.TEXTSPLIT(track_deg_dec!H9,","),1), "")} | O9: =IF(track_deg_dec!H9 <> "", _xlfn.CONCAT("0,", _xlfn.CHOOSECOLS(_xlfn.TEXTSPLIT(track_deg_dec!H9,","),2))*60, "") | P9: {=IF(track_deg_dec!I9 <> "", _xlfn.CHOOSECOLS(_xlfn.TEXTSPLIT(track_deg_dec!I9,","),1), "")} | Q9: =IF(track_deg_dec!I9 <> "", _xlfn.CONCAT("0,", _xlfn.CHOOSECOLS(_xlfn.TEXTSPLIT(track_deg_dec!I9,","),2))*60, "") | R9: {=IF(track_deg_dec!J9 <> "", _xlfn.CHOOSECOLS(_xlfn.TEXTSPLIT(track_deg_dec!J9,","),1), "")} | S9: =IF(track_deg_dec!J9 <> "", _xlfn.CONCAT("0,", _xlfn.CHOOSECOLS(_xlfn.TEXTSPLIT(track_deg_dec!J9,","),2))*60, "") | T9: {=IF(track_deg_dec!K9 <> "", _xlfn.CHOOSECOLS(_xlfn.TEXTSPLIT(track_deg_dec!K9,","),1), "")} | U9: =IF(track_deg_dec!K9 <> "", _xlfn.CONCAT("0,", _xlfn.CHOOSECOLS(_xlfn.TEXTSPLIT(track_deg_dec!K9,","),2))*60, "") | V9: {=IF(track_deg_dec!L9 <> "", _xlfn.CHOOSECOLS(_xlfn.TEXTSPLIT(track_deg_dec!L9,","),1), "")} | W9: =IF(track_deg_dec!L9 <> "", _xlfn.CONCAT("0,", _xlfn.CHOOSECOLS(_xlfn.TEXTSPLIT(track_deg_dec!L9,","),2))*60, "") | X9: {=IF(track_deg_dec!M9 <> "", _xlfn.CHOOSECOLS(_xlfn.TEXTSPLIT(track_deg_dec!M9,","),1), "")} | Y9: =IF(track_deg_dec!M9 <> "", _xlfn.CONCAT("0,", _xlfn.CHOOSECOLS(_xlfn.TEXTSPLIT(track_deg_dec!M9,","),2))*60, "") | Z9: {=IF(track_deg_dec!N9 <> "", _xlfn.CHOOSECOLS(_xlfn.TEXTSPLIT(track_deg_dec!N9,","),1), "")} | AA9: =IF(track_deg_dec!N9 <> "", _xlfn.CONCAT("0,", _xlfn.CHOOSECOLS(_xlfn.TEXTSPLIT(track_deg_dec!N9,","),2))*60, "") | AB9: {=IF(track_deg_dec!O9 <> "", _xlfn.CHOOSECOLS(_xlfn.TEXTSPLIT(track_deg_dec!O9,","),1), "")} | AC9: =IF(track_deg_dec!O9 <> "", _xlfn.CONCAT("0,", _xlfn.CHOOSECOLS(_xlfn.TEXTSPLIT(track_deg_dec!O9,","),2))*60, "") | AD9: {=IF(track_deg_dec!P9 <> "", _xlfn.CHOOSECOLS(_xlfn.TEXTSPLIT(track_deg_dec!P9,","),1), "")} | AE9: =IF(track_deg_dec!P9 <> "", _xlfn.CONCAT("0,", _xlfn.CHOOSECOLS(_xlfn.TEXTSPLIT(track_deg_dec!P9,","),2))*60, "") | AF9: {=IF(track_deg_dec!Q9 <> "", _xlfn.CHOOSECOLS(_xlfn.TEXTSPLIT(track_deg_dec!Q9,","),1), "")} | AG9: =IF(track_deg_dec!Q9 <> "", _xlfn.CONCAT("0,", _xlfn.CHOOSECOLS(_xlfn.TEXTSPLIT(track_deg_dec!Q9,","),2))*60, "") | AH9: {=IF(track_deg_dec!R9 <> "", _xlfn.CHOOSECOLS(_xlfn.TEXTSPLIT(track_deg_dec!R9,","),1), "")} | AI9: =IF(track_deg_dec!R9 <> "", _xlfn.CONCAT("0,", _xlfn.CHOOSECOLS(_xlfn.TEXTSPLIT(track_deg_dec!R9,","),2))*60, "") | AJ9: {=IF(track_deg_dec!S9 <> "", _xlfn.CHOOSECOLS(_xlfn.TEXTSPLIT(track_deg_dec!S9,","),1), "")} | AK9: =IF(track_deg_dec!S9 <> "", _xlfn.CONCAT("0,", _xlfn.CHOOSECOLS(_xlfn.TEXTSPLIT(track_deg_dec!S9,","),2))*60, "") | AL9: {=IF(track_deg_dec!T9 <> "", _xlfn.CHOOSECOLS(_xlfn.TEXTSPLIT(track_deg_dec!T9,","),1), "")} | AM9: =IF(track_deg_dec!T9 <> "", _xlfn.CONCAT("0,", _xlfn.CHOOSECOLS(_xlfn.TEXTSPLIT(track_deg_dec!T9,","),2))*60, "") | AN9: {=IF(track_deg_dec!U9 <> "", _xlfn.CHOOSECOLS(_xlfn.TEXTSPLIT(track_deg_dec!U9,","),1), "")} | AO9: =IF(track_deg_dec!U9 <> "", _xlfn.CONCAT("0,", _xlfn.CHOOSECOLS(_xlfn.TEXTSPLIT(track_deg_dec!U9,","),2))*60, "")
A10: =IF(track_deg_dec!A10 <> "", track_deg_dec!A10, "") -> 22012 | B10: {=IF(track_deg_dec!B10 <> "", _xlfn.CHOOSECOLS(_xlfn.TEXTSPLIT(track_deg_dec!B10,","),1), "")} -> 54 | C10: =IF(track_deg_dec!B10 <> "", _xlfn.CONCAT("0,", _xlfn.CHOOSECOLS(_xlfn.TEXTSPLIT(track_deg_dec!B10,","),2))*60, "") -> 25.22 | D10: {=IF(track_deg_dec!C10 <> "", _xlfn.CHOOSECOLS(_xlfn.TEXTSPLIT(track_deg_dec!C10,","),1), "")} -> 11 | E10: =IF(track_deg_dec!C10 <> "", _xlfn.CONCAT("0,", _xlfn.CHOOSECOLS(_xlfn.TEXTSPLIT(track_deg_dec!C10,","),2))*60, "") -> 31.07 | F10: {=IF(track_deg_dec!D10 <> "", _xlfn.CHOOSECOLS(_xlfn.TEXTSPLIT(track_deg_dec!D10,","),1), "")} -> 54 | G10: =IF(track_deg_dec!D10 <> "", _xlfn.CONCAT("0,", _xlfn.CHOOSECOLS(_xlfn.TEXTSPLIT(track_deg_dec!D10,","),2))*60, "") -> 23.61 | H10: {=IF(track_deg_dec!E10 <> "", _xlfn.CHOOSECOLS(_xlfn.TEXTSPLIT(track_deg_dec!E10,","),1), "")} -> 11 | I10: =IF(track_deg_dec!E10 <> "", _xlfn.CONCAT("0,", _xlfn.CHOOSECOLS(_xlfn.TEXTSPLIT(track_deg_dec!E10,","),2))*60, "") -> 30.54 | J10: {=IF(track_deg_dec!F10 <> "", _xlfn.CHOOSECOLS(_xlfn.TEXTSPLIT(track_deg_dec!F10,","),1), "")} | K10: =IF(track_deg_dec!F10 <> "", _xlfn.CONCAT("0,", _xlfn.CHOOSECOLS(_xlfn.TEXTSPLIT(track_deg_dec!F10,","),2))*60, "") | L10: {=IF(track_deg_dec!G10 <> "", _xlfn.CHOOSECOLS(_xlfn.TEXTSPLIT(track_deg_dec!G10,","),1), "")} | M10: =IF(track_deg_dec!G10 <> "", _xlfn.CONCAT("0,", _xlfn.CHOOSECOLS(_xlfn.TEXTSPLIT(track_deg_dec!G10,","),2))*60, "") | N10: {=IF(track_deg_dec!H10 <> "", _xlfn.CHOOSECOLS(_xlfn.TEXTSPLIT(track_deg_dec!H10,","),1), "")} | O10: =IF(track_deg_dec!H10 <> "", _xlfn.CONCAT("0,", _xlfn.CHOOSECOLS(_xlfn.TEXTSPLIT(track_deg_dec!H10,","),2))*60, "") | P10: {=IF(track_deg_dec!I10 <> "", _xlfn.CHOOSECOLS(_xlfn.TEXTSPLIT(track_deg_dec!I10,","),1), "")} | Q10: =IF(track_deg_dec!I10 <> "", _xlfn.CONCAT("0,", _xlfn.CHOOSECOLS(_xlfn.TEXTSPLIT(track_deg_dec!I10,","),2))*60, "") | R10: {=IF(track_deg_dec!J10 <> "", _xlfn.CHOOSECOLS(_xlfn.TEXTSPLIT(track_deg_dec!J10,","),1), "")} | S10: =IF(track_deg_dec!J10 <> "", _xlfn.CONCAT("0,", _xlfn.CHOOSECOLS(_xlfn.TEXTSPLIT(track_deg_dec!J10,","),2))*60, "") | T10: {=IF(track_deg_dec!K10 <> "", _xlfn.CHOOSECOLS(_xlfn.TEXTSPLIT(track_deg_dec!K10,","),1), "")} | U10: =IF(track_deg_dec!K10 <> "", _xlfn.CONCAT("0,", _xlfn.CHOOSECOLS(_xlfn.TEXTSPLIT(track_deg_dec!K10,","),2))*60, "") | V10: {=IF(track_deg_dec!L10 <> "", _xlfn.CHOOSECOLS(_xlfn.TEXTSPLIT(track_deg_dec!L10,","),1), "")} | W10: =IF(track_deg_dec!L10 <> "", _xlfn.CONCAT("0,", _xlfn.CHOOSECOLS(_xlfn.TEXTSPLIT(track_deg_dec!L10,","),2))*60, "") | X10: {=IF(track_deg_dec!M10 <> "", _xlfn.CHOOSECOLS(_xlfn.TEXTSPLIT(track_deg_dec!M10,","),1), "")} | Y10: =IF(track_deg_dec!M10 <> "", _xlfn.CONCAT("0,", _xlfn.CHOOSECOLS(_xlfn.TEXTSPLIT(track_deg_dec!M10,","),2))*60, "") | Z10: {=IF(track_deg_dec!N10 <> "", _xlfn.CHOOSECOLS(_xlfn.TEXTSPLIT(track_deg_dec!N10,","),1), "")} | AA10: =IF(track_deg_dec!N10 <> "", _xlfn.CONCAT("0,", _xlfn.CHOOSECOLS(_xlfn.TEXTSPLIT(track_deg_dec!N10,","),2))*60, "") | AB10: {=IF(track_deg_dec!O10 <> "", _xlfn.CHOOSECOLS(_xlfn.TEXTSPLIT(track_deg_dec!O10,","),1), "")} | AC10: =IF(track_deg_dec!O10 <> "", _xlfn.CONCAT("0,", _xlfn.CHOOSECOLS(_xlfn.TEXTSPLIT(track_deg_dec!O10,","),2))*60, "") | AD10: {=IF(track_deg_dec!P10 <> "", _xlfn.CHOOSECOLS(_xlfn.TEXTSPLIT(track_deg_dec!P10,","),1), "")} | AE10: =IF(track_deg_dec!P10 <> "", _xlfn.CONCAT("0,", _xlfn.CHOOSECOLS(_xlfn.TEXTSPLIT(track_deg_dec!P10,","),2))*60, "") | AF10: {=IF(track_deg_dec!Q10 <> "", _xlfn.CHOOSECOLS(_xlfn.TEXTSPLIT(track_deg_dec!Q10,","),1), "")} | AG10: =IF(track_deg_dec!Q10 <> "", _xlfn.CONCAT("0,", _xlfn.CHOOSECOLS(_xlfn.TEXTSPLIT(track_deg_dec!Q10,","),2))*60, "") | AH10: {=IF(track_deg_dec!R10 <> "", _xlfn.CHOOSECOLS(_xlfn.TEXTSPLIT(track_deg_dec!R10,","),1), "")} | AI10: =IF(track_deg_dec!R10 <> "", _xlfn.CONCAT("0,", _xlfn.CHOOSECOLS(_xlfn.TEXTSPLIT(track_deg_dec!R10,","),2))*60, "") | AJ10: {=IF(track_deg_dec!S10 <> "", _xlfn.CHOOSECOLS(_xlfn.TEXTSPLIT(track_deg_dec!S10,","),1), "")} | AK10: =IF(track_deg_dec!S10 <> "", _xlfn.CONCAT("0,", _xlfn.CHOOSECOLS(_xlfn.TEXTSPLIT(track_deg_dec!S10,","),2))*60, "") | AL10: {=IF(track_deg_dec!T10 <> "", _xlfn.CHOOSECOLS(_xlfn.TEXTSPLIT(track_deg_dec!T10,","),1), "")} | AM10: =IF(track_deg_dec!T10 <> "", _xlfn.CONCAT("0,", _xlfn.CHOOSECOLS(_xlfn.TEXTSPLIT(track_deg_dec!T10,","),2))*60, "") | AN10: {=IF(track_deg_dec!U10 <> "", _xlfn.CHOOSECOLS(_xlfn.TEXTSPLIT(track_deg_dec!U10,","),1), "")} | AO10: =IF(track_deg_dec!U10 <> "", _xlfn.CONCAT("0,", _xlfn.CHOOSECOLS(_xlfn.TEXTSPLIT(track_deg_dec!U10,","),2))*60, "")
A11: =IF(track_deg_dec!A11 <> "", track_deg_dec!A11, "") -> 22013 | B11: {=IF(track_deg_dec!B11 <> "", _xlfn.CHOOSECOLS(_xlfn.TEXTSPLIT(track_deg_dec!B11,","),1), "")} -> 54 | C11: =IF(track_deg_dec!B11 <> "", _xlfn.CONCAT("0,", _xlfn.CHOOSECOLS(_xlfn.TEXTSPLIT(track_deg_dec!B11,","),2))*60, "") -> 31.38 | D11: {=IF(track_deg_dec!C11 <> "", _xlfn.CHOOSECOLS(_xlfn.TEXTSPLIT(track_deg_dec!C11,","),1), "")} -> 11 | E11: =IF(track_deg_dec!C11 <> "", _xlfn.CONCAT("0,", _xlfn.CHOOSECOLS(_xlfn.TEXTSPLIT(track_deg_dec!C11,","),2))*60, "") -> 19.27 | F11: {=IF(track_deg_dec!D11 <> "", _xlfn.CHOOSECOLS(_xlfn.TEXTSPLIT(track_deg_dec!D11,","),1), "")} -> 54 | G11: =IF(track_deg_dec!D11 <> "", _xlfn.CONCAT("0,", _xlfn.CHOOSECOLS(_xlfn.TEXTSPLIT(track_deg_dec!D11,","),2))*60, "") -> 30.17 | H11: {=IF(track_deg_dec!E11 <> "", _xlfn.CHOOSECOLS(_xlfn.TEXTSPLIT(track_deg_dec!E11,","),1), "")} -> 11 | I11: =IF(track_deg_dec!E11 <> "", _xlfn.CONCAT("0,", _xlfn.CHOOSECOLS(_xlfn.TEXTSPLIT(track_deg_dec!E11,","),2))*60, "") -> 21.19 | J11: {=IF(track_deg_dec!F11 <> "", _xlfn.CHOOSECOLS(_xlfn.TEXTSPLIT(track_deg_dec!F11,","),1), "")} | K11: =IF(track_deg_dec!F11 <> "", _xlfn.CONCAT("0,", _xlfn.CHOOSECOLS(_xlfn.TEXTSPLIT(track_deg_dec!F11,","),2))*60, "") | L11: {=IF(track_deg_dec!G11 <> "", _xlfn.CHOOSECOLS(_xlfn.TEXTSPLIT(track_deg_dec!G11,","),1), "")} | M11: =IF(track_deg_dec!G11 <> "", _xlfn.CONCAT("0,", _xlfn.CHOOSECOLS(_xlfn.TEXTSPLIT(track_deg_dec!G11,","),2))*60, "") | N11: {=IF(track_deg_dec!H11 <> "", _xlfn.CHOOSECOLS(_xlfn.TEXTSPLIT(track_deg_dec!H11,","),1), "")} | O11: =IF(track_deg_dec!H11 <> "", _xlfn.CONCAT("0,", _xlfn.CHOOSECOLS(_xlfn.TEXTSPLIT(track_deg_dec!H11,","),2))*60, "") | P11: {=IF(track_deg_dec!I11 <> "", _xlfn.CHOOSECOLS(_xlfn.TEXTSPLIT(track_deg_dec!I11,","),1), "")} | Q11: =IF(track_deg_dec!I11 <> "", _xlfn.CONCAT("0,", _xlfn.CHOOSECOLS(_xlfn.TEXTSPLIT(track_deg_dec!I11,","),2))*60, "") | R11: {=IF(track_deg_dec!J11 <> "", _xlfn.CHOOSECOLS(_xlfn.TEXTSPLIT(track_deg_dec!J11,","),1), "")} | S11: =IF(track_deg_dec!J11 <> "", _xlfn.CONCAT("0,", _xlfn.CHOOSECOLS(_xlfn.TEXTSPLIT(track_deg_dec!J11,","),2))*60, "") | T11: {=IF(track_deg_dec!K11 <> "", _xlfn.CHOOSECOLS(_xlfn.TEXTSPLIT(track_deg_dec!K11,","),1), "")} | U11: =IF(track_deg_dec!K11 <> "", _xlfn.CONCAT("0,", _xlfn.CHOOSECOLS(_xlfn.TEXTSPLIT(track_deg_dec!K11,","),2))*60, "") | V11: {=IF(track_deg_dec!L11 <> "", _xlfn.CHOOSECOLS(_xlfn.TEXTSPLIT(track_deg_dec!L11,","),1), "")} | W11: =IF(track_deg_dec!L11 <> "", _xlfn.CONCAT("0,", _xlfn.CHOOSECOLS(_xlfn.TEXTSPLIT(track_deg_dec!L11,","),2))*60, "") | X11: {=IF(track_deg_dec!M11 <> "", _xlfn.CHOOSECOLS(_xlfn.TEXTSPLIT(track_deg_dec!M11,","),1), "")} | Y11: =IF(track_deg_dec!M11 <> "", _xlfn.CONCAT("0,", _xlfn.CHOOSECOLS(_xlfn.TEXTSPLIT(track_deg_dec!M11,","),2))*60, "") | Z11: {=IF(track_deg_dec!N11 <> "", _xlfn.CHOOSECOLS(_xlfn.TEXTSPLIT(track_deg_dec!N11,","),1), "")} | AA11: =IF(track_deg_dec!N11 <> "", _xlfn.CONCAT("0,", _xlfn.CHOOSECOLS(_xlfn.TEXTSPLIT(track_deg_dec!N11,","),2))*60, "") | AB11: {=IF(track_deg_dec!O11 <> "", _xlfn.CHOOSECOLS(_xlfn.TEXTSPLIT(track_deg_dec!O11,","),1), "")} | AC11: =IF(track_deg_dec!O11 <> "", _xlfn.CONCAT("0,", _xlfn.CHOOSECOLS(_xlfn.TEXTSPLIT(track_deg_dec!O11,","),2))*60, "") | AD11: {=IF(track_deg_dec!P11 <> "", _xlfn.CHOOSECOLS(_xlfn.TEXTSPLIT(track_deg_dec!P11,","),1), "")} | AE11: =IF(track_deg_dec!P11 <> "", _xlfn.CONCAT("0,", _xlfn.CHOOSECOLS(_xlfn.TEXTSPLIT(track_deg_dec!P11,","),2))*60, "") | AF11: {=IF(track_deg_dec!Q11 <> "", _xlfn.CHOOSECOLS(_xlfn.TEXTSPLIT(track_deg_dec!Q11,","),1), "")} | AG11: =IF(track_deg_dec!Q11 <> "", _xlfn.CONCAT("0,", _xlfn.CHOOSECOLS(_xlfn.TEXTSPLIT(track_deg_dec!Q11,","),2))*60, "") | AH11: {=IF(track_deg_dec!R11 <> "", _xlfn.CHOOSECOLS(_xlfn.TEXTSPLIT(track_deg_dec!R11,","),1), "")} | AI11: =IF(track_deg_dec!R11 <> "", _xlfn.CONCAT("0,", _xlfn.CHOOSECOLS(_xlfn.TEXTSPLIT(track_deg_dec!R11,","),2))*60, "") | AJ11: {=IF(track_deg_dec!S11 <> "", _xlfn.CHOOSECOLS(_xlfn.TEXTSPLIT(track_deg_dec!S11,","),1), "")} | AK11: =IF(track_deg_dec!S11 <> "", _xlfn.CONCAT("0,", _xlfn.CHOOSECOLS(_xlfn.TEXTSPLIT(track_deg_dec!S11,","),2))*60, "") | AL11: {=IF(track_deg_dec!T11 <> "", _xlfn.CHOOSECOLS(_xlfn.TEXTSPLIT(track_deg_dec!T11,","),1), "")} | AM11: =IF(track_deg_dec!T11 <> "", _xlfn.CONCAT("0,", _xlfn.CHOOSECOLS(_xlfn.TEXTSPLIT(track_deg_dec!T11,","),2))*60, "") | AN11: {=IF(track_deg_dec!U11 <> "", _xlfn.CHOOSECOLS(_xlfn.TEXTSPLIT(track_deg_dec!U11,","),1), "")} | AO11: =IF(track_deg_dec!U11 <> "", _xlfn.CONCAT("0,", _xlfn.CHOOSECOLS(_xlfn.TEXTSPLIT(track_deg_dec!U11,","),2))*60, "")
