Workbook

Sheet Cover sheet
A2: Year | B2: 2022
A3: Quarter | B3: 1

Sheet PlannedStations
A1: ID | C1: Country | D1: Vessel | E1: Quarter | F1: AreaSection | G1: Year | H1: PlannedNumberOfHauls
A2: =CONCATENATE(C2,B2,E2) -> Germany (SD 21-24)1 | B2: =IF(F2=2224," (SD 21-24)"," (SD 25-32)") -> (SD 21-24) | C2: Germany | D2: Solea | E2: 1 | F2: 2224 | G2: 2022 | H2: 60
A3: =CONCATENATE(C3,B3,E3) -> Denmark (SD 21-24)1 | B3: =IF(F3=2224," (SD 21-24)"," (SD 25-32)") -> (SD 21-24) | C3: Denmark | D3: Havfisken | E3: 1 | F3: 2224 | G3: 2022 | H3: 30
A4: =CONCATENATE(C4,B4,E4) -> Poland (SD 21-24)1 | B4: =IF(F4=2224," (SD 21-24)"," (SD 25-32)") -> (SD 21-24) | C4: Poland | D4: Baltica | E4: 1 | F4: 2224 | G4: 2022 | H4: 0
A5: =CONCATENATE(C5,B5,E5) -> Denmark (SD 25-32)1 | B5: =IF(F5=2224," (SD 21-24)"," (SD 25-32)") -> (SD 25-32) | C5: Denmark | D5: Dana | E5: 1 | F5: 2528 | G5: 2022 | H5: 55
A6: =CONCATENATE(C6,B6,E6) -> Estonia (SD 25-32)1 | B6: =IF(F6=2224," (SD 21-24)"," (SD 25-32)") -> (SD 25-32) | C6: Estonia | D6: Commercial vessel | E6: 1 | F6: 2528 | G6: 2022 | H6: 0
A7: =CONCATENATE(C7,B7,E7) -> Latvia (SD 25-32)1 | B7: =IF(F7=2224," (SD 21-24)"," (SD 25-32)") -> (SD 25-32) | C7: Latvia | D7: Chartered vessel | E7: 1 | F7: 2528 | G7: 2022 | H7: 25
A8: =CONCATENATE(C8,B8,E8) -> Lithuania (SD 25-32)1 | B8: =IF(F8=2224," (SD 21-24)"," (SD 25-32)") -> (SD 25-32) | C8: Lithuania | D8: Chartered vessel | E8: 1 | F8: 2528 | G8: 2022 | H8: 6
A9: =CONCATENATE(C9,B9,E9) -> Poland (SD 25-32)1 | B9: =IF(F9=2224," (SD 21-24)"," (SD 25-32)") -> (SD 25-32) | C9: Poland | D9: Baltica | E9: 1 | F9: 2528 | G9: 2022 | H9: 70
A10: =CONCATENATE(C10,B10,E10) -> Russia (SD 25-32)1 | B10: =IF(F10=2224," (SD 21-24)"," (SD 25-32)") -> (SD 25-32) | C10: Russia | D10: Atlantniro/Atlantida | E10: 1 | F10: 2528 | G10: 2022 | H10: 0
A11: =CONCATENATE(C11,B11,E11) -> Sweden (SD 25-32)1 | B11: =IF(F11=2224," (SD 21-24)"," (SD 25-32)") -> (SD 25-32) | C11: Sweden | D11: Svea | E11: 1 | F11: 2528 | G11: 2022 | H11: 50
A12: =CONCATENATE(C12,B12,E12) -> (SD 25-32) | B12: =IF(F12=2224," (SD 21-24)"," (SD 25-32)") -> (SD 25-32)
A13: =CONCATENATE(C13,B13,E13) -> (SD 25-32) | B13: =IF(F13=2224," (SD 21-24)"," (SD 25-32)") -> (SD 25-32)
A14: =CONCATENATE(C14,B14,E14) -> (SD 25-32) | B14: =IF(F14=2224," (SD 21-24)"," (SD 25-32)") -> (SD 25-32)
A15: =CONCATENATE(C15,B15,E15) -> (SD 25-32) | B15: =IF(F15=2224," (SD 21-24)"," (SD 25-32)") -> (SD 25-32)
A16: =CONCATENATE(C16,B16,E16) -> (SD 25-32) | B16: =IF(F16=2224," (SD 21-24)"," (SD 25-32)") -> (SD 25-32)
A17: =CONCATENATE(C17,B17,E17) -> (SD 25-32) | B17: =IF(F17=2224," (SD 21-24)"," (SD 25-32)") -> (SD 25-32)
A18: =CONCATENATE(C18,B18,E18) -> (SD 25-32) | B18: =IF(F18=2224," (SD 21-24)"," (SD 25-32)") -> (SD 25-32)
A19: =CONCATENATE(C19,B19,E19) -> (SD 25-32) | B19: =IF(F19=2224," (SD 21-24)"," (SD 25-32)") -> (SD 25-32)
A20: =CONCATENATE(C20,B20,E20) -> (SD 25-32) | B20: =IF(F20=2224," (SD 21-24)"," (SD 25-32)") -> (SD 25-32)
A21: =CONCATENATE(C21,B21,E21) -> (SD 25-32) | B21: =IF(F21=2224," (SD 21-24)"," (SD 25-32)") -> (SD 25-32)
A22: =CONCATENATE(C22,B22,E22) -> (SD 25-32) | B22: =IF(F22=2224," (SD 21-24)"," (SD 25-32)") -> (SD 25-32)
A23: =CONCATENATE(C23,B23,E23) -> (SD 25-32) | B23: =IF(F23=2224," (SD 21-24)"," (SD 25-32)") -> (SD 25-32)

Sheet Final list of total hauls pros
A1: NrHaul | B1: RectangleAlpha | C1: ICES.SD | D1: Latitude1_deg | E1: Latitude1_dec_min | F1: Longitude1_deg | G1: Longitude1_dec_min | H1: Layer | I1: EEZ | J1: Latitude1_deg_dec | K1: Longitude1_deg_dec | L1: codstock | M1: country
A2: 22002 | B2: 37G1 | C2: 22 | D2: 54 | E2: 11.27 | F2: 11 | G2: 55.26 | H2: 2 | I2: GFR | J2: 54.187833 | K2: 11.921 | L2: 21-24 | M2: GFR (SD 21-24)
A3: 22008 | B3: 37G1 | C3: 22 | D3: 54 | E3: 20.8 | F3: 11 | G3: 55.3 | H3: 2 | I3: GFR | J3: 54.346667 | K3: 11.921667 | L3: 21-24 | M3: GFR (SD 21-24)
A4: 22018 | B4: 39G1 | C4: 22 | D4: 55 | E4: 4.2 | F4: 11 | G4: 4.1 | H4: 2 | I4: DEN | J4: 55.07 | K4: 11.068333 | L4: 21-24 | M4: DEN (SD 21-24)
A5: 22020 | B5: 39G0 | C5: 22 | D5: 55 | E5: 12.7 | F5: 10 | G5: 56.3 | H5: 2 | I5: DEN | J5: 55.211667 | K5: 10.938333 | L5: 21-24 | M5: DEN (SD 21-24)
A6: 22023 | B6: 39G1 | C6: 22 | D6: 55 | E6: 18.47 | F6: 11 | G6: 1.28 | H6: 2 | I6: DEN | J6: 55.307833 | K6: 11.021333 | L6: 21-24 | M6: DEN (SD 21-24)
A7: 22024 | B7: 39F9 | C7: 22 | D7: 55 | E7: 21.9 | F7: 9 | G7: 45.16 | H7: 2 | I7: DEN | J7: 55.365 | K7: 9.7526667 | L7: 21-24 | M7: DEN (SD 21-24)
A8: 22025 | B8: 39G0 | C8: 22 | D8: 55 | E8: 23.14 | F8: 10 | G8: 50.56 | H8: 2 | I8: DEN | J8: 55.385667 | K8: 10.842667 | L8: 21-24 | M8: DEN (SD 21-24)
A9: 22026 | B9: 39G0 | C9: 22 | D9: 55 | E9: 25.4 | F9: 10 | G9: 46 | H9: 2 | I9: DEN | J9: 55.423333 | K9: 10.766667 | L9: 21-24 | M9: DEN (SD 21-24)
A10: 22027 | B10: 40G0 | C10: 22 | D10: 55 | E10: 38.1 | F10: 10 | G10: 0.4 | H10: 2 | I10: DEN | J10: 55.635 | K10: 10.006667 | L10: 21-24 | M10: DEN (SD 21-24)
A11: 22032 | B11: 40G0 | C11: 22 | D11: 55 | E11: 46.7 | F11: 10 | G11: 40.8 | H11: 2 | I11: DEN | J11: 55.778333 | K11: 10.68 | L11: 21-24 | M11: DEN (SD 21-24)
A12: 22034 | B12: 40G0 | C12: 22 | D12: 55 | E12: 59.6 | F12: 10 | G12: 38.4 | H12: 2 | I12: DEN | J12: 55.993333 | K12: 10.64 | L12: 21-24 | M12: DEN (SD 21-24)
A13: 22036 | B13: 40G1 | C13: 22 | D13: 55 | E13: 55.3 | F13: 11 | G13: 13.6 | H13: 2 | I13: DEN | J13: 55.921667 | K13: 11.226667 | L13: 21-24 | M13: DEN (SD 21-24)
... A296: 28173 | B296: 42H0 | C296: 28 | D296: 56 | E296: 38.85 | F296: 20 | G296: 36.28 | H296: 3 | I296: LAT | J296: 56.6475 | K296: 20.604667 | L296: 25-32 | M296: LAT (SD 25-32)

Sheet Processing
C1: Quarter | D1: ='Cover sheet'!B3 -> 1
K2: DEN (SD 21-24) | M2: DEN (SD 25-32) | O2: SWE (SD 25-32) | Q2: POL (SD 21-24) | S2: POL (SD 25-32) | U2: LAT (SD 25-32) | W2: EST (SD 25-32) | Y2: GFR (SD 21-24) | AA2: LTU (SD 25-32) | AC2: RUS (SD 25-32)
K3: Denmark (SD 21-24) | M3: Denmark (SD 25-32) | O3: Sweden (SD 25-32) | Q3: Poland (SD 21-24) | S3: Poland (SD 25-32) | U3: Latvia (SD 25-32) | W3: Estonia (SD 25-32) | Y3: Germany (SD 21-24) | AA3: Lithuania (SD 25-32) | AC3: Russia (SD 25-32)
A4: Allocation method | B4: ='Final list of total hauls pros'!M1 -> country | D4: ='Final list of total hauls pros'!A1 -> NrHaul | E4: Rect. | F4: ='Final list of total hauls pros'!B1 -> RectangleAlpha | G4: ='Final list of total hauls pros'!I1 -> EEZ | H4: ='Final list of total hauls pros'!L1 -> codstock | I4: Country (final) | K4: Allo | L4: Adj.(-/+) | M4: Allo | N4: Adj.(-/+) | O4: Allo | P4: Adj.(-/+) | Q4: Allo | R4: Adj.(-/+) | S4: Allo | T4: Adj.(-/+) | U4: Allo | V4: Adj.(-/+) | W4: Allo | X4: Adj.(-/+) | Y4: Allo | Z4: Adj.(-/+) | AA4: Allo | AB4: Adj.(-/+) | AC4: Allo | AD4: Adj.(-/+) | AG4: Check | AK4: Denmark (SD 21-24) | AL4: Denmark (SD 25-32) | AM4: Sweden (SD 25-32) | AN4: Poland (SD 21-24) | AO4: Poland (SD 25-32) | AP4: Latvia (SD 25-32) | AQ4: Estonia (SD 25-32) | AR4: Germany (SD 21-24) | AS4: Lithuania (SD 25-32) | AT4: Russia (SD 25-32)
A5: Standard | B5: ='Final list of total hauls pros'!M2 -> GFR (SD 21-24) | C5: 1 | D5: ='Final list of total hauls pros'!A2 -> 22002 | E5: =IF(D5<>"",LEFT(D5,2),"") -> 22 | F5: ='Final list of total hauls pros'!B2 -> 37G1 | G5: ='Final list of total hauls pros'!I2 -> GFR | H5: ='Final list of total hauls pros'!L2 -> 21-24 | I5: =IF(L5="+",$K$2,IF(N5="+",$M$2,IF(P5="+",$O$2,IF(R5="+",$Q$2,IF(T5="+",$S$2,IF(V5="+",$U$2,IF(X5="+",$W$2,IF(Z5="+",$Y$2,IF(AB5="+",$AA$2,IF(AD5="+",$AC$2,B5)))))))))) -> GFR (SD 21-24) | K5: =IF(L5="+",1,IF(L5="-","",IF(L5="",AK5))) | M5: =IF(N5="+",1,IF(N5="-","",IF(N5="",AL5))) | O5: =IF(P5="+",1,IF(P5="-","",IF(P5="",AM5))) | Q5: =IF(R5="+",1,IF(R5="-","",IF(R5="",AN5))) | S5: =IF(T5="+",1,IF(T5="-","",IF(T5="",AO5))) | U5: =IF(V5="+",1,IF(V5="-","",IF(V5="",AP5))) | W5: =IF(X5="+",1,IF(X5="-","",IF(X5="",AQ5))) | Y5: =IF(Z5="+",1,IF(Z5="-","",IF(Z5="",AR5))) -> 1 | AA5: =IF(AB5="+",1,IF(AB5="-","",IF(AB5="",AS5))) | AC5: =IF(AD5="+",1,IF(AD5="-","",IF(AD5="",AT5))) | AG5: =IF(SUM(K5:AC5)<>1,"FEJL","") | AK5: =IF(B5="DEN (SD 21-24)",1,"") | AL5: =IF(B5="DEN (SD 25-32)",1,"") | AM5: =IF(B5="SWE (SD 25-32)",1,"") | AN5: =IF(B5="POL (SD 21-24)",1,"") | AO5: =IF(B5="POL (SD 25-32)",1,"") | AP5: =IF(B5="LAT (SD 25-32)",1,"") | AQ5: =IF(B5="EST (SD 25-32)",1,"") | AR5: =IF(B5="GFR (SD 21-24)",1,"") -> 1 | AS5: =IF(B5="LTU (SD 25-32)",1,"") | AT5: =IF(B5="RUS (SD 25-32)",1,"")
A6: Standard | B6: ='Final list of total hauls pros'!M3 -> GFR (SD 21-24) | C6: 2 | D6: ='Final list of total hauls pros'!A3 -> 22008 | E6: =IF(D6<>"",LEFT(D6,2),"") -> 22 | F6: ='Final list of total hauls pros'!B3 -> 37G1 | G6: ='Final list of total hauls pros'!I3 -> GFR | H6: ='Final list of total hauls pros'!L3 -> 21-24 | I6: =IF(L6="+",$K$2,IF(N6="+",$M$2,IF(P6="+",$O$2,IF(R6="+",$Q$2,IF(T6="+",$S$2,IF(V6="+",$U$2,IF(X6="+",$W$2,IF(Z6="+",$Y$2,IF(AB6="+",$AA$2,IF(AD6="+",$AC$2,B6)))))))))) -> GFR (SD 21-24) | K6: =IF(L6="+",1,IF(L6="-","",IF(L6="",AK6))) | M6: =IF(N6="+",1,IF(N6="-","",IF(N6="",AL6))) | O6: =IF(P6="+",1,IF(P6="-","",IF(P6="",AM6))) | Q6: =IF(R6="+",1,IF(R6="-","",IF(R6="",AN6))) | S6: =IF(T6="+",1,IF(T6="-","",IF(T6="",AO6))) | U6: =IF(V6="+",1,IF(V6="-","",IF(V6="",AP6))) | W6: =IF(X6="+",1,IF(X6="-","",IF(X6="",AQ6))) | Y6: =IF(Z6="+",1,IF(Z6="-","",IF(Z6="",AR6))) -> 1 | AA6: =IF(AB6="+",1,IF(AB6="-","",IF(AB6="",AS6))) | AC6: =IF(AD6="+",1,IF(AD6="-","",IF(AD6="",AT6))) | AG6: =IF(SUM(K6:AC6)<>1,"FEJL","") | AK6: =IF(B6="DEN (SD 21-24)",1,"") | AL6: =IF(B6="DEN (SD 25-32)",1,"") | AM6: =IF(B6="SWE (SD 25-32)",1,"") | AN6: =IF(B6="POL (SD 21-24)",1,"") | AO6: =IF(B6="POL (SD 25-32)",1,"") | AP6: =IF(B6="LAT (SD 25-32)",1,"") | AQ6: =IF(B6="EST (SD 25-32)",1,"") | AR6: =IF(B6="GFR (SD 21-24)",1,"") -> 1 | AS6: =IF(B6="LTU (SD 25-32)",1,"") | AT6: =IF(B6="RUS (SD 25-32)",1,"")
A7: Standard | B7: ='Final list of total hauls pros'!M4 -> DEN (SD 21-24) | C7: 3 | D7: ='Final list of total hauls pros'!A4 -> 22018 | E7: =IF(D7<>"",LEFT(D7,2),"") -> 22 | F7: ='Final list of total hauls pros'!B4 -> 39G1 | G7: ='Final list of total hauls pros'!I4 -> DEN | H7: ='Final list of total hauls pros'!L4 -> 21-24 | I7: =IF(L7="+",$K$2,IF(N7="+",$M$2,IF(P7="+",$O$2,IF(R7="+",$Q$2,IF(T7="+",$S$2,IF(V7="+",$U$2,IF(X7="+",$W$2,IF(Z7="+",$Y$2,IF(AB7="+",$AA$2,IF(AD7="+",$AC$2,B7)))))))))) -> DEN (SD 21-24) | K7: =IF(L7="+",1,IF(L7="-","",IF(L7="",AK7))) -> 1 | M7: =IF(N7="+",1,IF(N7="-","",IF(N7="",AL7))) | O7: =IF(P7="+",1,IF(P7="-","",IF(P7="",AM7))) | Q7: =IF(R7="+",1,IF(R7="-","",IF(R7="",AN7))) | S7: =IF(T7="+",1,IF(T7="-","",IF(T7="",AO7))) | U7: =IF(V7="+",1,IF(V7="-","",IF(V7="",AP7))) | W7: =IF(X7="+",1,IF(X7="-","",IF(X7="",AQ7))) | Y7: =IF(Z7="+",1,IF(Z7="-","",IF(Z7="",AR7))) | AA7: =IF(AB7="+",1,IF(AB7="-","",IF(AB7="",AS7))) | AC7: =IF(AD7="+",1,IF(AD7="-","",IF(AD7="",AT7))) | AG7: =IF(SUM(K7:AC7)<>1,"FEJL","") | AK7: =IF(B7="DEN (SD 21-24)",1,"") -> 1 | AL7: =IF(B7="DEN (SD 25-32)",1,"") | AM7: =IF(B7="SWE (SD 25-32)",1,"") | AN7: =IF(B7="POL (SD 21-24)",1,"") | AO7: =IF(B7="POL (SD 25-32)",1,"") | AP7: =IF(B7="LAT (SD 25-32)",1,"") | AQ7: =IF(B7="EST (SD 25-32)",1,"") | AR7: =IF(B7="GFR (SD 21-24)",1,"") | AS7: =IF(B7="LTU (SD 25-32)",1,"") | AT7: =IF(B7="RUS (SD 25-32)",1,"")
A8: Standard | B8: ='Final list of total hauls pros'!M5 -> DEN (SD 21-24) | C8: 4 | D8: ='Final list of total hauls pros'!A5 -> 22020 | E8: =IF(D8<>"",LEFT(D8,2),"") -> 22 | F8: ='Final list of total hauls pros'!B5 -> 39G0 | G8: ='Final list of total hauls pros'!I5 -> DEN | H8: ='Final list of total hauls pros'!L5 -> 21-24 | I8: =IF(L8="+",$K$2,IF(N8="+",$M$2,IF(P8="+",$O$2,IF(R8="+",$Q$2,IF(T8="+",$S$2,IF(V8="+",$U$2,IF(X8="+",$W$2,IF(Z8="+",$Y$2,IF(AB8="+",$AA$2,IF(AD8="+",$AC$2,B8)))))))))) -> DEN (SD 21-24) | K8: =IF(L8="+",1,IF(L8="-","",IF(L8="",AK8))) -> 1 | M8: =IF(N8="+",1,IF(N8="-","",IF(N8="",AL8))) | O8: =IF(P8="+",1,IF(P8="-","",IF(P8="",AM8))) | Q8: =IF(R8="+",1,IF(R8="-","",IF(R8="",AN8))) | S8: =IF(T8="+",1,IF(T8="-","",IF(T8="",AO8))) | U8: =IF(V8="+",1,IF(V8="-","",IF(V8="",AP8))) | W8: =IF(X8="+",1,IF(X8="-","",IF(X8="",AQ8))) | Y8: =IF(Z8="+",1,IF(Z8="-","",IF(Z8="",AR8))) | AA8: =IF(AB8="+",1,IF(AB8="-","",IF(AB8="",AS8))) | AC8: =IF(AD8="+",1,IF(AD8="-","",IF(AD8="",AT8))) | AG8: =IF(SUM(K8:AC8)<>1,"FEJL","") | AK8: =IF(B8="DEN (SD 21-24)",1,"") -> 1 | AL8: =IF(B8="DEN (SD 25-32)",1,"") | AM8: =IF(B8="SWE (SD 25-32)",1,"") | AN8: =IF(B8="POL (SD 21-24)",1,"") | AO8: =IF(B8="POL (SD 25-32)",1,"") | AP8: =IF(B8="LAT (SD 25-32)",1,"") | AQ8: =IF(B8="EST (SD 25-32)",1,"") | AR8: =IF(B8="GFR (SD 21-24)",1,"") | AS8: =IF(B8="LTU (SD 25-32)",1,"") | AT8: =IF(B8="RUS (SD 25-32)",1,"")
A9: Standard | B9: ='Final list of total hauls pros'!M6 -> DEN (SD 21-24) | C9: 5 | D9: ='Final list of total hauls pros'!A6 -> 22023 | E9: =IF(D9<>"",LEFT(D9,2),"") -> 22 | F9: ='Final list of total hauls pros'!B6 -> 39G1 | G9: ='Final list of total hauls pros'!I6 -> DEN | H9: ='Final list of total hauls pros'!L6 -> 21-24 | I9: =IF(L9="+",$K$2,IF(N9="+",$M$2,IF(P9="+",$O$2,IF(R9="+",$Q$2,IF(T9="+",$S$2,IF(V9="+",$U$2,IF(X9="+",$W$2,IF(Z9="+",$Y$2,IF(AB9="+",$AA$2,IF(AD9="+",$AC$2,B9)))))))))) -> DEN (SD 21-24) | K9: =IF(L9="+",1,IF(L9="-","",IF(L9="",AK9))) -> 1 | M9: =IF(N9="+",1,IF(N9="-","",IF(N9="",AL9))) | O9: =IF(P9="+",1,IF(P9="-","",IF(P9="",AM9))) | Q9: =IF(R9="+",1,IF(R9="-","",IF(R9="",AN9))) | S9: =IF(T9="+",1,IF(T9="-","",IF(T9="",AO9))) | U9: =IF(V9="+",1,IF(V9="-","",IF(V9="",AP9))) | W9: =IF(X9="+",1,IF(X9="-","",IF(X9="",AQ9))) | Y9: =IF(Z9="+",1,IF(Z9="-","",IF(Z9="",AR9))) | AA9: =IF(AB9="+",1,IF(AB9="-","",IF(AB9="",AS9))) | AC9: =IF(AD9="+",1,IF(AD9="-","",IF(AD9="",AT9))) | AG9: =IF(SUM(K9:AC9)<>1,"FEJL","") | AK9: =IF(B9="DEN (SD 21-24)",1,"") -> 1 | AL9: =IF(B9="DEN (SD 25-32)",1,"") | AM9: =IF(B9="SWE (SD 25-32)",1,"") | AN9: =IF(B9="POL (SD 21-24)",1,"") | AO9: =IF(B9="POL (SD 25-32)",1,"") | AP9: =IF(B9="LAT (SD 25-32)",1,"") | AQ9: =IF(B9="EST (SD 25-32)",1,"") | AR9: =IF(B9="GFR (SD 21-24)",1,"") | AS9: =IF(B9="LTU (SD 25-32)",1,"") | AT9: =IF(B9="RUS (SD 25-32)",1,"")
A10: Standard | B10: ='Final list of total hauls pros'!M7 -> DEN (SD 21-24) | C10: 6 | D10: ='Final list of total hauls pros'!A7 -> 22024 | E10: =IF(D10<>"",LEFT(D10,2),"") -> 22 | F10: ='Final list of total hauls pros'!B7 -> 39F9 | G10: ='Final list of total hauls pros'!I7 -> DEN | H10: ='Final list of total hauls pros'!L7 -> 21-24 | I10: =IF(L10="+",$K$2,IF(N10="+",$M$2,IF(P10="+",$O$2,IF(R10="+",$Q$2,IF(T10="+",$S$2,IF(V10="+",$U$2,IF(X10="+",$W$2,IF(Z10="+",$Y$2,IF(AB10="+",$AA$2,IF(AD10="+",$AC$2,B10)))))))))) -> DEN (SD 21-24) | K10: =IF(L10="+",1,IF(L10="-","",IF(L10="",AK10))) -> 1 | M10: =IF(N10="+",1,IF(N10="-","",IF(N10="",AL10))) | O10: =IF(P10="+",1,IF(P10="-","",IF(P10="",AM10))) | Q10: =IF(R10="+",1,IF(R10="-","",IF(R10="",AN10))) | S10: =IF(T10="+",1,IF(T10="-","",IF(T10="",AO10))) | U10: =IF(V10="+",1,IF(V10="-","",IF(V10="",AP10))) | W10: =IF(X10="+",1,IF(X10="-","",IF(X10="",AQ10))) | Y10: =IF(Z10="+",1,IF(Z10="-","",IF(Z10="",AR10))) | AA10: =IF(AB10="+",1,IF(AB10="-","",IF(AB10="",AS10))) | AC10: =IF(AD10="+",1,IF(AD10="-","",IF(AD10="",AT10))) | AG10: =IF(SUM(K10:AC10)<>1,"FEJL","") | AK10: =IF(B10="DEN (SD 21-24)",1,"") -> 1 | AL10: =IF(B10="DEN (SD 25-32)",1,"") | AM10: =IF(B10="SWE (SD 25-32)",1,"") | AN10: =IF(B10="POL (SD 21-24)",1,"") | AO10: =IF(B10="POL (SD 25-32)",1,"") | AP10: =IF(B10="LAT (SD 25-32)",1,"") | AQ10: =IF(B10="EST (SD 25-32)",1,"") | AR10: =IF(B10="GFR (SD 21-24)",1,"") | AS10: =IF(B10="LTU (SD 25-32)",1,"") | AT10: =IF(B10="RUS (SD 25-32)",1,"")
A11: Standard | B11: ='Final list of total hauls pros'!M8 -> DEN (SD 21-24) | C11: 7 | D11: ='Final list of total hauls pros'!A8 -> 22025 | E11: =IF(D11<>"",LEFT(D11,2),"") -> 22 | F11: ='Final list of total hauls pros'!B8 -> 39G0 | G11: ='Final list of total hauls pros'!I8 -> DEN | H11: ='Final list of total hauls pros'!L8 -> 21-24 | I11: =IF(L11="+",$K$2,IF(N11="+",$M$2,IF(P11="+",$O$2,IF(R11="+",$Q$2,IF(T11="+",$S$2,IF(V11="+",$U$2,IF(X11="+",$W$2,IF(Z11="+",$Y$2,IF(AB11="+",$AA$2,IF(AD11="+",$AC$2,B11)))))))))) -> DEN (SD 21-24) | K11: =IF(L11="+",1,IF(L11="-","",IF(L11="",AK11))) -> 1 | M11: =IF(N11="+",1,IF(N11="-","",IF(N11="",AL11))) | O11: =IF(P11="+",1,IF(P11="-","",IF(P11="",AM11))) | Q11: =IF(R11="+",1,IF(R11="-","",IF(R11="",AN11))) | S11: =IF(T11="+",1,IF(T11="-","",IF(T11="",AO11))) | U11: =IF(V11="+",1,IF(V11="-","",IF(V11="",AP11))) | W11: =IF(X11="+",1,IF(X11="-","",IF(X11="",AQ11))) | Y11: =IF(Z11="+",1,IF(Z11="-","",IF(Z11="",AR11))) | AA11: =IF(AB11="+",1,IF(AB11="-","",IF(AB11="",AS11))) | AC11: =IF(AD11="+",1,IF(AD11="-","",IF(AD11="",AT11))) | AG11: =IF(SUM(K11:AC11)<>1,"FEJL","") | AK11: =IF(B11="DEN (SD 21-24)",1,"") -> 1 | AL11: =IF(B11="DEN (SD 25-32)",1,"") | AM11: =IF(B11="SWE (SD 25-32)",1,"") | AN11: =IF(B11="POL (SD 21-24)",1,"") | AO11: =IF(B11="POL (SD 25-32)",1,"") | AP11: =IF(B11="LAT (SD 25-32)",1,"") | AQ11: =IF(B11="EST (SD 25-32)",1,"") | AR11: =IF(B11="GFR (SD 21-24)",1,"") | AS11: =IF(B11="LTU (SD 25-32)",1,"") | AT11: =IF(B11="RUS (SD 25-32)",1,"")
A12: Standard | B12: ='Final list of total hauls pros'!M9 -> DEN (SD 21-24) | C12: 8 | D12: ='Final list of total hauls pros'!A9 -> 22026 | E12: =IF(D12<>"",LEFT(D12,2),"") -> 22 | F12: ='Final list of total hauls pros'!B9 -> 39G0 | G12: ='Final list of total hauls pros'!I9 -> DEN | H12: ='Final list of total hauls pros'!L9 -> 21-24 | I12: =IF(L12="+",$K$2,IF(N12="+",$M$2,IF(P12="+",$O$2,IF(R12="+",$Q$2,IF(T12="+",$S$2,IF(V12="+",$U$2,IF(X12="+",$W$2,IF(Z12="+",$Y$2,IF(AB12="+",$AA$2,IF(AD12="+",$AC$2,B12)))))))))) -> DEN (SD 21-24) | K12: =IF(L12="+",1,IF(L12="-","",IF(L12="",AK12))) -> 1 | M12: =IF(N12="+",1,IF(N12="-","",IF(N12="",AL12))) | O12: =IF(P12="+",1,IF(P12="-","",IF(P12="",AM12))) | Q12: =IF(R12="+",1,IF(R12="-","",IF(R12="",AN12))) | S12: =IF(T12="+",1,IF(T12="-","",IF(T12="",AO12))) | U12: =IF(V12="+",1,IF(V12="-","",IF(V12="",AP12))) | W12: =IF(X12="+",1,IF(X12="-","",IF(X12="",AQ12))) | Y12: =IF(Z12="+",1,IF(Z12="-","",IF(Z12="",AR12))) | AA12: =IF(AB12="+",1,IF(AB12="-","",IF(AB12="",AS12))) | AC12: =IF(AD12="+",1,IF(AD12="-","",IF(AD12="",AT12))) | AG12: =IF(SUM(K12:AC12)<>1,"FEJL","") | AK12: =IF(B12="DEN (SD 21-24)",1,"") -> 1 | AL12: =IF(B12="DEN (SD 25-32)",1,"") | AM12: =IF(B12="SWE (SD 25-32)",1,"") | AN12: =IF(B12="POL (SD 21-24)",1,"") | AO12: =IF(B12="POL (SD 25-32)",1,"") | AP12: =IF(B12="LAT (SD 25-32)",1,"") | AQ12: =IF(B12="EST (SD 25-32)",1,"") | AR12: =IF(B12="GFR (SD 21-24)",1,"") | AS12: =IF(B12="LTU (SD 25-32)",1,"") | AT12: =IF(B12="RUS (SD 25-32)",1,"")
A13: Standard | B13: ='Final list of total hauls pros'!M10 -> DEN (SD 21-24) | C13: 9 | D13: ='Final list of total hauls pros'!A10 -> 22027 | E13: =IF(D13<>"",LEFT(D13,2),"") -> 22 | F13: ='Final list of total hauls pros'!B10 -> 40G0 | G13: ='Final list of total hauls pros'!I10 -> DEN | H13: ='Final list of total hauls pros'!L10 -> 21-24 | I13: =IF(L13="+",$K$2,IF(N13="+",$M$2,IF(P13="+",$O$2,IF(R13="+",$Q$2,IF(T13="+",$S$2,IF(V13="+",$U$2,IF(X13="+",$W$2,IF(Z13="+",$Y$2,IF(AB13="+",$AA$2,IF(AD13="+",$AC$2,B13)))))))))) -> DEN (SD 21-24) | K13: =IF(L13="+",1,IF(L13="-","",IF(L13="",AK13))) -> 1 | M13: =IF(N13="+",1,IF(N13="-","",IF(N13="",AL13))) | O13: =IF(P13="+",1,IF(P13="-","",IF(P13="",AM13))) | Q13: =IF(R13="+",1,IF(R13="-","",IF(R13="",AN13))) | S13: =IF(T13="+",1,IF(T13="-","",IF(T13="",AO13))) | U13: =IF(V13="+",1,IF(V13="-","",IF(V13="",AP13))) | W13: =IF(X13="+",1,IF(X13="-","",IF(X13="",AQ13))) | Y13: =IF(Z13="+",1,IF(Z13="-","",IF(Z13="",AR13))) | AA13: =IF(AB13="+",1,IF(AB13="-","",IF(AB13="",AS13))) | AC13: =IF(AD13="+",1,IF(AD13="-","",IF(AD13="",AT13))) | AG13: =IF(SUM(K13:AC13)<>1,"FEJL","") | AK13: =IF(B13="DEN (SD 21-24)",1,"") -> 1 | AL13: =IF(B13="DEN (SD 25-32)",1,"") | AM13: =IF(B13="SWE (SD 25-32)",1,"") | AN13: =IF(B13="POL (SD 21-24)",1,"") | AO13: =IF(B13="POL (SD 25-32)",1,"") | AP13: =IF(B13="LAT (SD 25-32)",1,"") | AQ13: =IF(B13="EST (SD 25-32)",1,"") | AR13: =IF(B13="GFR (SD 21-24)",1,"") | AS13: =IF(B13="LTU (SD 25-32)",1,"") | AT13: =IF(B13="RUS (SD 25-32)",1,"")
A14: Standard | B14: ='Final list of total hauls pros'!M11 -> DEN (SD 21-24) | C14: 10 | D14: ='Final list of total hauls pros'!A11 -> 22032 | E14: =IF(D14<>"",LEFT(D14,2),"") -> 22 | F14: ='Final list of total hauls pros'!B11 -> 40G0 | G14: ='Final list of total hauls pros'!I11 -> DEN | H14: ='Final list of total hauls pros'!L11 -> 21-24 | I14: =IF(L14="+",$K$2,IF(N14="+",$M$2,IF(P14="+",$O$2,IF(R14="+",$Q$2,IF(T14="+",$S$2,IF(V14="+",$U$2,IF(X14="+",$W$2,IF(Z14="+",$Y$2,IF(AB14="+",$AA$2,IF(AD14="+",$AC$2,B14)))))))))) -> DEN (SD 21-24) | K14: =IF(L14="+",1,IF(L14="-","",IF(L14="",AK14))) -> 1 | M14: =IF(N14="+",1,IF(N14="-","",IF(N14="",AL14))) | O14: =IF(P14="+",1,IF(P14="-","",IF(P14="",AM14))) | Q14: =IF(R14="+",1,IF(R14="-","",IF(R14="",AN14))) | S14: =IF(T14="+",1,IF(T14="-","",IF(T14="",AO14))) | U14: =IF(V14="+",1,IF(V14="-","",IF(V14="",AP14))) | W14: =IF(X14="+",1,IF(X14="-","",IF(X14="",AQ14))) | Y14: =IF(Z14="+",1,IF(Z14="-","",IF(Z14="",AR14))) | AA14: =IF(AB14="+",1,IF(AB14="-","",IF(AB14="",AS14))) | AC14: =IF(AD14="+",1,IF(AD14="-","",IF(AD14="",AT14))) | AG14: =IF(SUM(K14:AC14)<>1,"FEJL","") | AK14: =IF(B14="DEN (SD 21-24)",1,"") -> 1 | AL14: =IF(B14="DEN (SD 25-32)",1,"") | AM14: =IF(B14="SWE (SD 25-32)",1,"") | AN14: =IF(B14="POL (SD 21-24)",1,"") | AO14: =IF(B14="POL (SD 25-32)",1,"") | AP14: =IF(B14="LAT (SD 25-32)",1,"") | AQ14: =IF(B14="EST (SD 25-32)",1,"") | AR14: =IF(B14="GFR (SD 21-24)",1,"") | AS14: =IF(B14="LTU (SD 25-32)",1,"") | AT14: =IF(B14="RUS (SD 25-32)",1,"")
A15: Standard | B15: ='Final list of total hauls pros'!M12 -> DEN (SD 21-24) | C15: 11 | D15: ='Final list of total hauls pros'!A12 -> 22034 | E15: =IF(D15<>"",LEFT(D15,2),"") -> 22 | F15: ='Final list of total hauls pros'!B12 -> 40G0 | G15: ='Final list of total hauls pros'!I12 -> DEN | H15: ='Final list of total hauls pros'!L12 -> 21-24 | I15: =IF(L15="+",$K$2,IF(N15="+",$M$2,IF(P15="+",$O$2,IF(R15="+",$Q$2,IF(T15="+",$S$2,IF(V15="+",$U$2,IF(X15="+",$W$2,IF(Z15="+",$Y$2,IF(AB15="+",$AA$2,IF(AD15="+",$AC$2,B15)))))))))) -> DEN (SD 21-24) | K15: =IF(L15="+",1,IF(L15="-","",IF(L15="",AK15))) -> 1 | M15: =IF(N15="+",1,IF(N15="-","",IF(N15="",AL15))) | O15: =IF(P15="+",1,IF(P15="-","",IF(P15="",AM15))) | Q15: =IF(R15="+",1,IF(R15="-","",IF(R15="",AN15))) | S15: =IF(T15="+",1,IF(T15="-","",IF(T15="",AO15))) | U15: =IF(V15="+",1,IF(V15="-","",IF(V15="",AP15))) | W15: =IF(X15="+",1,IF(X15="-","",IF(X15="",AQ15))) | Y15: =IF(Z15="+",1,IF(Z15="-","",IF(Z15="",AR15))) | AA15: =IF(AB15="+",1,IF(AB15="-","",IF(AB15="",AS15))) | AC15: =IF(AD15="+",1,IF(AD15="-","",IF(AD15="",AT15))) | AG15: =IF(SUM(K15:AC15)<>1,"FEJL","") | AK15: =IF(B15="DEN (SD 21-24)",1,"") -> 1 | AL15: =IF(B15="DEN (SD 25-32)",1,"") | AM15: =IF(B15="SWE (SD 25-32)",1,"") | AN15: =IF(B15="POL (SD 21-24)",1,"") | AO15: =IF(B15="POL (SD 25-32)",1,"") | AP15: =IF(B15="LAT (SD 25-32)",1,"") | AQ15: =IF(B15="EST (SD 25-32)",1,"") | AR15: =IF(B15="GFR (SD 21-24)",1,"") | AS15: =IF(B15="LTU (SD 25-32)",1,"") | AT15: =IF(B15="RUS (SD 25-32)",1,"")
A16: Standard | B16: ='Final list of total hauls pros'!M13 -> DEN (SD 21-24) | C16: 12 | D16: ='Final list of total hauls pros'!A13 -> 22036 | E16: =IF(D16<>"",LEFT(D16,2),"") -> 22 | F16: ='Final list of total hauls pros'!B13 -> 40G1 | G16: ='Final list of total hauls pros'!I13 -> DEN | H16: ='Final list of total hauls pros'!L13 -> 21-24 | I16: =IF(L16="+",$K$2,IF(N16="+",$M$2,IF(P16="+",$O$2,IF(R16="+",$Q$2,IF(T16="+",$S$2,IF(V16="+",$U$2,IF(X16="+",$W$2,IF(Z16="+",$Y$2,IF(AB16="+",$AA$2,IF(AD16="+",$AC$2,B16)))))))))) -> DEN (SD 21-24) | K16: =IF(L16="+",1,IF(L16="-","",IF(L16="",AK16))) -> 1 | M16: =IF(N16="+",1,IF(N16="-","",IF(N16="",AL16))) | O16: =IF(P16="+",1,IF(P16="-","",IF(P16="",AM16))) | Q16: =IF(R16="+",1,IF(R16="-","",IF(R16="",AN16))) | S16: =IF(T16="+",1,IF(T16="-","",IF(T16="",AO16))) | U16: =IF(V16="+",1,IF(V16="-","",IF(V16="",AP16))) | W16: =IF(X16="+",1,IF(X16="-","",IF(X16="",AQ16))) | Y16: =IF(Z16="+",1,IF(Z16="-","",IF(Z16="",AR16))) | AA16: =IF(AB16="+",1,IF(AB16="-","",IF(AB16="",AS16))) | AC16: =IF(AD16="+",1,IF(AD16="-","",IF(AD16="",AT16))) | AG16: =IF(SUM(K16:AC16)<>1,"FEJL","") | AK16: =IF(B16="DEN (SD 21-24)",1,"") -> 1 | AL16: =IF(B16="DEN (SD 25-32)",1,"") | AM16: =IF(B16="SWE (SD 25-32)",1,"") | AN16: =IF(B16="POL (SD 21-24)",1,"") | AO16: =IF(B16="POL (SD 25-32)",1,"") | AP16: =IF(B16="LAT (SD 25-32)",1,"") | AQ16: =IF(B16="EST (SD 25-32)",1,"") | AR16: =IF(B16="GFR (SD 21-24)",1,"") | AS16: =IF(B16="LTU (SD 25-32)",1,"") | AT16: =IF(B16="RUS (SD 25-32)",1,"")
... A21: Standard | B21: ='Final list of total hauls pros'!M18 -> GFR (SD 21-24) | C21: 17 | D21: ='Final list of total hauls pros'!A18 -> 22058 | E21: =IF(D21<>"",LEFT(D21,2),"") -> 22 | F21: ='Final list of total hauls pros'!B18 -> 37G1 | G21: ='Final list of total hauls pros'!I18 -> GFR | H21: ='Final list of total hauls pros'!L18 -> 21-24 | I21: =IF(L21="+",$K$2,IF(N21="+",$M$2,IF(P21="+",$O$2,IF(R21="+",$Q$2,IF(T21="+",$S$2,IF(V21="+",$U$2,IF(X21="+",$W$2,IF(Z21="+",$Y$2,IF(AB21="+",$AA$2,IF(AD21="+",$AC$2,B21)))))))))) -> GFR (SD 21-24) | K21: =IF(L21="+",1,IF(L21="-","",IF(L21="",AK21))) | M21: =IF(N21="+",1,IF(N21="-","",IF(N21="",AL21))) | O21: =IF(P21="+",1,IF(P21="-","",IF(P21="",AM21))) | Q21: =IF(R21="+",1,IF(R21="-","",IF(R21="",AN21))) | S21: =IF(T21="+",1,IF(T21="-","",IF(T21="",AO21))) | U21: =IF(V21="+",1,IF(V21="-","",IF(V21="",AP21))) | W21: =IF(X21="+",1,IF(X21="-","",IF(X21="",AQ21))) | Y21: =IF(Z21="+",1,IF(Z21="-","",IF(Z21="",AR21))) -> 1 | AA21: =IF(AB21="+",1,IF(AB21="-","",IF(AB21="",AS21))) | AC21: =IF(AD21="+",1,IF(AD21="-","",IF(AD21="",AT21))) | AG21: =IF(SUM(K21:AC21)<>1,"FEJL","") | AK21: =IF(B21="DEN (SD 21-24)",1,"") | AL21: =IF(B21="DEN (SD 25-32)",1,"") | AM21: =IF(B21="SWE (SD 25-32)",1,"") | AN21: =IF(B21="POL (SD 21-24)",1,"") | AO21: =IF(B21="POL (SD 25-32)",1,"") | AP21: =IF(B21="LAT (SD 25-32)",1,"") | AQ21: =IF(B21="EST (SD 25-32)",1,"") | AR21: =IF(B21="GFR (SD 21-24)",1,"") -> 1 | AS21: =IF(B21="LTU (SD 25-32)",1,"") | AT21: =IF(B21="RUS (SD 25-32)",1,"")
A22: Standard | B22: ='Final list of total hauls pros'!M19 -> DEN (SD 21-24) | C22: 18 | D22: ='Final list of total hauls pros'!A19 -> 22071 | E22: =IF(D22<>"",LEFT(D22,2),"") -> 22 | F22: ='Final list of total hauls pros'!B19 -> 38G1 | G22: ='Final list of total hauls pros'!I19 -> DEN | H22: ='Final list of total hauls pros'!L19 -> 21-24 | I22: =IF(L22="+",$K$2,IF(N22="+",$M$2,IF(P22="+",$O$2,IF(R22="+",$Q$2,IF(T22="+",$S$2,IF(V22="+",$U$2,IF(X22="+",$W$2,IF(Z22="+",$Y$2,IF(AB22="+",$AA$2,IF(AD22="+",$AC$2,B22)))))))))) -> GFR (SD 21-24) | K22: =IF(L22="+",1,IF(L22="-","",IF(L22="",AK22))) | L22: - | M22: =IF(N22="+",1,IF(N22="-","",IF(N22="",AL22))) | O22: =IF(P22="+",1,IF(P22="-","",IF(P22="",AM22))) | Q22: =IF(R22="+",1,IF(R22="-","",IF(R22="",AN22))) | S22: =IF(T22="+",1,IF(T22="-","",IF(T22="",AO22))) | U22: =IF(V22="+",1,IF(V22="-","",IF(V22="",AP22))) | W22: =IF(X22="+",1,IF(X22="-","",IF(X22="",AQ22))) | Y22: =IF(Z22="+",1,IF(Z22="-","",IF(Z22="",AR22))) -> 1 | Z22: + | AA22: =IF(AB22="+",1,IF(AB22="-","",IF(AB22="",AS22))) | AC22: =IF(AD22="+",1,IF(AD22="-","",IF(AD22="",AT22))) | AG22: =IF(SUM(K22:AC22)<>1,"FEJL","") | AK22: =IF(B22="DEN (SD 21-24)",1,"") -> 1 | AL22: =IF(B22="DEN (SD 25-32)",1,"") | AM22: =IF(B22="SWE (SD 25-32)",1,"") | AN22: =IF(B22="POL (SD 21-24)",1,"") | AO22: =IF(B22="POL (SD 25-32)",1,"") | AP22: =IF(B22="LAT (SD 25-32)",1,"") | AQ22: =IF(B22="EST (SD 25-32)",1,"") | AR22: =IF(B22="GFR (SD 21-24)",1,"") | AS22: =IF(B22="LTU (SD 25-32)",1,"") | AT22: =IF(B22="RUS (SD 25-32)",1,"")
A23: Standard | B23: ='Final list of total hauls pros'!M20 -> GFR (SD 21-24) | C23: 19 | D23: ='Final list of total hauls pros'!A20 -> 22072 | E23: =IF(D23<>"",LEFT(D23,2),"") -> 22 | F23: ='Final list of total hauls pros'!B20 -> 38G1 | G23: ='Final list of total hauls pros'!I20 -> GFR | H23: ='Final list of total hauls pros'!L20 -> 21-24 | I23: =IF(L23="+",$K$2,IF(N23="+",$M$2,IF(P23="+",$O$2,IF(R23="+",$Q$2,IF(T23="+",$S$2,IF(V23="+",$U$2,IF(X23="+",$W$2,IF(Z23="+",$Y$2,IF(AB23="+",$AA$2,IF(AD23="+",$AC$2,B23)))))))))) -> GFR (SD 21-24) | K23: =IF(L23="+",1,IF(L23="-","",IF(L23="",AK23))) | M23: =IF(N23="+",1,IF(N23="-","",IF(N23="",AL23))) | O23: =IF(P23="+",1,IF(P23="-","",IF(P23="",AM23))) | Q23: =IF(R23="+",1,IF(R23="-","",IF(R23="",AN23))) | S23: =IF(T23="+",1,IF(T23="-","",IF(T23="",AO23))) | U23: =IF(V23="+",1,IF(V23="-","",IF(V23="",AP23))) | W23: =IF(X23="+",1,IF(X23="-","",IF(X23="",AQ23))) | Y23: =IF(Z23="+",1,IF(Z23="-","",IF(Z23="",AR23))) -> 1 | AA23: =IF(AB23="+",1,IF(AB23="-","",IF(AB23="",AS23))) | AC23: =IF(AD23="+",1,IF(AD23="-","",IF(AD23="",AT23))) | AG23: =IF(SUM(K23:AC23)<>1,"FEJL","") | AK23: =IF(B23="DEN (SD 21-24)",1,"") | AL23: =IF(B23="DEN (SD 25-32)",1,"") | AM23: =IF(B23="SWE (SD 25-32)",1,"") | AN23: =IF(B23="POL (SD 21-24)",1,"") | AO23: =IF(B23="POL (SD 25-32)",1,"") | AP23: =IF(B23="LAT (SD 25-32)",1,"") | AQ23: =IF(B23="EST (SD 25-32)",1,"") | AR23: =IF(B23="GFR (SD 21-24)",1,"") -> 1 | AS23: =IF(B23="LTU (SD 25-32)",1,"") | AT23: =IF(B23="RUS (SD 25-32)",1,"")
A24: Standard | B24: ='Final list of total hauls pros'!M21 -> DEN (SD 21-24) | C24: 20 | D24: ='Final list of total hauls pros'!A21 -> 22075 | E24: =IF(D24<>"",LEFT(D24,2),"") -> 22 | F24: ='Final list of total hauls pros'!B21 -> 38G0 | G24: ='Final list of total hauls pros'!I21 -> DEN | H24: ='Final list of total hauls pros'!L21 -> 21-24 | I24: =IF(L24="+",$K$2,IF(N24="+",$M$2,IF(P24="+",$O$2,IF(R24="+",$Q$2,IF(T24="+",$S$2,IF(V24="+",$U$2,IF(X24="+",$W$2,IF(Z24="+",$Y$2,IF(AB24="+",$AA$2,IF(AD24="+",$AC$2,B24)))))))))) -> DEN (SD 21-24) | K24: =IF(L24="+",1,IF(L24="-","",IF(L24="",AK24))) -> 1 | M24: =IF(N24="+",1,IF(N24="-","",IF(N24="",AL24))) | O24: =IF(P24="+",1,IF(P24="-","",IF(P24="",AM24))) | Q24: =IF(R24="+",1,IF(R24="-","",IF(R24="",AN24))) | S24: =IF(T24="+",1,IF(T24="-","",IF(T24="",AO24))) | U24: =IF(V24="+",1,IF(V24="-","",IF(V24="",AP24))) | W24: =IF(X24="+",1,IF(X24="-","",IF(X24="",AQ24))) | Y24: =IF(Z24="+",1,IF(Z24="-","",IF(Z24="",AR24))) | AA24: =IF(AB24="+",1,IF(AB24="-","",IF(AB24="",AS24))) | AC24: =IF(AD24="+",1,IF(AD24="-","",IF(AD24="",AT24))) | AG24: =IF(SUM(K24:AC24)<>1,"FEJL","") | AK24: =IF(B24="DEN (SD 21-24)",1,"") -> 1 | AL24: =IF(B24="DEN (SD 25-32)",1,"") | AM24: =IF(B24="SWE (SD 25-32)",1,"") | AN24: =IF(B24="POL (SD 21-24)",1,"") | AO24: =IF(B24="POL (SD 25-32)",1,"") | AP24: =IF(B24="LAT (SD 25-32)",1,"") | AQ24: =IF(B24="EST (SD 25-32)",1,"") | AR24: =IF(B24="GFR (SD 21-24)",1,"") | AS24: =IF(B24="LTU (SD 25-32)",1,"") | AT24: =IF(B24="RUS (SD 25-32)",1,"")
A25: Standard | B25: ='Final list of total hauls pros'!M22 -> DEN (SD 21-24) | C25: 21 | D25: ='Final list of total hauls pros'!A22 -> 22076 | E25: =IF(D25<>"",LEFT(D25,2),"") -> 22 | F25: ='Final list of total hauls pros'!B22 -> 38G0 | G25: ='Final list of total hauls pros'!I22 -> DEN | H25: ='Final list of total hauls pros'!L22 -> 21-24 | I25: =IF(L25="+",$K$2,IF(N25="+",$M$2,IF(P25="+",$O$2,IF(R25="+",$Q$2,IF(T25="+",$S$2,IF(V25="+",$U$2,IF(X25="+",$W$2,IF(Z25="+",$Y$2,IF(AB25="+",$AA$2,IF(AD25="+",$AC$2,B25)))))))))) -> DEN (SD 21-24) | K25: =IF(L25="+",1,IF(L25="-","",IF(L25="",AK25))) -> 1 | M25: =IF(N25="+",1,IF(N25="-","",IF(N25="",AL25))) | O25: =IF(P25="+",1,IF(P25="-","",IF(P25="",AM25))) | Q25: =IF(R25="+",1,IF(R25="-","",IF(R25="",AN25))) | S25: =IF(T25="+",1,IF(T25="-","",IF(T25="",AO25))) | U25: =IF(V25="+",1,IF(V25="-","",IF(V25="",AP25))) | W25: =IF(X25="+",1,IF(X25="-","",IF(X25="",AQ25))) | Y25: =IF(Z25="+",1,IF(Z25="-","",IF(Z25="",AR25))) | AA25: =IF(AB25="+",1,IF(AB25="-","",IF(AB25="",AS25))) | AC25: =IF(AD25="+",1,IF(AD25="-","",IF(AD25="",AT25))) | AG25: =IF(SUM(K25:AC25)<>1,"FEJL","") | AK25: =IF(B25="DEN (SD 21-24)",1,"") -> 1 | AL25: =IF(B25="DEN (SD 25-32)",1,"") | AM25: =IF(B25="SWE (SD 25-32)",1,"") | AN25: =IF(B25="POL (SD 21-24)",1,"") | AO25: =IF(B25="POL (SD 25-32)",1,"") | AP25: =IF(B25="LAT (SD 25-32)",1,"") | AQ25: =IF(B25="EST (SD 25-32)",1,"") | AR25: =IF(B25="GFR (SD 21-24)",1,"") | AS25: =IF(B25="LTU (SD 25-32)",1,"") | AT25: =IF(B25="RUS (SD 25-32)",1,"")
A26: Standard | B26: ='Final list of total hauls pros'!M23 -> DEN (SD 21-24) | C26: 22 | D26: ='Final list of total hauls pros'!A23 -> 22077 | E26: =IF(D26<>"",LEFT(D26,2),"") -> 22 | F26: ='Final list of total hauls pros'!B23 -> 38G0 | G26: ='Final list of total hauls pros'!I23 -> DEN | H26: ='Final list of total hauls pros'!L23 -> 21-24 | I26: =IF(L26="+",$K$2,IF(N26="+",$M$2,IF(P26="+",$O$2,IF(R26="+",$Q$2,IF(T26="+",$S$2,IF(V26="+",$U$2,IF(X26="+",$W$2,IF(Z26="+",$Y$2,IF(AB26="+",$AA$2,IF(AD26="+",$AC$2,B26)))))))))) -> DEN (SD 21-24) | K26: =IF(L26="+",1,IF(L26="-","",IF(L26="",AK26))) -> 1 | M26: =IF(N26="+",1,IF(N26="-","",IF(N26="",AL26))) | O26: =IF(P26="+",1,IF(P26="-","",IF(P26="",AM26))) | Q26: =IF(R26="+",1,IF(R26="-","",IF(R26="",AN26))) | S26: =IF(T26="+",1,IF(T26="-","",IF(T26="",AO26))) | U26: =IF(V26="+",1,IF(V26="-","",IF(V26="",AP26))) | W26: =IF(X26="+",1,IF(X26="-","",IF(X26="",AQ26))) | Y26: =IF(Z26="+",1,IF(Z26="-","",IF(Z26="",AR26))) | AA26: =IF(AB26="+",1,IF(AB26="-","",IF(AB26="",AS26))) | AC26: =IF(AD26="+",1,IF(AD26="-","",IF(AD26="",AT26))) | AG26: =IF(SUM(K26:AC26)<>1,"FEJL","") | AK26: =IF(B26="DEN (SD 21-24)",1,"") -> 1 | AL26: =IF(B26="DEN (SD 25-32)",1,"") | AM26: =IF(B26="SWE (SD 25-32)",1,"") | AN26: =IF(B26="POL (SD 21-24)",1,"") | AO26: =IF(B26="POL (SD 25-32)",1,"") | AP26: =IF(B26="LAT (SD 25-32)",1,"") | AQ26: =IF(B26="EST (SD 25-32)",1,"") | AR26: =IF(B26="GFR (SD 21-24)",1,"") | AS26: =IF(B26="LTU (SD 25-32)",1,"") | AT26: =IF(B26="RUS (SD 25-32)",1,"")
A27: Standard | B27: ='Final list of total hauls pros'!M24 -> DEN (SD 21-24) | C27: 23 | D27: ='Final list of total hauls pros'!A24 -> 22079 | E27: =IF(D27<>"",LEFT(D27,2),"") -> 22 | F27: ='Final list of total hauls pros'!B24 -> 38G0 | G27: ='Final list of total hauls pros'!I24 -> DEN | H27: ='Final list of total hauls pros'!L24 -> 21-24 | I27: =IF(L27="+",$K$2,IF(N27="+",$M$2,IF(P27="+",$O$2,IF(R27="+",$Q$2,IF(T27="+",$S$2,IF(V27="+",$U$2,IF(X27="+",$W$2,IF(Z27="+",$Y$2,IF(AB27="+",$AA$2,IF(AD27="+",$AC$2,B27)))))))))) -> DEN (SD 21-24) | K27: =IF(L27="+",1,IF(L27="-","",IF(L27="",AK27))) -> 1 | M27: =IF(N27="+",1,IF(N27="-","",IF(N27="",AL27))) | O27: =IF(P27="+",1,IF(P27="-","",IF(P27="",AM27))) | Q27: =IF(R27="+",1,IF(R27="-","",IF(R27="",AN27))) | S27: =IF(T27="+",1,IF(T27="-","",IF(T27="",AO27))) | U27: =IF(V27="+",1,IF(V27="-","",IF(V27="",AP27))) | W27: =IF(X27="+",1,IF(X27="-","",IF(X27="",AQ27))) | Y27: =IF(Z27="+",1,IF(Z27="-","",IF(Z27="",AR27))) | AA27: =IF(AB27="+",1,IF(AB27="-","",IF(AB27="",AS27))) | AC27: =IF(AD27="+",1,IF(AD27="-","",IF(AD27="",AT27))) | AG27: =IF(SUM(K27:AC27)<>1,"FEJL","") | AK27: =IF(B27="DEN (SD 21-24)",1,"") -> 1 | AL27: =IF(B27="DEN (SD 25-32)",1,"") | AM27: =IF(B27="SWE (SD 25-32)",1,"") | AN27: =IF(B27="POL (SD 21-24)",1,"") | AO27: =IF(B27="POL (SD 25-32)",1,"") | AP27: =IF(B27="LAT (SD 25-32)",1,"") | AQ27: =IF(B27="EST (SD 25-32)",1,"") | AR27: =IF(B27="GFR (SD 21-24)",1,"") | AS27: =IF(B27="LTU (SD 25-32)",1,"") | AT27: =IF(B27="RUS (SD 25-32)",1,"")
A28: Standard | B28: ='Final list of total hauls pros'!M25 -> DEN (SD 21-24) | C28: 24 | D28: ='Final list of total hauls pros'!A25 -> 22081 | E28: =IF(D28<>"",LEFT(D28,2),"") -> 22 | F28: ='Final list of total hauls pros'!B25 -> 39F9 | G28: ='Final list of total hauls pros'!I25 -> DEN | H28: ='Final list of total hauls pros'!L25 -> 21-24 | I28: =IF(L28="+",$K$2,IF(N28="+",$M$2,IF(P28="+",$O$2,IF(R28="+",$Q$2,IF(T28="+",$S$2,IF(V28="+",$U$2,IF(X28="+",$W$2,IF(Z28="+",$Y$2,IF(AB28="+",$AA$2,IF(AD28="+",$AC$2,B28)))))))))) -> DEN (SD 21-24) | K28: =IF(L28="+",1,IF(L28="-","",IF(L28="",AK28))) -> 1 | M28: =IF(N28="+",1,IF(N28="-","",IF(N28="",AL28))) | O28: =IF(P28="+",1,IF(P28="-","",IF(P28="",AM28))) | Q28: =IF(R28="+",1,IF(R28="-","",IF(R28="",AN28))) | S28: =IF(T28="+",1,IF(T28="-","",IF(T28="",AO28))) | U28: =IF(V28="+",1,IF(V28="-","",IF(V28="",AP28))) | W28: =IF(X28="+",1,IF(X28="-","",IF(X28="",AQ28))) | Y28: =IF(Z28="+",1,IF(Z28="-","",IF(Z28="",AR28))) | AA28: =IF(AB28="+",1,IF(AB28="-","",IF(AB28="",AS28))) | AC28: =IF(AD28="+",1,IF(AD28="-","",IF(AD28="",AT28))) | AG28: =IF(SUM(K28:AC28)<>1,"FEJL","") | AK28: =IF(B28="DEN (SD 21-24)",1,"") -> 1 | AL28: =IF(B28="DEN (SD 25-32)",1,"") | AM28: =IF(B28="SWE (SD 25-32)",1,"") | AN28: =IF(B28="POL (SD 21-24)",1,"") | AO28: =IF(B28="POL (SD 25-32)",1,"") | AP28: =IF(B28="LAT (SD 25-32)",1,"") | AQ28: =IF(B28="EST (SD 25-32)",1,"") | AR28: =IF(B28="GFR (SD 21-24)",1,"") | AS28: =IF(B28="LTU (SD 25-32)",1,"") | AT28: =IF(B28="RUS (SD 25-32)",1,"")
A29: Standard | B29: ='Final list of total hauls pros'!M26 -> DEN (SD 21-24) | C29: 25 | D29: ='Final list of total hauls pros'!A26 -> 22084 | E29: =IF(D29<>"",LEFT(D29,2),"") -> 22 | F29: ='Final list of total hauls pros'!B26 -> 39G1 | G29: ='Final list of total hauls pros'!I26 -> DEN | H29: ='Final list of total hauls pros'!L26 -> 21-24 | I29: =IF(L29="+",$K$2,IF(N29="+",$M$2,IF(P29="+",$O$2,IF(R29="+",$Q$2,IF(T29="+",$S$2,IF(V29="+",$U$2,IF(X29="+",$W$2,IF(Z29="+",$Y$2,IF(AB29="+",$AA$2,IF(AD29="+",$AC$2,B29)))))))))) -> DEN (SD 21-24) | K29: =IF(L29="+",1,IF(L29="-","",IF(L29="",AK29))) -> 1 | M29: =IF(N29="+",1,IF(N29="-","",IF(N29="",AL29))) | O29: =IF(P29="+",1,IF(P29="-","",IF(P29="",AM29))) | Q29: =IF(R29="+",1,IF(R29="-","",IF(R29="",AN29))) | S29: =IF(T29="+",1,IF(T29="-","",IF(T29="",AO29))) | U29: =IF(V29="+",1,IF(V29="-","",IF(V29="",AP29))) | W29: =IF(X29="+",1,IF(X29="-","",IF(X29="",AQ29))) | Y29: =IF(Z29="+",1,IF(Z29="-","",IF(Z29="",AR29))) | AA29: =IF(AB29="+",1,IF(AB29="-","",IF(AB29="",AS29))) | AC29: =IF(AD29="+",1,IF(AD29="-","",IF(AD29="",AT29))) | AG29: =IF(SUM(K29:AC29)<>1,"FEJL","") | AK29: =IF(B29="DEN (SD 21-24)",1,"") -> 1 | AL29: =IF(B29="DEN (SD 25-32)",1,"") | AM29: =IF(B29="SWE (SD 25-32)",1,"") | AN29: =IF(B29="POL (SD 21-24)",1,"") | AO29: =IF(B29="POL (SD 25-32)",1,"") | AP29: =IF(B29="LAT (SD 25-32)",1,"") | AQ29: =IF(B29="EST (SD 25-32)",1,"") | AR29: =IF(B29="GFR (SD 21-24)",1,"") | AS29: =IF(B29="LTU (SD 25-32)",1,"") | AT29: =IF(B29="RUS (SD 25-32)",1,"")
A30: Standard | B30: ='Final list of total hauls pros'!M27 -> DEN (SD 21-24) | C30: 26 | D30: ='Final list of total hauls pros'!A27 -> 22085 | E30: =IF(D30<>"",LEFT(D30,2),"") -> 22 | F30: ='Final list of total hauls pros'!B27 -> 40G0 | G30: ='Final list of total hauls pros'!I27 -> DEN | H30: ='Final list of total hauls pros'!L27 -> 21-24 | I30: =IF(L30="+",$K$2,IF(N30="+",$M$2,IF(P30="+",$O$2,IF(R30="+",$Q$2,IF(T30="+",$S$2,IF(V30="+",$U$2,IF(X30="+",$W$2,IF(Z30="+",$Y$2,IF(AB30="+",$AA$2,IF(AD30="+",$AC$2,B30)))))))))) -> DEN (SD 21-24) | K30: =IF(L30="+",1,IF(L30="-","",IF(L30="",AK30))) -> 1 | M30: =IF(N30="+",1,IF(N30="-","",IF(N30="",AL30))) | O30: =IF(P30="+",1,IF(P30="-","",IF(P30="",AM30))) | Q30: =IF(R30="+",1,IF(R30="-","",IF(R30="",AN30))) | S30: =IF(T30="+",1,IF(T30="-","",IF(T30="",AO30))) | U30: =IF(V30="+",1,IF(V30="-","",IF(V30="",AP30))) | W30: =IF(X30="+",1,IF(X30="-","",IF(X30="",AQ30))) | Y30: =IF(Z30="+",1,IF(Z30="-","",IF(Z30="",AR30))) | AA30: =IF(AB30="+",1,IF(AB30="-","",IF(AB30="",AS30))) | AC30: =IF(AD30="+",1,IF(AD30="-","",IF(AD30="",AT30))) | AG30: =IF(SUM(K30:AC30)<>1,"FEJL","") | AK30: =IF(B30="DEN (SD 21-24)",1,"") -> 1 | AL30: =IF(B30="DEN (SD 25-32)",1,"") | AM30: =IF(B30="SWE (SD 25-32)",1,"") | AN30: =IF(B30="POL (SD 21-24)",1,"") | AO30: =IF(B30="POL (SD 25-32)",1,"") | AP30: =IF(B30="LAT (SD 25-32)",1,"") | AQ30: =IF(B30="EST (SD 25-32)",1,"") | AR30: =IF(B30="GFR (SD 21-24)",1,"") | AS30: =IF(B30="LTU (SD 25-32)",1,"") | AT30: =IF(B30="RUS (SD 25-32)",1,"")
A31: Standard | B31: ='Final list of total hauls pros'!M28 -> DEN (SD 21-24) | C31: 27 | D31: ='Final list of total hauls pros'!A28 -> 22086 | E31: =IF(D31<>"",LEFT(D31,2),"") -> 22 | F31: ='Final list of total hauls pros'!B28 -> 40G0 | G31: ='Final list of total hauls pros'!I28 -> DEN | H31: ='Final list of total hauls pros'!L28 -> 21-24 | I31: =IF(L31="+",$K$2,IF(N31="+",$M$2,IF(P31="+",$O$2,IF(R31="+",$Q$2,IF(T31="+",$S$2,IF(V31="+",$U$2,IF(X31="+",$W$2,IF(Z31="+",$Y$2,IF(AB31="+",$AA$2,IF(AD31="+",$AC$2,B31)))))))))) -> DEN (SD 21-24) | K31: =IF(L31="+",1,IF(L31="-","",IF(L31="",AK31))) -> 1 | M31: =IF(N31="+",1,IF(N31="-","",IF(N31="",AL31))) | O31: =IF(P31="+",1,IF(P31="-","",IF(P31="",AM31))) | Q31: =IF(R31="+",1,IF(R31="-","",IF(R31="",AN31))) | S31: =IF(T31="+",1,IF(T31="-","",IF(T31="",AO31))) | U31: =IF(V31="+",1,IF(V31="-","",IF(V31="",AP31))) | W31: =IF(X31="+",1,IF(X31="-","",IF(X31="",AQ31))) | Y31: =IF(Z31="+",1,IF(Z31="-","",IF(Z31="",AR31))) | AA31: =IF(AB31="+",1,IF(AB31="-","",IF(AB31="",AS31))) | AC31: =IF(AD31="+",1,IF(AD31="-","",IF(AD31="",AT31))) | AG31: =IF(SUM(K31:AC31)<>1,"FEJL","") | AK31: =IF(B31="DEN (SD 21-24)",1,"") -> 1 | AL31: =IF(B31="DEN (SD 25-32)",1,"") | AM31: =IF(B31="SWE (SD 25-32)",1,"") | AN31: =IF(B31="POL (SD 21-24)",1,"") | AO31: =IF(B31="POL (SD 25-32)",1,"") | AP31: =IF(B31="LAT (SD 25-32)",1,"") | AQ31: =IF(B31="EST (SD 25-32)",1,"") | AR31: =IF(B31="GFR (SD 21-24)",1,"") | AS31: =IF(B31="LTU (SD 25-32)",1,"") | AT31: =IF(B31="RUS (SD 25-32)",1,"")
A32: Standard | B32: ='Final list of total hauls pros'!M29 -> DEN (SD 21-24) | C32: 28 | D32: ='Final list of total hauls pros'!A29 -> 22092 | E32: =IF(D32<>"",LEFT(D32,2),"") -> 22 | F32: ='Final list of total hauls pros'!B29 -> 40G0 | G32: ='Final list of total hauls pros'!I29 -> DEN | H32: ='Final list of total hauls pros'!L29 -> 21-24 | I32: =IF(L32="+",$K$2,IF(N32="+",$M$2,IF(P32="+",$O$2,IF(R32="+",$Q$2,IF(T32="+",$S$2,IF(V32="+",$U$2,IF(X32="+",$W$2,IF(Z32="+",$Y$2,IF(AB32="+",$AA$2,IF(AD32="+",$AC$2,B32)))))))))) -> DEN (SD 21-24) | K32: =IF(L32="+",1,IF(L32="-","",IF(L32="",AK32))) -> 1 | M32: =IF(N32="+",1,IF(N32="-","",IF(N32="",AL32))) | O32: =IF(P32="+",1,IF(P32="-","",IF(P32="",AM32))) | Q32: =IF(R32="+",1,IF(R32="-","",IF(R32="",AN32))) | S32: =IF(T32="+",1,IF(T32="-","",IF(T32="",AO32))) | U32: =IF(V32="+",1,IF(V32="-","",IF(V32="",AP32))) | W32: =IF(X32="+",1,IF(X32="-","",IF(X32="",AQ32))) | Y32: =IF(Z32="+",1,IF(Z32="-","",IF(Z32="",AR32))) | AA32: =IF(AB32="+",1,IF(AB32="-","",IF(AB32="",AS32))) | AC32: =IF(AD32="+",1,IF(AD32="-","",IF(AD32="",AT32))) | AG32: =IF(SUM(K32:AC32)<>1,"FEJL","") | AK32: =IF(B32="DEN (SD 21-24)",1,"") -> 1 | AL32: =IF(B32="DEN (SD 25-32)",1,"") | AM32: =IF(B32="SWE (SD 25-32)",1,"") | AN32: =IF(B32="POL (SD 21-24)",1,"") | AO32: =IF(B32="POL (SD 25-32)",1,"") | AP32: =IF(B32="LAT (SD 25-32)",1,"") | AQ32: =IF(B32="EST (SD 25-32)",1,"") | AR32: =IF(B32="GFR (SD 21-24)",1,"") | AS32: =IF(B32="LTU (SD 25-32)",1,"") | AT32: =IF(B32="RUS (SD 25-32)",1,"")
A33: Standard | B33: ='Final list of total hauls pros'!M30 -> DEN (SD 21-24) | C33: 29 | D33: ='Final list of total hauls pros'!A30 -> 22103 | E33: =IF(D33<>"",LEFT(D33,2),"") -> 22 | F33: ='Final list of total hauls pros'!B30 -> 39G1 | G33: ='Final list of total hauls pros'!I30 -> DEN | H33: ='Final list of total hauls pros'!L30 -> 21-24 | I33: =IF(L33="+",$K$2,IF(N33="+",$M$2,IF(P33="+",$O$2,IF(R33="+",$Q$2,IF(T33="+",$S$2,IF(V33="+",$U$2,IF(X33="+",$W$2,IF(Z33="+",$Y$2,IF(AB33="+",$AA$2,IF(AD33="+",$AC$2,B33)))))))))) -> DEN (SD 21-24) | K33: =IF(L33="+",1,IF(L33="-","",IF(L33="",AK33))) -> 1 | M33: =IF(N33="+",1,IF(N33="-","",IF(N33="",AL33))) | O33: =IF(P33="+",1,IF(P33="-","",IF(P33="",AM33))) | Q33: =IF(R33="+",1,IF(R33="-","",IF(R33="",AN33))) | S33: =IF(T33="+",1,IF(T33="-","",IF(T33="",AO33))) | U33: =IF(V33="+",1,IF(V33="-","",IF(V33="",AP33))) | W33: =IF(X33="+",1,IF(X33="-","",IF(X33="",AQ33))) | Y33: =IF(Z33="+",1,IF(Z33="-","",IF(Z33="",AR33))) | AA33: =IF(AB33="+",1,IF(AB33="-","",IF(AB33="",AS33))) | AC33: =IF(AD33="+",1,IF(AD33="-","",IF(AD33="",AT33))) | AG33: =IF(SUM(K33:AC33)<>1,"FEJL","") | AK33: =IF(B33="DEN (SD 21-24)",1,"") -> 1 | AL33: =IF(B33="DEN (SD 25-32)",1,"") | AM33: =IF(B33="SWE (SD 25-32)",1,"") | AN33: =IF(B33="POL (SD 21-24)",1,"") | AO33: =IF(B33="POL (SD 25-32)",1,"") | AP33: =IF(B33="LAT (SD 25-32)",1,"") | AQ33: =IF(B33="EST (SD 25-32)",1,"") | AR33: =IF(B33="GFR (SD 21-24)",1,"") | AS33: =IF(B33="LTU (SD 25-32)",1,"") | AT33: =IF(B33="RUS (SD 25-32)",1,"")
A34: Standard | B34: ='Final list of total hauls pros'!M31 -> DEN (SD 21-24) | C34: 30 | D34: ='Final list of total hauls pros'!A31 -> 22111 | E34: =IF(D34<>"",LEFT(D34,2),"") -> 22 | F34: ='Final list of total hauls pros'!B31 -> 38G0 | G34: ='Final list of total hauls pros'!I31 -> DEN | H34: ='Final list of total hauls pros'!L31 -> 21-24 | I34: =IF(L34="+",$K$2,IF(N34="+",$M$2,IF(P34="+",$O$2,IF(R34="+",$Q$2,IF(T34="+",$S$2,IF(V34="+",$U$2,IF(X34="+",$W$2,IF(Z34="+",$Y$2,IF(AB34="+",$AA$2,IF(AD34="+",$AC$2,B34)))))))))) -> DEN (SD 21-24) | K34: =IF(L34="+",1,IF(L34="-","",IF(L34="",AK34))) -> 1 | M34: =IF(N34="+",1,IF(N34="-","",IF(N34="",AL34))) | O34: =IF(P34="+",1,IF(P34="-","",IF(P34="",AM34))) | Q34: =IF(R34="+",1,IF(R34="-","",IF(R34="",AN34))) | S34: =IF(T34="+",1,IF(T34="-","",IF(T34="",AO34))) | U34: =IF(V34="+",1,IF(V34="-","",IF(V34="",AP34))) | W34: =IF(X34="+",1,IF(X34="-","",IF(X34="",AQ34))) | Y34: =IF(Z34="+",1,IF(Z34="-","",IF(Z34="",AR34))) | AA34: =IF(AB34="+",1,IF(AB34="-","",IF(AB34="",AS34))) | AC34: =IF(AD34="+",1,IF(AD34="-","",IF(AD34="",AT34))) | AG34: =IF(SUM(K34:AC34)<>1,"FEJL","") | AK34: =IF(B34="DEN (SD 21-24)",1,"") -> 1 | AL34: =IF(B34="DEN (SD 25-32)",1,"") | AM34: =IF(B34="SWE (SD 25-32)",1,"") | AN34: =IF(B34="POL (SD 21-24)",1,"") | AO34: =IF(B34="POL (SD 25-32)",1,"") | AP34: =IF(B34="LAT (SD 25-32)",1,"") | AQ34: =IF(B34="EST (SD 25-32)",1,"") | AR34: =IF(B34="GFR (SD 21-24)",1,"") | AS34: =IF(B34="LTU (SD 25-32)",1,"") | AT34: =IF(B34="RUS (SD 25-32)",1,"")
... A54: Standard | B54: ='Final list of total hauls pros'!M51 -> GFR (SD 21-24) | C54: 50 | D54: ='Final list of total hauls pros'!A51 -> 24016 | E54: =IF(D54<>"",LEFT(D54,2),"") -> 24 | F54: ='Final list of total hauls pros'!B51 -> 38G2 | G54: ='Final list of total hauls pros'!I51 -> GFR | H54: ='Final list of total hauls pros'!L51 -> 21-24 | I54: =IF(L54="+",$K$2,IF(N54="+",$M$2,IF(P54="+",$O$2,IF(R54="+",$Q$2,IF(T54="+",$S$2,IF(V54="+",$U$2,IF(X54="+",$W$2,IF(Z54="+",$Y$2,IF(AB54="+",$AA$2,IF(AD54="+",$AC$2,B54)))))))))) -> GFR (SD 21-24) | K54: =IF(L54="+",1,IF(L54="-","",IF(L54="",AK54))) | M54: =IF(N54="+",1,IF(N54="-","",IF(N54="",AL54))) | O54: =IF(P54="+",1,IF(P54="-","",IF(P54="",AM54))) | Q54: =IF(R54="+",1,IF(R54="-","",IF(R54="",AN54))) | S54: =IF(T54="+",1,IF(T54="-","",IF(T54="",AO54))) | U54: =IF(V54="+",1,IF(V54="-","",IF(V54="",AP54))) | W54: =IF(X54="+",1,IF(X54="-","",IF(X54="",AQ54))) | Y54: =IF(Z54="+",1,IF(Z54="-","",IF(Z54="",AR54))) -> 1 | AA54: =IF(AB54="+",1,IF(AB54="-","",IF(AB54="",AS54))) | AC54: =IF(AD54="+",1,IF(AD54="-","",IF(AD54="",AT54))) | AG54: =IF(SUM(K54:AC54)<>1,"FEJL","") | AK54: =IF(B54="DEN (SD 21-24)",1,"") | AL54: =IF(B54="DEN (SD 25-32)",1,"") | AM54: =IF(B54="SWE (SD 25-32)",1,"") | AN54: =IF(B54="POL (SD 21-24)",1,"") | AO54: =IF(B54="POL (SD 25-32)",1,"") | AP54: =IF(B54="LAT (SD 25-32)",1,"") | AQ54: =IF(B54="EST (SD 25-32)",1,"") | AR54: =IF(B54="GFR (SD 21-24)",1,"") -> 1 | AS54: =IF(B54="LTU (SD 25-32)",1,"") | AT54: =IF(B54="RUS (SD 25-32)",1,"")
A55: Standard | B55: ='Final list of total hauls pros'!M52 -> POL (SD 21-24) | C55: 51 | D55: ='Final list of total hauls pros'!A52 -> 24022 | E55: =IF(D55<>"",LEFT(D55,2),"") -> 24 | F55: ='Final list of total hauls pros'!B52 -> 37G4 | G55: ='Final list of total hauls pros'!I52 -> POL | H55: ='Final list of total hauls pros'!L52 -> 21-24 | I55: =IF(L55="+",$K$2,IF(N55="+",$M$2,IF(P55="+",$O$2,IF(R55="+",$Q$2,IF(T55="+",$S$2,IF(V55="+",$U$2,IF(X55="+",$W$2,IF(Z55="+",$Y$2,IF(AB55="+",$AA$2,IF(AD55="+",$AC$2,B55)))))))))) -> GFR (SD 21-24) | K55: =IF(L55="+",1,IF(L55="-","",IF(L55="",AK55))) | M55: =IF(N55="+",1,IF(N55="-","",IF(N55="",AL55))) | O55: =IF(P55="+",1,IF(P55="-","",IF(P55="",AM55))) | Q55: =IF(R55="+",1,IF(R55="-","",IF(R55="",AN55))) | R55: - | S55: =IF(T55="+",1,IF(T55="-","",IF(T55="",AO55))) | U55: =IF(V55="+",1,IF(V55="-","",IF(V55="",AP55))) | W55: =IF(X55="+",1,IF(X55="-","",IF(X55="",AQ55))) | Y55: =IF(Z55="+",1,IF(Z55="-","",IF(Z55="",AR55))) -> 1 | Z55: + | AA55: =IF(AB55="+",1,IF(AB55="-","",IF(AB55="",AS55))) | AC55: =IF(AD55="+",1,IF(AD55="-","",IF(AD55="",AT55))) | AG55: =IF(SUM(K55:AC55)<>1,"FEJL","") | AK55: =IF(B55="DEN (SD 21-24)",1,"") | AL55: =IF(B55="DEN (SD 25-32)",1,"") | AM55: =IF(B55="SWE (SD 25-32)",1,"") | AN55: =IF(B55="POL (SD 21-24)",1,"") -> 1 | AO55: =IF(B55="POL (SD 25-32)",1,"") | AP55: =IF(B55="LAT (SD 25-32)",1,"") | AQ55: =IF(B55="EST (SD 25-32)",1,"") | AR55: =IF(B55="GFR (SD 21-24)",1,"") | AS55: =IF(B55="LTU (SD 25-32)",1,"") | AT55: =IF(B55="RUS (SD 25-32)",1,"")
A56: Standard | B56: ='Final list of total hauls pros'!M53 -> GFR (SD 21-24) | C56: 52 | D56: ='Final list of total hauls pros'!A53 -> 24024 | E56: =IF(D56<>"",LEFT(D56,2),"") -> 24 | F56: ='Final list of total hauls pros'!B53 -> 38G3 | G56: ='Final list of total hauls pros'!I53 -> GFR | H56: ='Final list of total hauls pros'!L53 -> 21-24 | I56: =IF(L56="+",$K$2,IF(N56="+",$M$2,IF(P56="+",$O$2,IF(R56="+",$Q$2,IF(T56="+",$S$2,IF(V56="+",$U$2,IF(X56="+",$W$2,IF(Z56="+",$Y$2,IF(AB56="+",$AA$2,IF(AD56="+",$AC$2,B56)))))))))) -> GFR (SD 21-24) | K56: =IF(L56="+",1,IF(L56="-","",IF(L56="",AK56))) | M56: =IF(N56="+",1,IF(N56="-","",IF(N56="",AL56))) | O56: =IF(P56="+",1,IF(P56="-","",IF(P56="",AM56))) | Q56: =IF(R56="+",1,IF(R56="-","",IF(R56="",AN56))) | S56: =IF(T56="+",1,IF(T56="-","",IF(T56="",AO56))) | U56: =IF(V56="+",1,IF(V56="-","",IF(V56="",AP56))) | W56: =IF(X56="+",1,IF(X56="-","",IF(X56="",AQ56))) | Y56: =IF(Z56="+",1,IF(Z56="-","",IF(Z56="",AR56))) -> 1 | AA56: =IF(AB56="+",1,IF(AB56="-","",IF(AB56="",AS56))) | AC56: =IF(AD56="+",1,IF(AD56="-","",IF(AD56="",AT56))) | AG56: =IF(SUM(K56:AC56)<>1,"FEJL","") | AK56: =IF(B56="DEN (SD 21-24)",1,"") | AL56: =IF(B56="DEN (SD 25-32)",1,"") | AM56: =IF(B56="SWE (SD 25-32)",1,"") | AN56: =IF(B56="POL (SD 21-24)",1,"") | AO56: =IF(B56="POL (SD 25-32)",1,"") | AP56: =IF(B56="LAT (SD 25-32)",1,"") | AQ56: =IF(B56="EST (SD 25-32)",1,"") | AR56: =IF(B56="GFR (SD 21-24)",1,"") -> 1 | AS56: =IF(B56="LTU (SD 25-32)",1,"") | AT56: =IF(B56="RUS (SD 25-32)",1,"")
A57: Standard | B57: ='Final list of total hauls pros'!M54 -> GFR (SD 21-24) | C57: 53 | D57: ='Final list of total hauls pros'!A54 -> 24039 | E57: =IF(D57<>"",LEFT(D57,2),"") -> 24 | F57: ='Final list of total hauls pros'!B54 -> 38G4 | G57: ='Final list of total hauls pros'!I54 -> GFR | H57: ='Final list of total hauls pros'!L54 -> 21-24 | I57: =IF(L57="+",$K$2,IF(N57="+",$M$2,IF(P57="+",$O$2,IF(R57="+",$Q$2,IF(T57="+",$S$2,IF(V57="+",$U$2,IF(X57="+",$W$2,IF(Z57="+",$Y$2,IF(AB57="+",$AA$2,IF(AD57="+",$AC$2,B57)))))))))) -> GFR (SD 21-24) | K57: =IF(L57="+",1,IF(L57="-","",IF(L57="",AK57))) | M57: =IF(N57="+",1,IF(N57="-","",IF(N57="",AL57))) | O57: =IF(P57="+",1,IF(P57="-","",IF(P57="",AM57))) | Q57: =IF(R57="+",1,IF(R57="-","",IF(R57="",AN57))) | S57: =IF(T57="+",1,IF(T57="-","",IF(T57="",AO57))) | U57: =IF(V57="+",1,IF(V57="-","",IF(V57="",AP57))) | W57: =IF(X57="+",1,IF(X57="-","",IF(X57="",AQ57))) | Y57: =IF(Z57="+",1,IF(Z57="-","",IF(Z57="",AR57))) -> 1 | AA57: =IF(AB57="+",1,IF(AB57="-","",IF(AB57="",AS57))) | AC57: =IF(AD57="+",1,IF(AD57="-","",IF(AD57="",AT57))) | AG57: =IF(SUM(K57:AC57)<>1,"FEJL","") | AK57: =IF(B57="DEN (SD 21-24)",1,"") | AL57: =IF(B57="DEN (SD 25-32)",1,"") | AM57: =IF(B57="SWE (SD 25-32)",1,"") | AN57: =IF(B57="POL (SD 21-24)",1,"") | AO57: =IF(B57="POL (SD 25-32)",1,"") | AP57: =IF(B57="LAT (SD 25-32)",1,"") | AQ57: =IF(B57="EST (SD 25-32)",1,"") | AR57: =IF(B57="GFR (SD 21-24)",1,"") -> 1 | AS57: =IF(B57="LTU (SD 25-32)",1,"") | AT57: =IF(B57="RUS (SD 25-32)",1,"")
A58: Standard | B58: ='Final list of total hauls pros'!M55 -> GFR (SD 21-24) | C58: 54 | D58: ='Final list of total hauls pros'!A55 -> 24046 | E58: =IF(D58<>"",LEFT(D58,2),"") -> 24 | F58: ='Final list of total hauls pros'!B55 -> 38G4 | G58: ='Final list of total hauls pros'!I55 -> DEN | H58: ='Final list of total hauls pros'!L55 -> 21-24 | I58: =IF(L58="+",$K$2,IF(N58="+",$M$2,IF(P58="+",$O$2,IF(R58="+",$Q$2,IF(T58="+",$S$2,IF(V58="+",$U$2,IF(X58="+",$W$2,IF(Z58="+",$Y$2,IF(AB58="+",$AA$2,IF(AD58="+",$AC$2,B58)))))))))) -> GFR (SD 21-24) | K58: =IF(L58="+",1,IF(L58="-","",IF(L58="",AK58))) | M58: =IF(N58="+",1,IF(N58="-","",IF(N58="",AL58))) | O58: =IF(P58="+",1,IF(P58="-","",IF(P58="",AM58))) | Q58: =IF(R58="+",1,IF(R58="-","",IF(R58="",AN58))) | S58: =IF(T58="+",1,IF(T58="-","",IF(T58="",AO58))) | U58: =IF(V58="+",1,IF(V58="-","",IF(V58="",AP58))) | W58: =IF(X58="+",1,IF(X58="-","",IF(X58="",AQ58))) | Y58: =IF(Z58="+",1,IF(Z58="-","",IF(Z58="",AR58))) -> 1 | AA58: =IF(AB58="+",1,IF(AB58="-","",IF(AB58="",AS58))) | AC58: =IF(AD58="+",1,IF(AD58="-","",IF(AD58="",AT58))) | AG58: =IF(SUM(K58:AC58)<>1,"FEJL","") | AK58: =IF(B58="DEN (SD 21-24)",1,"") | AL58: =IF(B58="DEN (SD 25-32)",1,"") | AM58: =IF(B58="SWE (SD 25-32)",1,"") | AN58: =IF(B58="POL (SD 21-24)",1,"") | AO58: =IF(B58="POL (SD 25-32)",1,"") | AP58: =IF(B58="LAT (SD 25-32)",1,"") | AQ58: =IF(B58="EST (SD 25-32)",1,"") | AR58: =IF(B58="GFR (SD 21-24)",1,"") -> 1 | AS58: =IF(B58="LTU (SD 25-32)",1,"") | AT58: =IF(B58="RUS (SD 25-32)",1,"")
A59: Standard | B59: ='Final list of total hauls pros'!M56 -> GFR (SD 21-24) | C59: 55 | D59: ='Final list of total hauls pros'!A56 -> 24047 | E59: =IF(D59<>"",LEFT(D59,2),"") -> 24 | F59: ='Final list of total hauls pros'!B56 -> 38G4 | G59: ='Final list of total hauls pros'!I56 -> GFR | H59: ='Final list of total hauls pros'!L56 -> 21-24 | I59: =IF(L59="+",$K$2,IF(N59="+",$M$2,IF(P59="+",$O$2,IF(R59="+",$Q$2,IF(T59="+",$S$2,IF(V59="+",$U$2,IF(X59="+",$W$2,IF(Z59="+",$Y$2,IF(AB59="+",$AA$2,IF(AD59="+",$AC$2,B59)))))))))) -> GFR (SD 21-24) | K59: =IF(L59="+",1,IF(L59="-","",IF(L59="",AK59))) | M59: =IF(N59="+",1,IF(N59="-","",IF(N59="",AL59))) | O59: =IF(P59="+",1,IF(P59="-","",IF(P59="",AM59))) | Q59: =IF(R59="+",1,IF(R59="-","",IF(R59="",AN59))) | S59: =IF(T59="+",1,IF(T59="-","",IF(T59="",AO59))) | U59: =IF(V59="+",1,IF(V59="-","",IF(V59="",AP59))) | W59: =IF(X59="+",1,IF(X59="-","",IF(X59="",AQ59))) | Y59: =IF(Z59="+",1,IF(Z59="-","",IF(Z59="",AR59))) -> 1 | AA59: =IF(AB59="+",1,IF(AB59="-","",IF(AB59="",AS59))) | AC59: =IF(AD59="+",1,IF(AD59="-","",IF(AD59="",AT59))) | AG59: =IF(SUM(K59:AC59)<>1,"FEJL","") | AK59: =IF(B59="DEN (SD 21-24)",1,"") | AL59: =IF(B59="DEN (SD 25-32)",1,"") | AM59: =IF(B59="SWE (SD 25-32)",1,"") | AN59: =IF(B59="POL (SD 21-24)",1,"") | AO59: =IF(B59="POL (SD 25-32)",1,"") | AP59: =IF(B59="LAT (SD 25-32)",1,"") | AQ59: =IF(B59="EST (SD 25-32)",1,"") | AR59: =IF(B59="GFR (SD 21-24)",1,"") -> 1 | AS59: =IF(B59="LTU (SD 25-32)",1,"") | AT59: =IF(B59="RUS (SD 25-32)",1,"")
A60: Standard | B60: ='Final list of total hauls pros'!M57 -> POL (SD 21-24) | C60: 56 | D60: ='Final list of total hauls pros'!A57 -> 24055 | E60: =IF(D60<>"",LEFT(D60,2),"") -> 24 | F60: ='Final list of total hauls pros'!B57 -> 38G4 | G60: ='Final list of total hauls pros'!I57 -> POL | H60: ='Final list of total hauls pros'!L57 -> 21-24 | I60: =IF(L60="+",$K$2,IF(N60="+",$M$2,IF(P60="+",$O$2,IF(R60="+",$Q$2,IF(T60="+",$S$2,IF(V60="+",$U$2,IF(X60="+",$W$2,IF(Z60="+",$Y$2,IF(AB60="+",$AA$2,IF(AD60="+",$AC$2,B60)))))))))) -> GFR (SD 21-24) | K60: =IF(L60="+",1,IF(L60="-","",IF(L60="",AK60))) | M60: =IF(N60="+",1,IF(N60="-","",IF(N60="",AL60))) | O60: =IF(P60="+",1,IF(P60="-","",IF(P60="",AM60))) | Q60: =IF(R60="+",1,IF(R60="-","",IF(R60="",AN60))) | R60: - | S60: =IF(T60="+",1,IF(T60="-","",IF(T60="",AO60))) | U60: =IF(V60="+",1,IF(V60="-","",IF(V60="",AP60))) | W60: =IF(X60="+",1,IF(X60="-","",IF(X60="",AQ60))) | Y60: =IF(Z60="+",1,IF(Z60="-","",IF(Z60="",AR60))) -> 1 | Z60: + | AA60: =IF(AB60="+",1,IF(AB60="-","",IF(AB60="",AS60))) | AC60: =IF(AD60="+",1,IF(AD60="-","",IF(AD60="",AT60))) | AG60: =IF(SUM(K60:AC60)<>1,"FEJL","") | AK60: =IF(B60="DEN (SD 21-24)",1,"") | AL60: =IF(B60="DEN (SD 25-32)",1,"") | AM60: =IF(B60="SWE (SD 25-32)",1,"") | AN60: =IF(B60="POL (SD 21-24)",1,"") -> 1 | AO60: =IF(B60="POL (SD 25-32)",1,"") | AP60: =IF(B60="LAT (SD 25-32)",1,"") | AQ60: =IF(B60="EST (SD 25-32)",1,"") | AR60: =IF(B60="GFR (SD 21-24)",1,"") | AS60: =IF(B60="LTU (SD 25-32)",1,"") | AT60: =IF(B60="RUS (SD 25-32)",1,"")
A61: Standard | B61: ='Final list of total hauls pros'!M58 -> POL (SD 21-24) | C61: 57 | D61: ='Final list of total hauls pros'!A58 -> 24057 | E61: =IF(D61<>"",LEFT(D61,2),"") -> 24 | F61: ='Final list of total hauls pros'!B58 -> 37G4 | G61: ='Final list of total hauls pros'!I58 -> POL | H61: ='Final list of total hauls pros'!L58 -> 21-24 | I61: =IF(L61="+",$K$2,IF(N61="+",$M$2,IF(P61="+",$O$2,IF(R61="+",$Q$2,IF(T61="+",$S$2,IF(V61="+",$U$2,IF(X61="+",$W$2,IF(Z61="+",$Y$2,IF(AB61="+",$AA$2,IF(AD61="+",$AC$2,B61)))))))))) -> GFR (SD 21-24) | K61: =IF(L61="+",1,IF(L61="-","",IF(L61="",AK61))) | M61: =IF(N61="+",1,IF(N61="-","",IF(N61="",AL61))) | O61: =IF(P61="+",1,IF(P61="-","",IF(P61="",AM61))) | Q61: =IF(R61="+",1,IF(R61="-","",IF(R61="",AN61))) | R61: - | S61: =IF(T61="+",1,IF(T61="-","",IF(T61="",AO61))) | U61: =IF(V61="+",1,IF(V61="-","",IF(V61="",AP61))) | W61: =IF(X61="+",1,IF(X61="-","",IF(X61="",AQ61))) | Y61: =IF(Z61="+",1,IF(Z61="-","",IF(Z61="",AR61))) -> 1 | Z61: + | AA61: =IF(AB61="+",1,IF(AB61="-","",IF(AB61="",AS61))) | AC61: =IF(AD61="+",1,IF(AD61="-","",IF(AD61="",AT61))) | AG61: =IF(SUM(K61:AC61)<>1,"FEJL","") | AK61: =IF(B61="DEN (SD 21-24)",1,"") | AL61: =IF(B61="DEN (SD 25-32)",1,"") | AM61: =IF(B61="SWE (SD 25-32)",1,"") | AN61: =IF(B61="POL (SD 21-24)",1,"") -> 1 | AO61: =IF(B61="POL (SD 25-32)",1,"") | AP61: =IF(B61="LAT (SD 25-32)",1,"") | AQ61: =IF(B61="EST (SD 25-32)",1,"") | AR61: =IF(B61="GFR (SD 21-24)",1,"") | AS61: =IF(B61="LTU (SD 25-32)",1,"") | AT61: =IF(B61="RUS (SD 25-32)",1,"")
A62: Standard | B62: ='Final list of total hauls pros'!M59 -> GFR (SD 21-24) | C62: 58 | D62: ='Final list of total hauls pros'!A59 -> 24059 | E62: =IF(D62<>"",LEFT(D62,2),"") -> 24 | F62: ='Final list of total hauls pros'!B59 -> 38G2 | G62: ='Final list of total hauls pros'!I59 -> DEN | H62: ='Final list of total hauls pros'!L59 -> 21-24 | I62: =IF(L62="+",$K$2,IF(N62="+",$M$2,IF(P62="+",$O$2,IF(R62="+",$Q$2,IF(T62="+",$S$2,IF(V62="+",$U$2,IF(X62="+",$W$2,IF(Z62="+",$Y$2,IF(AB62="+",$AA$2,IF(AD62="+",$AC$2,B62)))))))))) -> GFR (SD 21-24) | K62: =IF(L62="+",1,IF(L62="-","",IF(L62="",AK62))) | M62: =IF(N62="+",1,IF(N62="-","",IF(N62="",AL62))) | O62: =IF(P62="+",1,IF(P62="-","",IF(P62="",AM62))) | Q62: =IF(R62="+",1,IF(R62="-","",IF(R62="",AN62))) | S62: =IF(T62="+",1,IF(T62="-","",IF(T62="",AO62))) | U62: =IF(V62="+",1,IF(V62="-","",IF(V62="",AP62))) | W62: =IF(X62="+",1,IF(X62="-","",IF(X62="",AQ62))) | Y62: =IF(Z62="+",1,IF(Z62="-","",IF(Z62="",AR62))) -> 1 | AA62: =IF(AB62="+",1,IF(AB62="-","",IF(AB62="",AS62))) | AC62: =IF(AD62="+",1,IF(AD62="-","",IF(AD62="",AT62))) | AG62: =IF(SUM(K62:AC62)<>1,"FEJL","") | AK62: =IF(B62="DEN (SD 21-24)",1,"") | AL62: =IF(B62="DEN (SD 25-32)",1,"") | AM62: =IF(B62="SWE (SD 25-32)",1,"") | AN62: =IF(B62="POL (SD 21-24)",1,"") | AO62: =IF(B62="POL (SD 25-32)",1,"") | AP62: =IF(B62="LAT (SD 25-32)",1,"") | AQ62: =IF(B62="EST (SD 25-32)",1,"") | AR62: =IF(B62="GFR (SD 21-24)",1,"") -> 1 | AS62: =IF(B62="LTU (SD 25-32)",1,"") | AT62: =IF(B62="RUS (SD 25-32)",1,"")
